<?xml version="1.0" ?>
<!-- =================================================================================== -->
<!-- |    This document was autogenerated by xacro from dagana.urdf.xacro              | -->
<!-- |    EDITING THIS FILE BY HAND IS NOT RECOMMENDED                                 | -->
<!-- =================================================================================== -->
<robot name="dagana">
  <link name="world"/>
  <joint name="virtualFixed" type="fixed">
    <parent link="world"/>
    <child link="dagana_gripper_base"/>
  </joint>
  <link name="dagana_gripper_base"/>
  <material name="dark_grey">
    <color rgba="0.2 0.2 0.2 1"/>
  </material>
  <joint name="dagana_gripper_mount_joint" type="fixed">
    <origin rpy="0 0 0" xyz="0 0 0"/>
    <parent link="dagana_gripper_base"/>
    <child link="dagana_gripper_top_link"/>
  </joint>
  <link name="dagana_gripper_top_link">
    <inertial>
      <origin rpy="0 0 0" xyz="-0.0063562154 -0.0060265532000000005  0.060068288000000004"/>
      <mass value="1.7432400"/>
      <inertia ixx="0.0050510328" ixy="-0.00025264216" ixz="-0.00012103013" iyy="0.0047944612" iyz="-0.00073917704" izz="0.0031156997"/>
    </inertial>
    <visual>
      <origin rpy="0 0 0" xyz="0 0 0"/>
      <geometry>
        <mesh filename="package://dagana_urdf/meshes/dg0001-simplified.stl" scale="0.001 0.001 0.001"/>
      </geometry>
      <material name="dark_grey"/>
    </visual>
    <collision>
      <origin rpy="0 0 0" xyz="0 0 0"/>
      <geometry>
        <mesh filename="package://dagana_urdf/meshes/dg0001-ch.stl" scale="0.001 0.001 0.001"/>
      </geometry>
      <material name="dark_grey"/>
    </collision>
  </link>
  <joint name="dagana_gripper_claw_joint" type="revolute">
    <origin rpy="0.5 0 3.14159265359" xyz="0.0 -0.028 0.05025"/>
    <parent link="dagana_gripper_top_link"/>
    <child link="dagana_gripper_bottom_link"/>
    <axis xyz="1 0 0"/>
    <limit effort="1000" lower="0" upper="1" velocity="2.0"/>
  </joint>
  <link name="dagana_gripper_bottom_link">
    <inertial>
      <origin rpy="0 0 0" xyz="0.069644767 0.0026548329 -0.041960263"/>
      <mass value="4.6117745e-01"/>
      <inertia ixx="0.0009385556899999999" ixy="-0.000264452" ixz="7.134683e-05" iyy="0.0019472731" iyz="2.529065e-06" izz="0.0014726990999999999"/>
    </inertial>
    <visual>
      <origin rpy="0 0 0" xyz="0 0 0"/>
      <geometry>
        <mesh filename="package://dagana_urdf/meshes/dg0002.stl" scale="0.001 0.001 0.001"/>
      </geometry>
      <material name="dark_grey"/>
    </visual>
    <collision>
      <origin rpy="0 0 0" xyz="0 0 0"/>
      <geometry>
        <mesh filename="package://dagana_urdf/meshes/dg0002-ch.stl" scale="0.001 0.001 0.001"/>
      </geometry>
      <material name="dark_grey"/>
    </collision>
  </link>
</robot>

