<?xml version="1.0" ?>
<!-- =================================================================================== -->
<!-- |    This document was autogenerated by xacro from two_finger_mimic.urdf.xacro    | -->
<!-- |    EDITING THIS FILE BY HAND IS NOT RECOMMENDED                                 | -->
<!-- =================================================================================== -->
<robot name="ex1" xmlns:xacro="http://ros.org/wiki/xacro">
  <link name="world"/>
  <joint name="virtualFixed" type="fixed">
    <parent link="world"/>
    <child link="motor"/>
  </joint>
  <link name="motor">
    <inertial>
      <mass value="1"/>
      <inertia ixx="100" ixy="0" ixz="0" iyy="100" iyz="0" izz="100"/>
      <origin/>
    </inertial>
    <visual>
      <geometry>
        <cylinder length="0.6" radius=".2"/>
      </geometry>
      <material name="black">
        <color rgba=".1 .1 .1 .1"/>
      </material>
    </visual>
    <collision>
      <origin xyz="0 0 0"/>
      <geometry>
        <cylinder length="0.6" radius=".2"/>
      </geometry>
      <contact_coefficients kd="1.0" kp="1000.0" mu="0"/>
    </collision>
  </link>
  <link name="base">
    <inertial>
      <mass value="1"/>
      <inertia ixx="100" ixy="0" ixz="0" iyy="100" iyz="0" izz="100"/>
      <origin/>
    </inertial>
    <visual>
      <geometry>
        <box size="0.1 .025 .15"/>
      </geometry>
      <origin rpy="0 0 0" xyz="0 -0.15 0"/>
      <material name="white">
        <color rgba="1 1 1 1"/>
      </material>
    </visual>
    <collision>
      <origin rpy="0 0 0" xyz="0 -0.15 0"/>
      <geometry>
        <box size="0.4 .1 .6"/>
      </geometry>
      <contact_coefficients kd="1.0" kp="1000.0" mu="0"/>
    </collision>
  </link>
  <joint name="motor_to_base" type="fixed">
    <parent link="motor"/>
    <child link="base"/>
    <origin xyz="0 -0.15 0"/>
  </joint>
<!--  <link name="left_finger">
    <inertial>
      <mass value="1"/>
      <inertia ixx="100" ixy="0" ixz="0" iyy="100" iyz="0" izz="100"/>
      <origin/>
    </inertial>
    <visual>
      <geometry>
        <box size="0.1 .4 .1"/>
      </geometry>
      <origin rpy="0 0 -0.7" xyz="-0.35 -0.3 0"/>
      <material name="white">
        <color rgba="1 1 1 1"/>
      </material>
    </visual>
    <collision>
      <origin rpy="0 0 -0.7" xyz="-0.4 -0.3 0"/>
      <geometry>
        <box size="0.1 .4 .1"/>
      </geometry>
      <contact_coefficients kd="1.0" kp="1000.0" mu="0"/>
    </collision>
  </link>
  <joint name="base_to_left_finger" type="revolute">
    <axis xyz="0 0 1"/>
    <limit effort="1000.0" lower="0.0" upper="0.7" velocity="0.5"/>
    <parent link="base"/>
    <child link="left_finger"/>
    <origin xyz="-0.1 0 0"/>
  </joint> -->
  
  <!-- ///////////////////////////////////////   Long finger 1   ////////////////////////////////////////// -->
  <!-- ///////////////////////////////////////   Base_Link of the long_finger   ////////////////////////////////////////// -->
    <link name="motor_finger1_virtual_link">
   <inertial> <!-- We need inertial otherwise gazebo does not load the motor joints. I put very low inertia-->
      <origin rpy="0 0 0" xyz="0 0 0"/>
      <mass value="0.01"/>
      <inertia ixx="0.0001" ixy="0.0" ixz="0.0" iyy="0.0001" iyz="0.0" izz="0.0001"/>
    </inertial>
  </link>
    <joint name="motor_finger1" type="revolute">
    <origin rpy="0 0 0" xyz="0 0 0"/>
    <parent link="base"/>
    <child link="motor_finger1_virtual_link"/>
    <limit effort="10" lower="0" upper="2.5" velocity="1"/>
    <dynamics damping="0.003" friction="0.003"/>
  </joint>
  
  
  <link name="LFB1">
    <inertial>
      <origin rpy="0 0 0" xyz="0.000045491656 -0.0037522651 0.0064111226"/>
      <mass value="0.0039598861"/>
      <inertia ixx="4.3061452E-07" ixy="0" ixz="-1.2027573E-07" iyy="3.9605806E-07" iyz="0" izz="3.9738552E-07"/>
    </inertial>
    <visual>
      <origin rpy="0 0 0" xyz="0 0 0"/>
      <geometry>
        <mesh filename="package://iit_heri_ii_hand_description/description/meshes/heri_II/LFB1.STL" />
      </geometry>
      <material name="">
        <color rgba="0.75294 0.75294 0.75294 1"/>
      </material>
    </visual>
    <collision>
      <origin rpy="0 0 0" xyz="0 0 0"/>
      <geometry>
        <mesh filename="package://iit_heri_ii_hand_description/description/meshes/heri_II/LFB1.STL"/>
      </geometry>
    </collision>
  </link>
  <!-- ///////////////////////////////////////   Joint of BASE and the base_link of the short finger   ////////////////////////////////////////// -->
  <joint name="BASE__LFB1" type="revolute">
    <origin rpy="1.57 0 -1.57" xyz="-0.05 -0.15 0"/>
    <parent link="base"/>
    <child link="LFB1"/>
    <axis xyz="0 0 1"/>
    <limit effort="10" lower="-0.1" upper="0.1" velocity="1"/>
    <dynamics damping="0.003" friction="0.003"/>
  </joint>
  <!-- ///////////////////////////////////////   First phalanx of the Long_Finger   ////////////////////////////////////////// -->
  <link name="LFP1_1">
    <inertial>
      <origin rpy="0 0 0" xyz="0.013537693 -0.00011389541 0.00014514898"/>
      <mass value="0.021630428"/>
      <inertia ixx="1.7547572E-06" ixy="1.2425281E-07" ixz="-5.2776703E-08" iyy="7.3422819E-06" iyz="-1.1395559E-09" izz="7.1587820E-06"/>
    </inertial>
    <visual>
      <origin rpy="0 0 0" xyz="0 0 0"/>
      <geometry>
        <mesh filename="package://iit_heri_ii_hand_description/description/meshes/heri_II/LFP1_1.STL"/>
      </geometry>
      <material name="">
        <color rgba="0.75294 0.75294 0.75294 1"/>
      </material>
    </visual>
    <collision>
      <origin rpy="0 0 0" xyz="0 0 0"/>
      <geometry>
        <mesh filename="package://iit_heri_ii_hand_description/description/meshes/heri_II/LFP1_1.STL"/>
      </geometry>
    </collision>
  </link>
  <!-- ///////////////////////////////////////   Joint of base_link and the first phalanx of the short finger   ////////////////////////////////////////// -->
  <joint name="LFB1__LFP1_1" type="revolute">
    <origin rpy="1.5708 -0.29671 0" xyz="0.011 0 0.007"/>
    <parent link="LFB1"/>
    <child link="LFP1_1"/>
    <axis xyz="0 0 -1"/>
    <limit effort="10" lower="-0.1" upper="0.56" velocity="1"/>
    <dynamics damping="0.003" friction="0.003"/>
    <!-- joint of the first phalange -->
    <mimic joint="motor_finger1" nlFunPos="0.08519*2.71828^(-((x-0.9172)/0.1817)^2) + 21500000000000*2.71828^(-((x-32.2)/5.513)^2) + -714900*2.71828^(-((x--17.93)/4.61)^2) + 0.2555*2.71828^(-((x-0.7317)/1.105)^2)"/>
  </joint>
  <gazebo>
    <plugin filename="libroboticsgroup_gazebo_mimic_joint_plugin.so" name="LFB1__LFP1_1_jointmimic_joint_plugin">
      <joint>motor_finger1</joint>
      <mimicJoint>LFB1__LFP1_1</mimicJoint>
      <multiplier>0</multiplier>
      <offset>0</offset>
      <sensitiveness>0.0</sensitiveness>
      <!-- if absolute difference between setpoint and process value is below this threshold, do nothing; 0.0 = disable [rad] -->
      <maxEffort>10.0</maxEffort>
      <nlFunPos>0.08519*2.71828^(-((x-0.9172)/0.1817)^2) + 21500000000000*2.71828^(-((x-32.2)/5.513)^2) + -714900*2.71828^(-((x--17.93)/4.61)^2) + 0.2555*2.71828^(-((x-0.7317)/1.105)^2)</nlFunPos>
    </plugin>
  </gazebo>
  <!-- ///////////////////////////////////////   Second phalanx of the Long_Finger   ////////////////////////////////////////// -->
  <link name="LFP1_2">
    <inertial>
      <origin rpy="0 0 0" xyz="0.012816858 0.00029615072 0.00012767631"/>
      <mass value="0.022869549"/>
      <inertia ixx="1.9943688E-06" ixy="1.3380251E-07" ixz="-5.3468405E-08" iyy="7.4922799E-06" iyz="-9.2812315E-10" izz="7.3102836E-06"/>
    </inertial>
    <visual>
      <origin rpy="0 0 0" xyz="0 0 0"/>
      <geometry>
        <mesh filename="package://iit_heri_ii_hand_description/description/meshes/heri_II/LFP1_2.STL"/>
      </geometry>
      <material name="">
        <color rgba="0.75294 0.75294 0.75294 1"/>
      </material>
    </visual>
    <collision>
      <origin rpy="0 0 0" xyz="0 0 0"/>
      <geometry>
        <mesh filename="package://iit_heri_ii_hand_description/description/meshes/heri_II/LFP1_2.STL"/>
      </geometry>
    </collision>
  </link>
  <!-- ///////////////////////////////////////   Joint of base_link and the first phalanx of the long finger   ////////////////////////////////////////// -->
  <joint name="LFP1_1__LFP1_2" type="revolute">
    <origin rpy="0 0 0" xyz="0.035 0 0"/>
    <parent link="LFP1_1"/>
    <child link="LFP1_2"/>
    <axis xyz="0 0 -1"/>
    <limit effort="10" lower="-0.1" upper="1.22" velocity="1"/>
    <dynamics damping="0.06" friction="0.05"/>
    <!-- joint of the 2 phalange -->
    <mimic joint="motor_finger1" nlFunPos="-0.1028*x^4 + 0.4311*x^3 + -0.6019*x^2 +0.9364*x + -0.01132"/>
  </joint>

  <!-- ///////////////////////////////////////   Tip phalanx of the long finger   ////////////////////////////////////////// -->
  <link name="LFP1_3">
    <inertial>
      <origin rpy="0 0 0" xyz="0.012398348 -0.00034958691 0.000050212619"/>
      <mass value="0.02226615"/>
      <inertia ixx="1.7400409E-06" ixy="4.4309075E-07" ixz="-1.3771833E-08" iyy="6.8917616E-06" iyz="6.4562527E-09" izz="6.4653229E-06"/>
    </inertial>
    <visual>
      <origin rpy="0 0 0" xyz="0 0 0"/>
      <geometry>
        <mesh filename="package://iit_heri_ii_hand_description/description/meshes/heri_II/LFP1_3.STL"/>
      </geometry>
      <material name="">
        <color rgba="0.75294 0.75294 0.75294 1"/>
      </material>
    </visual>
    <collision>
      <origin rpy="0 0 0" xyz="0 0 0"/>
      <geometry>
        <mesh filename="package://iit_heri_ii_hand_description/description/meshes/heri_II/LFP1_3.STL"/>
      </geometry>
    </collision>
  </link>
  <!-- ///////////////////////////////////////   Joint of second and tip phalanxs of the long finger   ////////////////////////////////////////// -->
  <joint name="LFP1_2__LFP1_3" type="revolute">
    <origin rpy="0 0 0" xyz="0.035 0 0"/>
    <parent link="LFP1_2"/>
    <child link="LFP1_3"/>
    <axis xyz="0 0 -1"/>
    <limit effort="10" lower="-0.1" upper="1.22" velocity="1"/>
    <dynamics damping="0.003" friction="0.003"/>
    <!-- joint of the 3 phalange -->
    <mimic joint="motor_finger1" nlFunPos="-0.06965*x^5 + 0.4258*x^4 + -0.7659*x^3 +0.3528*x^2 + 0.4078*x + 0.007414"/>
  </joint>
  
  

  <link name="right_finger1">
  <inertial>
    <mass value="1"/>
    <inertia ixx="100" ixy="0" ixz="0" iyy="100" iyz="0" izz="100" />
    <origin/>
  </inertial>
    <visual>
      <geometry>
        <box size="0.1 .4 .1"/>
      </geometry>
      <origin rpy="0 0 0.7" xyz="0.4 -0.3 0.25"/>
      <material name="white">
        <color rgba="1 1 1 1"/>
      </material>
    </visual>
  <collision>
      <origin rpy="0 0 0.7" xyz="0.4 -0.3 0.25"/>
    <geometry>
        <box size="0.1 .4 .1"/>
    </geometry>
    <contact_coefficients mu="0" kp="1000.0" kd="1.0"/>
  </collision>
  </link>

  <joint name="base_to_right_finger1" type="revolute">
    <axis xyz="0 0 1"/>
    <limit effort="1000.0" lower="-0.7" upper="0.0" velocity="0.5"/>
    <parent link="base"/>
    <child link="right_finger1"/>
    <origin xyz=".1 0 0"/>
  </joint>

  <link name="right_finger2">
  <inertial>
    <mass value="1"/>
    <inertia ixx="100" ixy="0" ixz="0" iyy="100" iyz="0" izz="100" />
    <origin/>
  </inertial>
    <visual>
      <geometry>
        <box size="0.1 .4 .1"/>
      </geometry>
      <origin rpy="0 0 0.7" xyz="0.4 -0.3 -0.25"/>
      <material name="white">
        <color rgba="1 1 1 1"/>
      </material>
    </visual>
  <collision>
      <origin rpy="0 0 0.7" xyz="0.4 -0.3 -0.25"/>
    <geometry>
        <box size="0.1 .4 .1"/>
    </geometry>
    <contact_coefficients mu="0" kp="1000.0" kd="1.0"/>
  </collision>
  </link>

  <joint name="base_to_right_finger2" type="revolute">
    <axis xyz="0 0 1"/>
    <limit effort="1000.0" lower="-0.7" upper="0.0" velocity="0.5"/>
    <parent link="base"/>
    <child link="right_finger2"/>
    <origin xyz=".1 0 0"/>
  </joint>
  
<!--  <link name="left_fingertip">
    <inertial>
      <mass value="1"/>
      <inertia ixx="100" ixy="0" ixz="0" iyy="100" iyz="0" izz="100"/>
      <origin/>
    </inertial>
    <visual>
      <geometry>
        <box size="0.1 .3 .1"/>
      </geometry>
      <origin rpy="0 0 0" xyz="0.1 -0.1 0"/>
      <material name="white">
        <color rgba="1 1 1 1"/>
      </material>
    </visual>
    <collision>
      <origin rpy="0 0 0" xyz="0.1 -0.1 0"/>
      <geometry>
        <box size="0.1 .3 .1"/>
      </geometry>
      <contact_coefficients kd="1.0" kp="1000.0" mu="0"/>
    </collision>
  </link>
  <joint name="left_finger_to_left_fingertip" type="revolute">
    <axis xyz="0 0 1"/>
    <limit effort="1.0" lower="0" upper="0.9" velocity="0.5"/>
    <parent link="left_finger"/>
    <child link="left_fingertip"/>
    <origin xyz="-0.6 -0.5 0"/>
    <mimic joint="base_to_left_finger" multiplier="0.85" offset="0"/>
  </joint> -->
  
  
 <link name="right_fingertip1">
  <inertial>
    <mass value="1"/>
    <inertia ixx="100" ixy="0" ixz="0" iyy="100" iyz="0" izz="100" />
    <origin/>
  </inertial>
    <visual>
      <geometry>
        <box size="0.1 .3 .1"/>
      </geometry>
      <origin rpy="0 0 0" xyz="-0.1 -0.1 0"/>
      <material name="white">
        <color rgba="1 1 1 1"/>
      </material>
    </visual>
  <collision>
      <origin rpy="0 0 0" xyz="-0.1 -0.1 0"/>
    <geometry>
        <box size="0.1 .3 .1"/>
    </geometry>
    <contact_coefficients mu="0" kp="1000.0" kd="1.0"/>
  </collision>
  </link>

  <joint name="right_finger1_to_right_fingertip1" type="revolute">
    <axis xyz="0 0 1"/>
    <limit effort="1.0" lower="-0.9" upper="0.0" velocity="0.5"/>
    <parent link="right_finger1"/>
    <child link="right_fingertip1"/>
    <origin xyz="0.6 -0.5 0.25"/>
    <mimic joint="base_to_right_finger1" multiplier="0.85" offset="0"/>
  </joint>

  <link name="right_fingertip2">
  <inertial>
    <mass value="1"/>
    <inertia ixx="100" ixy="0" ixz="0" iyy="100" iyz="0" izz="100" />
    <origin/>
  </inertial>
    <visual>
      <geometry>
        <box size="0.1 .3 .1"/>
      </geometry>
      <origin rpy="0 0 0" xyz="-0.1 -0.1 0"/>
      <material name="white">
        <color rgba="1 1 1 1"/>
      </material>
    </visual>
  <collision>
     <origin rpy="0 0 0" xyz="-0.1 -0.1 0"/>
    <geometry>
        <box size="0.1 .3 .1"/>
    </geometry>
    <contact_coefficients mu="0" kp="1000.0" kd="1.0"/>
  </collision>
  </link>

  <joint name="right_finger2_to_right_fingertip2" type="revolute">
    <axis xyz="0 0 1"/>
    <limit effort="1.0" lower="-0.9" upper="0.0" velocity="0.5"/>
    <parent link="right_finger2"/>
    <child link="right_fingertip2"/>
    <origin xyz="0.6 -0.5 -0.25"/>
    <mimic joint="base_to_right_finger2" multiplier="0.85" offset="0"/>
  </joint>
  
</robot>
