<?xml version="1.0" encoding="utf-8"?>
<robot name="heri" xmlns:xacro="http://ros.org/wiki/xacro">

  <!-- Import all Gazebo-customization elements, including Gazebo colors -->
  <xacro:include filename="$(find ros_end_effector)/configs/urdf/iit_heri_ros.gazebo" />

  <!-- Import Rviz colors -->
  <xacro:include filename="$(find heri_description)/urdf/materials.xacro" />

  <!-- ///////////////////////////////////////   Short Finger   ////////////////////////////////////////// -->
  <!-- ///////////////////////////////////////   base_link   ////////////////////////////////////////// -->
  <link name="world"/>

  <joint name="world_base" type="fixed">
    <!-- z!= from 1 is necessary because otherwise the hand has tremors. I think this is because it compentetrate
     with the terrain ? -->
    <origin xyz="0 0 0.015" rpy="0 0 0" />
    <parent link="world" />
    <child link="base_link"/>
  </joint>
  
  <link name="base_link">
    <inertial>
      <origin xyz="0.00030739 0.003138 -0.0012876" rpy="0 0 0" />
      <mass value="0.73864" />
      <inertia ixx="0.01" ixy="0" ixz="0" iyy="0.01" iyz="0" izz="0.01" />
    </inertial>
    <visual>
      <origin xyz="0 0 0" rpy="0 0 0" />
      <geometry>
        <mesh filename="package://heri_description/meshes/base_link.STL" />
      </geometry>
      <material name="">
        <color rgba="0.75294 0.75294 0.75294 1" />
      </material>
    </visual>
    <collision>
      <origin xyz="0 0 0" rpy="0 0 0" />
      <geometry>
        <mesh filename="package://heri_description/meshes/base_link.STL" />
      </geometry>
    </collision>
  </link>

  <!-- ///////////////////////////////////////   Base_Link of the short_finger   ////////////////////////////////////////// -->
  <link name="SFB1">
    <inertial>
      <origin xyz="0.000045491656 -0.0037522651 0.0064111226" rpy="0 0 0" />
      <mass value="0.0039598861" />
      <inertia ixx="0.01" ixy="0" ixz="0" iyy="0.01" iyz="0" izz="0.01" />
    </inertial>
    <visual>
      <origin xyz="0 0 0" rpy="0 0 0" />
      <geometry>
        <mesh filename="package://heri_description/meshes/SFB1.STL" />
      </geometry>
      <material name="">
        <color rgba="0.75294 0.75294 0.75294 1" />
      </material>
    </visual>
    <collision>
      <origin xyz="0 0 0" rpy="0 0 0" />
      <geometry>
        <mesh filename="package://heri_description/meshes/SFB1.STL" />
      </geometry>
    </collision>
  </link>

  <!-- ///////////////////////////////////////   Joint of BASE and the base_link of the short finger   ////////////////////////////////////////// -->
  <joint name="BASE__SFB1" type="revolute">
    <origin xyz="-0.0167 -0.0405 0.0635" rpy="1.5708 -1.5708 0" />
    <parent link="base_link" />
    <child link="SFB1" />
    <axis xyz="0 0 1" />
    <limit lower="-0.1" upper="0.1" effort="10" velocity="1" />
    <dynamics damping="0.7" />
  </joint>

  <!-- ///////////////////////////////////////   First phalanx of the Short_Finger   ////////////////////////////////////////// -->
  <link name="SFB1_1">
    <inertial>
      <origin xyz="0.013537693 -0.00011389541 0.00014514898" rpy="0 0 0" />
      <mass value="0.021630428" />
      <inertia ixx="0.01" ixy="0" ixz="0" iyy="0.01" iyz="0" izz="0.01" />
    </inertial>
    <visual>
      <origin xyz="0 0 0" rpy="0 0 0" />
      <geometry>
        <mesh filename="package://heri_description/meshes/SFB1_1.STL" />
      </geometry>
      <material name="">
        <color rgba="0.75294 0.75294 0.75294 1" />
      </material>
    </visual>
    <collision>
      <origin xyz="0 0 0" rpy="0 0 0" />
      <geometry>
        <mesh filename="package://heri_description/meshes/SFB1_1.STL" />
      </geometry>
    </collision>
  </link>

  <!-- ///////////////////////////////////////   Joint of base_link and the first phalanx of the short finger   ////////////////////////////////////////// -->
  <joint name="SFB1__SFP1_1" type="revolute">
    <origin xyz="0.011 0 0.007" rpy="1.5708 -0.29671 0" />
    <parent link="SFB1" />
    <child link="SFB1_1" />
    <axis xyz="0 0 -1" />
    <limit lower="-0.1" upper="0.5" effort="10" velocity="1" />
    <dynamics damping="0.7" />
  </joint>

  <!-- ///////////////////////////////////////   Tip phalanx of the short finger   ////////////////////////////////////////// -->
  <link name="SFP1_2">
    <inertial>
      <origin xyz="0.012398348 -0.00034958691 0.000050212619" rpy="0 0 0" />
      <mass value="0.02226615" />
      <inertia ixx="0.01" ixy="0" ixz="0" iyy="0.01" iyz="0" izz="0.01" />
    </inertial>
    <visual>
      <origin xyz="0 0 0" rpy="0 0 0" />
      <geometry>
        <mesh filename="package://heri_description/meshes/SFP1_2.STL" />
      </geometry>
      <material name="">
        <color rgba="0.75294 0.75294 0.75294 1" />
      </material>
    </visual>
    <collision>
      <origin xyz="0 0 0" rpy="0 0 0" />
      <geometry>
        <mesh filename="package://heri_description/meshes/SFP1_2.STL" />
      </geometry>
    </collision>
  </link>

  <!-- ///////////////////////////////////////   Joint of first and tip phalanxs of the short finger   ////////////////////////////////////////// -->
  <joint name="SFP1_1__SFP1_2" type="revolute">
    <origin xyz="0.035 0 0" rpy="0 0 0" />
    <parent link="SFB1_1" />
    <child link="SFP1_2" />
    <axis xyz="0 0 -1" />
    <limit lower="-0.1" upper="0.5" effort="10" velocity="1" />
    <dynamics damping="0.7" />
    <mimic joint="SFB1__SFP1_1" multiplier="1" offset="0"/>
  </joint>
  
      <xacro:mimic_joint_plugin_gazebo name_prefix="SFP1_1__SFP1_2_joint"
    parent_joint="SFB1__SFP1_1" mimic_joint="SFP1_1__SFP1_2"
    has_pid="false" multiplier="1.0" max_effort="10.0" />

<!-- ///////////////////////////////////////   Long finger 1   ////////////////////////////////////////// -->

  <!-- ///////////////////////////////////////   Base_Link of the long_finger   ////////////////////////////////////////// -->
  <link name="LFB1">
    <inertial>
      <origin xyz="0.000045491656 -0.0037522651 0.0064111226" rpy="0 0 0" />
      <mass value="0.0039598861" />
      <inertia ixx="0.01" ixy="0" ixz="0" iyy="0.01" iyz="0" izz="0.01" />
    </inertial>
    <visual>
      <origin xyz="0 0 0" rpy="0 0 0" />
      <geometry>
        <mesh filename="package://heri_description/meshes/LFB1.STL" />
      </geometry>
      <material name="">
        <color rgba="0.75294 0.75294 0.75294 1" />
      </material>
    </visual>
    <collision>
      <origin xyz="0 0 0" rpy="0 0 0" />
      <geometry>
        <mesh filename="package://heri_description/meshes/LFB1.STL" />
      </geometry>
    </collision>
  </link>

  <!-- ///////////////////////////////////////   Joint of BASE and the base_link of the short finger   ////////////////////////////////////////// -->
  <joint name="BASE__LFB1" type="revolute">
    <origin xyz="-0.0167 0.0405 0.0635" rpy="1.5708 -1.5708 3.1415927" />
    <parent link="base_link" />
    <child link="LFB1" />
    <axis xyz="0 0 1" />
    <limit lower="-0.1" upper="0.1" effort="10" velocity="1" />
    <dynamics damping="0.7" />
  </joint>

  <!-- ///////////////////////////////////////   First phalanx of the Long_Finger   ////////////////////////////////////////// -->
  <link name="LFP1_1">
    <inertial>
      <origin xyz="0.013537693 -0.00011389541 0.00014514898" rpy="0 0 0" />
      <mass value="0.021630428" />
      <inertia ixx="0.01" ixy="0" ixz="0" iyy="0.01" iyz="0" izz="0.01" />
    </inertial>
    <visual>
      <origin xyz="0 0 0" rpy="0 0 0" />
      <geometry>
        <mesh filename="package://heri_description/meshes/LFP1_1.STL" />
      </geometry>
      <material name="">
        <color rgba="0.75294 0.75294 0.75294 1" />
      </material>
    </visual>
    <collision>
      <origin xyz="0 0 0" rpy="0 0 0" />
      <geometry>
        <mesh filename="package://heri_description/meshes/LFP1_1.STL" />
      </geometry>
    </collision>
  </link>

  <!-- ///////////////////////////////////////   Joint of base_link and the first phalanx of the short finger   ////////////////////////////////////////// -->
  <joint name="LFB1__LFP1_1" type="revolute">
    <origin xyz="0.011 0 0.007" rpy="1.5708 -0.29671 0" />
    <parent link="LFB1" />
    <child link="LFP1_1" />
    <axis xyz="0 0 -1" />
    <limit lower="-0.1" upper="0.5" effort="10" velocity="1" />
    <dynamics damping="0.7" />
  </joint>

  <!-- ///////////////////////////////////////   Second phalanx of the Long_Finger   ////////////////////////////////////////// -->
  <link name="LFP1_2">
    <inertial>
      <origin xyz="0.012816858 0.00029615072 0.00012767631" rpy="0 0 0" />
      <mass value="0.022869549" />
      <inertia ixx="0.01" ixy="0" ixz="0" iyy="0.01" iyz="0" izz="0.01" />
    </inertial>
    <visual>
      <origin xyz="0 0 0" rpy="0 0 0" />
      <geometry>
        <mesh filename="package://heri_description/meshes/LFP1_2.STL" />
      </geometry>
      <material name="">
        <color rgba="0.75294 0.75294 0.75294 1" />
      </material>
    </visual>
    <collision>
      <origin xyz="0 0 0" rpy="0 0 0" />
      <geometry>
        <mesh filename="package://heri_description/meshes/LFP1_2.STL" />
      </geometry>
    </collision>
  </link>

  <!-- ///////////////////////////////////////   Joint of base_link and the first phalanx of the short finger   ////////////////////////////////////////// -->
  <joint name="LFP1_1__LFP1_2" type="revolute">
    <origin xyz="0.035 0 0" rpy="0 0 0" />
    <parent link="LFP1_1" />
    <child link="LFP1_2" />
    <axis xyz="0 0 -1" />
    <limit lower="-0.1" upper="0.5" effort="10" velocity="1" />
    <dynamics damping="0.7" />
    <mimic joint="LFB1__LFP1_1" multiplier="1" offset="0"/>
  </joint>
  
        <xacro:mimic_joint_plugin_gazebo name_prefix="LFP1_1__LFP1_2_joint"
    parent_joint="LFB1__LFP1_1" mimic_joint="LFP1_1__LFP1_2"
    has_pid="false" multiplier="1.0" max_effort="10.0" />

  <!-- ///////////////////////////////////////   Tip phalanx of the long finger   ////////////////////////////////////////// -->
  <link name="LFP1_3">
    <inertial>
      <origin xyz="0.012398348 -0.00034958691 0.000050212619" rpy="0 0 0" />
      <mass value="0.02226615" />
      <inertia ixx="0.01" ixy="0" ixz="0" iyy="0.01" iyz="0" izz="0.01" />
    </inertial>
    <visual>
      <origin xyz="0 0 0" rpy="0 0 0" />
      <geometry>
        <mesh filename="package://heri_description/meshes/LFP1_3.STL" />
      </geometry>
      <material name="">
        <color rgba="0.75294 0.75294 0.75294 1" />
      </material>
    </visual>
    <collision>
      <origin xyz="0 0 0" rpy="0 0 0" />
      <geometry>
        <mesh filename="package://heri_description/meshes/LFP1_3.STL" />
      </geometry>
    </collision>
  </link>

  <!-- ///////////////////////////////////////   Joint of second and tip phalanxs of the long finger   ////////////////////////////////////////// -->
  <joint name="LFP1_2__LFP1_3" type="revolute">
    <origin xyz="0.035 0 0" rpy="0 0 0" />
    <parent link="LFP1_2" />
    <child link="LFP1_3" />
    <axis xyz="0 0 -1" />
    <limit lower="-0.1" upper="0.5" effort="10" velocity="1" />
    <dynamics damping="0.7" />
    <mimic joint="LFB1__LFP1_1" multiplier="1" offset="0"/>
  </joint>

        <xacro:mimic_joint_plugin_gazebo name_prefix="LFP1_1__LFP1_3_joint"
    parent_joint="LFB1__LFP1_1" mimic_joint="LFP1_2__LFP1_3"
    has_pid="false" multiplier="1.0" max_effort="10.0" />


  <!-- ///////////////////////////////////////   Long finger 2   ////////////////////////////////////////// -->

  <!-- ///////////////////////////////////////   Base_Link of the long_finger   ////////////////////////////////////////// -->
  <link name="LFB2">
    <inertial>
      <origin xyz="0.000045491656 -0.0037522651 0.0064111226" rpy="0 0 0" />
      <mass value="0.0039598861" />
      <inertia ixx="0.1" ixy="0" ixz="0" iyy="0.1" iyz="0" izz="0.1" />
    </inertial>
    <visual>
      <origin xyz="0 0 0" rpy="0 0 0" />
      <geometry>
        <mesh filename="package://heri_description/meshes/LFB2.STL" />
      </geometry>
      <material name="">
        <color rgba="0.75294 0.75294 0.75294 1" />
      </material>
    </visual>
    <collision>
      <origin xyz="0 0 0" rpy="0 0 0" />
      <geometry>
        <mesh filename="package://heri_description/meshes/LFB2.STL" />
      </geometry>
    </collision>
  </link>

  <!-- ///////////////////////////////////////   Joint of BASE and the base_link of the short finger   ////////////////////////////////////////// -->
  <joint name="BASE__LFB2" type="revolute">
    <origin xyz="0.0353 0.0405 0.0635" rpy="1.5708 -1.5708 3.1415927" />
    <parent link="base_link" />
    <child link="LFB2" />
    <axis xyz="0 0 1" />
    <limit lower="-0.1" upper="0.1" effort="10" velocity="1" />
    <dynamics damping="0.7" />
  </joint>

  <!-- ///////////////////////////////////////   First phalanx of the Long_Finger   ////////////////////////////////////////// -->
  <link name="LFP2_1">
    <inertial>
      <origin xyz="0.013537693 -0.00011389541 0.00014514898" rpy="0 0 0" />
      <mass value="0.021630428" />
      <inertia ixx="0.01" ixy="0" ixz="0" iyy="0.01" iyz="0" izz="0.01" />
    </inertial>
    <visual>
      <origin xyz="0 0 0" rpy="0 0 0" />
      <geometry>
        <mesh filename="package://heri_description/meshes/LFP2_1.STL" />
      </geometry>
      <material name="">
        <color rgba="0.75294 0.75294 0.75294 1" />
      </material>
    </visual>
    <collision>
      <origin xyz="0 0 0" rpy="0 0 0" />
      <geometry>
        <mesh filename="package://heri_description/meshes/LFP2_1.STL" />
      </geometry>
    </collision>
  </link>

  <!-- ///////////////////////////////////////   Joint of base_link and the first phalanx of the short finger   ////////////////////////////////////////// -->
  <joint name="LFB2__LFP2_1" type="revolute">
    <origin xyz="0.011 0 0.007" rpy="1.5708 -0.29671 0" />
    <parent link="LFB2" />
    <child link="LFP2_1" />
    <axis xyz="0 0 -1" />
    <limit lower="-0.1" upper="0.5" effort="10" velocity="1" />
    <dynamics damping="0.7" />
  </joint>

  <!-- ///////////////////////////////////////   Second phalanx of the Long_Finger   ////////////////////////////////////////// -->
  <link name="LFP2_2">
    <inertial>
      <origin xyz="0.012816858 0.00029615072 0.00012767631" rpy="0 0 0" />
      <mass value="0.022869549" />
      <inertia ixx="0.01" ixy="0" ixz="0" iyy="0.01" iyz="0" izz="0.01" />
    </inertial>
    <visual>
      <origin xyz="0 0 0" rpy="0 0 0" />
      <geometry>
        <mesh filename="package://heri_description/meshes/LFP2_2.STL" />
      </geometry>
      <material name="">
        <color rgba="0.75294 0.75294 0.75294 1" />
      </material>
    </visual>
    <collision>
      <origin xyz="0 0 0" rpy="0 0 0" />
      <geometry>
        <mesh filename="package://heri_description/meshes/LFP2_2.STL" />
      </geometry>
    </collision>
  </link>

  <!-- ///////////////////////////////////////   Joint of base_link and the first phalanx of the short finger   ////////////////////////////////////////// -->
  <joint name="LFP2_1__LFP2_2" type="revolute">
    <origin xyz="0.035 0 0" rpy="0 0 0" />
    <parent link="LFP2_1" />
    <child link="LFP2_2" />
    <axis xyz="0 0 -1" />
    <limit lower="-0.1" upper="0.5" effort="10" velocity="1"/>
    <dynamics damping="0.7" />
    <mimic joint="LFB2__LFP2_1" multiplier="1" offset="0"/>    
  </joint>
  
          <xacro:mimic_joint_plugin_gazebo name_prefix="LFP2_1__LFP2_2_joint"
    parent_joint="LFB2__LFP2_1" mimic_joint="LFP2_1__LFP2_2"
    has_pid="false" multiplier="1.0" max_effort="10.0" />
  
  

  <!-- ///////////////////////////////////////   Tip phalanx of the long finger   ////////////////////////////////////////// -->
  <link name="LFP2_3">
    <inertial>
      <origin xyz="0.012398348 -0.00034958691 0.000050212619" rpy="0 0 0" />
      <mass value="0.02226615" />
      <inertia ixx="0.01" ixy="0" ixz="0" iyy="0.01" iyz="0" izz="0.01" />
    </inertial>
    <visual>
      <origin xyz="0 0 0" rpy="0 0 0" />
      <geometry>
        <mesh filename="package://heri_description/meshes/LFP2_3.STL" />
      </geometry>
      <material name="">
        <color rgba="0.75294 0.75294 0.75294 1" />
      </material>
    </visual>
    <collision>
      <origin xyz="0 0 0" rpy="0 0 0" />
      <geometry>
        <mesh filename="package://heri_description/meshes/LFP2_3.STL" />
      </geometry>
    </collision>
  </link>

  <!-- ///////////////////////////////////////   Joint of second and tip phalanxs of the long finger   ////////////////////////////////////////// -->
  <joint name="LFP2_2__LFP2_3" type="revolute">
    <origin xyz="0.035 0 0" rpy="0 0 0" />
    <parent link="LFP2_2" />
    <child link="LFP2_3" />
    <axis xyz="0 0 -1" />
    <limit lower="-0.1" upper="0.5" effort="10" velocity="1"/>
    <dynamics damping="0.7" />
    <mimic joint="LFB2__LFP2_1" multiplier="1" offset="0"/>
  </joint>
  
            <xacro:mimic_joint_plugin_gazebo name_prefix="LFP2_2__LFP2_3_joint"
    parent_joint="LFB2__LFP2_1" mimic_joint="LFP2_2__LFP2_3"
    has_pid="false" multiplier="1.0" max_effort="10.0" />

</robot>
