<?xml version="1.0" ?>
<!-- =================================================================================== -->
<!-- |    This document was autogenerated by xacro from iit_heri_ros.xacro             | -->
<!-- |    EDITING THIS FILE BY HAND IS NOT RECOMMENDED                                 | -->
<!-- =================================================================================== -->
<robot name="iit_heri_ros" xmlns:xacro="http://ros.org/wiki/xacro">
  <!-- ros_control plugin -->
  <gazebo>
    <plugin filename="libgazebo_ros_control.so" name="gazebo_ros_control">
      <robotNamespace>/iit_heri_ros</robotNamespace>
      <robotSimType>gazebo_ros_control/DefaultRobotHWSim</robotSimType>
      <legacyModeNS>true</legacyModeNS>
    </plugin>
  </gazebo>
  <!-- /////////////////////////////////   Gazebo   ////////////////////////////////////// -->
  <gazebo reference="base_link">
    <fudgeFactor value="0.5"/>
    <material>Gazebo/Red</material>
  </gazebo>
  <gazebo reference="SFB1">
    <fudgeFactor value="0.5"/>
    <material>Gazebo/White</material>
  </gazebo>
  <gazebo reference="SFB1_1">
    <fudgeFactor value="0.5"/>
    <material>Gazebo/White</material>
  </gazebo>
  <gazebo reference="SFP1_2">
    <fudgeFactor value="0.5"/>
    <material>Gazebo/Blue</material>
  </gazebo>
  <gazebo reference="LFB1">
    <fudgeFactor value="0.5"/>
    <material>Gazebo/White</material>
  </gazebo>
  <gazebo reference="LFP1_1">
    <fudgeFactor value="0.5"/>
    <material>Gazebo/White</material>
  </gazebo>
  <gazebo reference="LFP1_2">
    <fudgeFactor value="0.5"/>
    <material>Gazebo/White</material>
  </gazebo>
  <gazebo reference="LFP1_3">
    <fudgeFactor value="0.5"/>
    <material>Gazebo/Blue</material>
  </gazebo>
  <gazebo reference="LFB2">
    <fudgeFactor value="0.5"/>
    <material>Gazebo/White</material>
  </gazebo>
  <gazebo reference="LFP2_1">
    <fudgeFactor value="0.5"/>
    <material>Gazebo/White</material>
  </gazebo>
  <gazebo reference="LFP2_2">
    <fudgeFactor value="0.5"/>
    <material>Gazebo/White</material>
  </gazebo>
  <gazebo reference="LFP2_3">
    <fudgeFactor value="0.5"/>
    <material>Gazebo/Blue</material>
  </gazebo>
  <material name="Black">
    <color rgba="0 0 0 1"/>
  </material>
  <material name="White">
    <color rgba="1 1 1 1"/>
  </material>
  <material name="Blue">
    <color rgba="0 0 1 1"/>
  </material>
  <material name="Red">
    <color rgba="1 0 0 1"/>
  </material>
  <!-- ///////////////////////////////////////   Short Finger   ////////////////////////////////////////// -->
  <!-- ///////////////////////////////////////   base_link   ////////////////////////////////////////// -->
  <link name="world"/>
  <joint name="world_base" type="fixed">
    <origin rpy="0 0 0" xyz="0 0 0.015"/>
    <parent link="world"/>
    <child link="base_link"/>
  </joint>
  <link name="base_link">
    <inertial>
      <origin rpy="0 0 0" xyz="0.00030739 0.003138 -0.0012876"/>
      <mass value="0.73864"/>
      <inertia ixx="0.01" ixy="0" ixz="0" iyy="0.01" iyz="0" izz="0.01"/>
    </inertial>
    <visual>
      <origin rpy="0 0 0" xyz="0 0 0"/>
      <geometry>
        <mesh filename="package://heri_description/meshes/base_link.STL"/>
      </geometry>
      <material name="">
        <color rgba="0.75294 0.75294 0.75294 1"/>
      </material>
    </visual>
    <collision>
      <origin rpy="0 0 0" xyz="0 0 0"/>
      <geometry>
        <mesh filename="package://heri_description/meshes/base_link.STL"/>
      </geometry>
    </collision>
  </link>
  <!-- ///////////////////////////////////////   Base_Link of the short_finger   ////////////////////////////////////////// -->
  <link name="SFB1">
    <inertial>
      <origin rpy="0 0 0" xyz="0.000045491656 -0.0037522651 0.0064111226"/>
      <mass value="0.0039598861"/>
      <inertia ixx="0.01" ixy="0" ixz="0" iyy="0.01" iyz="0" izz="0.01"/>
    </inertial>
    <visual>
      <origin rpy="0 0 0" xyz="0 0 0"/>
      <geometry>
        <mesh filename="package://heri_description/meshes/SFB1.STL"/>
      </geometry>
      <material name="">
        <color rgba="0.75294 0.75294 0.75294 1"/>
      </material>
    </visual>
    <collision>
      <origin rpy="0 0 0" xyz="0 0 0"/>
      <geometry>
        <mesh filename="package://heri_description/meshes/SFB1.STL"/>
      </geometry>
    </collision>
  </link>
  <!-- ///////////////////////////////////////   Joint of BASE and the base_link of the short finger   ////////////////////////////////////////// -->
  <joint name="BASE__SFB1" type="revolute">
    <origin rpy="1.5708 -1.5708 0" xyz="-0.0167 -0.0405 0.0635"/>
    <parent link="base_link"/>
    <child link="SFB1"/>
    <axis xyz="0 0 1"/>
    <limit effort="10" lower="-0.1" upper="0.1" velocity="1"/>
    <dynamics damping="0.7"/>
  </joint>
  <!-- ///////////////////////////////////////   First phalanx of the Short_Finger   ////////////////////////////////////////// -->
  <link name="SFB1_1">
    <inertial>
      <origin rpy="0 0 0" xyz="0.013537693 -0.00011389541 0.00014514898"/>
      <mass value="0.021630428"/>
      <inertia ixx="0.01" ixy="0" ixz="0" iyy="0.01" iyz="0" izz="0.01"/>
    </inertial>
    <visual>
      <origin rpy="0 0 0" xyz="0 0 0"/>
      <geometry>
        <mesh filename="package://heri_description/meshes/SFB1_1.STL"/>
      </geometry>
      <material name="">
        <color rgba="0.75294 0.75294 0.75294 1"/>
      </material>
    </visual>
    <collision>
      <origin rpy="0 0 0" xyz="0 0 0"/>
      <geometry>
        <mesh filename="package://heri_description/meshes/SFB1_1.STL"/>
      </geometry>
    </collision>
  </link>
  <!-- ///////////////////////////////////////   Joint of base_link and the first phalanx of the short finger   ////////////////////////////////////////// -->
  <joint name="SFB1__SFP1_1" type="revolute">
    <origin rpy="1.5708 -0.29671 0" xyz="0.011 0 0.007"/>
    <parent link="SFB1"/>
    <child link="SFB1_1"/>
    <axis xyz="0 0 -1"/>
    <limit effort="10" lower="-0.1" upper="0.5" velocity="1"/>
    <dynamics damping="0.7"/>
  </joint>
  <!-- ///////////////////////////////////////   Tip phalanx of the short finger   ////////////////////////////////////////// -->
  <link name="SFP1_2">
    <inertial>
      <origin rpy="0 0 0" xyz="0.012398348 -0.00034958691 0.000050212619"/>
      <mass value="0.02226615"/>
      <inertia ixx="0.01" ixy="0" ixz="0" iyy="0.01" iyz="0" izz="0.01"/>
    </inertial>
    <visual>
      <origin rpy="0 0 0" xyz="0 0 0"/>
      <geometry>
        <mesh filename="package://heri_description/meshes/SFP1_2.STL"/>
      </geometry>
      <material name="">
        <color rgba="0.75294 0.75294 0.75294 1"/>
      </material>
    </visual>
    <collision>
      <origin rpy="0 0 0" xyz="0 0 0"/>
      <geometry>
        <mesh filename="package://heri_description/meshes/SFP1_2.STL"/>
      </geometry>
    </collision>
  </link>
  <!-- ///////////////////////////////////////   Joint of first and tip phalanxs of the short finger   ////////////////////////////////////////// -->
  <joint name="SFP1_1__SFP1_2" type="revolute">
    <origin rpy="0 0 0" xyz="0.035 0 0"/>
    <parent link="SFB1_1"/>
    <child link="SFP1_2"/>
    <axis xyz="0 0 -1"/>
    <limit effort="10" lower="-0.1" upper="0.5" velocity="1"/>
    <dynamics damping="0.7"/>
  </joint>
  <!-- ///////////////////////////////////////   Long finger 1   ////////////////////////////////////////// -->
  <!-- ///////////////////////////////////////   Base_Link of the long_finger   ////////////////////////////////////////// -->
  <link name="LFB1">
    <inertial>
      <origin rpy="0 0 0" xyz="0.000045491656 -0.0037522651 0.0064111226"/>
      <mass value="0.0039598861"/>
      <inertia ixx="0.01" ixy="0" ixz="0" iyy="0.01" iyz="0" izz="0.01"/>
    </inertial>
    <visual>
      <origin rpy="0 0 0" xyz="0 0 0"/>
      <geometry>
        <mesh filename="package://heri_description/meshes/LFB1.STL"/>
      </geometry>
      <material name="">
        <color rgba="0.75294 0.75294 0.75294 1"/>
      </material>
    </visual>
    <collision>
      <origin rpy="0 0 0" xyz="0 0 0"/>
      <geometry>
        <mesh filename="package://heri_description/meshes/LFB1.STL"/>
      </geometry>
    </collision>
  </link>
  <!-- ///////////////////////////////////////   Joint of BASE and the base_link of the short finger   ////////////////////////////////////////// -->
  <joint name="BASE__LFB1" type="revolute">
    <origin rpy="1.5708 -1.5708 3.1415927" xyz="-0.0167 0.0405 0.0635"/>
    <parent link="base_link"/>
    <child link="LFB1"/>
    <axis xyz="0 0 1"/>
    <limit effort="10" lower="-0.1" upper="0.1" velocity="1"/>
    <dynamics damping="0.7"/>
  </joint>
  <!-- ///////////////////////////////////////   First phalanx of the Long_Finger   ////////////////////////////////////////// -->
  <link name="LFP1_1">
    <inertial>
      <origin rpy="0 0 0" xyz="0.013537693 -0.00011389541 0.00014514898"/>
      <mass value="0.021630428"/>
      <inertia ixx="0.01" ixy="0" ixz="0" iyy="0.01" iyz="0" izz="0.01"/>
    </inertial>
    <visual>
      <origin rpy="0 0 0" xyz="0 0 0"/>
      <geometry>
        <mesh filename="package://heri_description/meshes/LFP1_1.STL"/>
      </geometry>
      <material name="">
        <color rgba="0.75294 0.75294 0.75294 1"/>
      </material>
    </visual>
    <collision>
      <origin rpy="0 0 0" xyz="0 0 0"/>
      <geometry>
        <mesh filename="package://heri_description/meshes/LFP1_1.STL"/>
      </geometry>
    </collision>
  </link>
  <!-- ///////////////////////////////////////   Joint of base_link and the first phalanx of the short finger   ////////////////////////////////////////// -->
  <joint name="LFB1__LFP1_1" type="revolute">
    <origin rpy="1.5708 -0.29671 0" xyz="0.011 0 0.007"/>
    <parent link="LFB1"/>
    <child link="LFP1_1"/>
    <axis xyz="0 0 -1"/>
    <limit effort="10" lower="-0.1" upper="0.5" velocity="1"/>
    <dynamics damping="0.7"/>
  </joint>
  <!-- ///////////////////////////////////////   Second phalanx of the Long_Finger   ////////////////////////////////////////// -->
  <link name="LFP1_2">
    <inertial>
      <origin rpy="0 0 0" xyz="0.012816858 0.00029615072 0.00012767631"/>
      <mass value="0.022869549"/>
      <inertia ixx="0.01" ixy="0" ixz="0" iyy="0.01" iyz="0" izz="0.01"/>
    </inertial>
    <visual>
      <origin rpy="0 0 0" xyz="0 0 0"/>
      <geometry>
        <mesh filename="package://heri_description/meshes/LFP1_2.STL"/>
      </geometry>
      <material name="">
        <color rgba="0.75294 0.75294 0.75294 1"/>
      </material>
    </visual>
    <collision>
      <origin rpy="0 0 0" xyz="0 0 0"/>
      <geometry>
        <mesh filename="package://heri_description/meshes/LFP1_2.STL"/>
      </geometry>
    </collision>
  </link>
  <!-- ///////////////////////////////////////   Joint of base_link and the first phalanx of the short finger   ////////////////////////////////////////// -->
  <joint name="LFP1_1__LFP1_2" type="revolute">
    <origin rpy="0 0 0" xyz="0.035 0 0"/>
    <parent link="LFP1_1"/>
    <child link="LFP1_2"/>
    <axis xyz="0 0 -1"/>
    <limit effort="10" lower="-0.1" upper="0.5" velocity="1"/>
    <dynamics damping="0.7"/>
  </joint>
  <!-- ///////////////////////////////////////   Tip phalanx of the long finger   ////////////////////////////////////////// -->
  <link name="LFP1_3">
    <inertial>
      <origin rpy="0 0 0" xyz="0.012398348 -0.00034958691 0.000050212619"/>
      <mass value="0.02226615"/>
      <inertia ixx="0.01" ixy="0" ixz="0" iyy="0.01" iyz="0" izz="0.01"/>
    </inertial>
    <visual>
      <origin rpy="0 0 0" xyz="0 0 0"/>
      <geometry>
        <mesh filename="package://heri_description/meshes/LFP1_3.STL"/>
      </geometry>
      <material name="">
        <color rgba="0.75294 0.75294 0.75294 1"/>
      </material>
    </visual>
    <collision>
      <origin rpy="0 0 0" xyz="0 0 0"/>
      <geometry>
        <mesh filename="package://heri_description/meshes/LFP1_3.STL"/>
      </geometry>
    </collision>
  </link>
  <!-- ///////////////////////////////////////   Joint of second and tip phalanxs of the long finger   ////////////////////////////////////////// -->
  <joint name="LFP1_2__LFP1_3" type="revolute">
    <origin rpy="0 0 0" xyz="0.035 0 0"/>
    <parent link="LFP1_2"/>
    <child link="LFP1_3"/>
    <axis xyz="0 0 -1"/>
    <limit effort="10" lower="-0.1" upper="0.5" velocity="1"/>
    <dynamics damping="0.7"/>
  </joint>
  <!-- ///////////////////////////////////////   Long finger 2   ////////////////////////////////////////// -->
  <!-- ///////////////////////////////////////   Base_Link of the long_finger   ////////////////////////////////////////// -->
  <link name="LFB2">
    <inertial>
      <origin rpy="0 0 0" xyz="0.000045491656 -0.0037522651 0.0064111226"/>
      <mass value="0.0039598861"/>
      <inertia ixx="0.1" ixy="0" ixz="0" iyy="0.1" iyz="0" izz="0.1"/>
    </inertial>
    <visual>
      <origin rpy="0 0 0" xyz="0 0 0"/>
      <geometry>
        <mesh filename="package://heri_description/meshes/LFB2.STL"/>
      </geometry>
      <material name="">
        <color rgba="0.75294 0.75294 0.75294 1"/>
      </material>
    </visual>
    <collision>
      <origin rpy="0 0 0" xyz="0 0 0"/>
      <geometry>
        <mesh filename="package://heri_description/meshes/LFB2.STL"/>
      </geometry>
    </collision>
  </link>
  <!-- ///////////////////////////////////////   Joint of BASE and the base_link of the short finger   ////////////////////////////////////////// -->
  <joint name="BASE__LFB2" type="revolute">
    <origin rpy="1.5708 -1.5708 3.1415927" xyz="0.0353 0.0405 0.0635"/>
    <parent link="base_link"/>
    <child link="LFB2"/>
    <axis xyz="0 0 1"/>
    <limit effort="10" lower="-0.1" upper="0.1" velocity="1"/>
    <dynamics damping="0.7"/>
  </joint>
  <!-- ///////////////////////////////////////   First phalanx of the Long_Finger   ////////////////////////////////////////// -->
  <link name="LFP2_1">
    <inertial>
      <origin rpy="0 0 0" xyz="0.013537693 -0.00011389541 0.00014514898"/>
      <mass value="0.021630428"/>
      <inertia ixx="0.01" ixy="0" ixz="0" iyy="0.01" iyz="0" izz="0.01"/>
    </inertial>
    <visual>
      <origin rpy="0 0 0" xyz="0 0 0"/>
      <geometry>
        <mesh filename="package://heri_description/meshes/LFP2_1.STL"/>
      </geometry>
      <material name="">
        <color rgba="0.75294 0.75294 0.75294 1"/>
      </material>
    </visual>
    <collision>
      <origin rpy="0 0 0" xyz="0 0 0"/>
      <geometry>
        <mesh filename="package://heri_description/meshes/LFP2_1.STL"/>
      </geometry>
    </collision>
  </link>
  <!-- ///////////////////////////////////////   Joint of base_link and the first phalanx of the short finger   ////////////////////////////////////////// -->
  <joint name="LFB2__LFP2_1" type="revolute">
    <origin rpy="1.5708 -0.29671 0" xyz="0.011 0 0.007"/>
    <parent link="LFB2"/>
    <child link="LFP2_1"/>
    <axis xyz="0 0 -1"/>
    <limit effort="10" lower="-0.1" upper="0.5" velocity="1"/>
    <dynamics damping="0.7"/>
  </joint>
  <!-- ///////////////////////////////////////   Second phalanx of the Long_Finger   ////////////////////////////////////////// -->
  <link name="LFP2_2">
    <inertial>
      <origin rpy="0 0 0" xyz="0.012816858 0.00029615072 0.00012767631"/>
      <mass value="0.022869549"/>
      <inertia ixx="0.01" ixy="0" ixz="0" iyy="0.01" iyz="0" izz="0.01"/>
    </inertial>
    <visual>
      <origin rpy="0 0 0" xyz="0 0 0"/>
      <geometry>
        <mesh filename="package://heri_description/meshes/LFP2_2.STL"/>
      </geometry>
      <material name="">
        <color rgba="0.75294 0.75294 0.75294 1"/>
      </material>
    </visual>
    <collision>
      <origin rpy="0 0 0" xyz="0 0 0"/>
      <geometry>
        <mesh filename="package://heri_description/meshes/LFP2_2.STL"/>
      </geometry>
    </collision>
  </link>
  <!-- ///////////////////////////////////////   Joint of base_link and the first phalanx of the short finger   ////////////////////////////////////////// -->
  <joint name="LFP2_1__LFP2_2" type="revolute">
    <origin rpy="0 0 0" xyz="0.035 0 0"/>
    <parent link="LFP2_1"/>
    <child link="LFP2_2"/>
    <axis xyz="0 0 -1"/>
    <limit effort="10" lower="-0.1" upper="0.5" velocity="1"/>
    <dynamics damping="0.7"/>
  </joint>
  <!-- ///////////////////////////////////////   Tip phalanx of the long finger   ////////////////////////////////////////// -->
  <link name="LFP2_3">
    <inertial>
      <origin rpy="0 0 0" xyz="0.012398348 -0.00034958691 0.000050212619"/>
      <mass value="0.02226615"/>
      <inertia ixx="0.01" ixy="0" ixz="0" iyy="0.01" iyz="0" izz="0.01"/>
    </inertial>
    <visual>
      <origin rpy="0 0 0" xyz="0 0 0"/>
      <geometry>
        <mesh filename="package://heri_description/meshes/LFP2_3.STL"/>
      </geometry>
      <material name="">
        <color rgba="0.75294 0.75294 0.75294 1"/>
      </material>
    </visual>
    <collision>
      <origin rpy="0 0 0" xyz="0 0 0"/>
      <geometry>
        <mesh filename="package://heri_description/meshes/LFP2_3.STL"/>
      </geometry>
    </collision>
  </link>
  <!-- ///////////////////////////////////////   Joint of second and tip phalanxs of the long finger   ////////////////////////////////////////// -->
  <joint name="LFP2_2__LFP2_3" type="revolute">
    <origin rpy="0 0 0" xyz="0.035 0 0"/>
    <parent link="LFP2_2"/>
    <child link="LFP2_3"/>
    <axis xyz="0 0 -1"/>
    <limit effort="10" lower="-0.1" upper="0.5" velocity="1"/>
    <dynamics damping="0.7"/>
  </joint>
  <transmission name="tran1">
    <type>transmission_interface/SimpleTransmission</type>
    <joint name="BASE__SFB1">
      <hardwareInterface>hardware_interface/EffortJointInterface</hardwareInterface>
    </joint>
    <actuator name="motor1">
      <hardwareInterface>hardware_interface/EffortJointInterface</hardwareInterface>
      <mechanicalReduction>1</mechanicalReduction>
    </actuator>
  </transmission>
  <transmission name="tran2">
    <type>transmission_interface/SimpleTransmission</type>
    <joint name="SFB1__SFP1_1">
      <hardwareInterface>hardware_interface/EffortJointInterface</hardwareInterface>
    </joint>
    <actuator name="motor2">
      <hardwareInterface>hardware_interface/EffortJointInterface</hardwareInterface>
      <mechanicalReduction>1</mechanicalReduction>
    </actuator>
  </transmission>
  <transmission name="tran3">
    <type>transmission_interface/SimpleTransmission</type>
    <joint name="SFP1_1__SFP1_2">
      <hardwareInterface>hardware_interface/EffortJointInterface</hardwareInterface>
    </joint>
    <actuator name="motor3">
      <hardwareInterface>hardware_interface/EffortJointInterface</hardwareInterface>
      <mechanicalReduction>1</mechanicalReduction>
    </actuator>
  </transmission>
  <transmission name="tran4">
    <type>transmission_interface/SimpleTransmission</type>
    <joint name="BASE__LFB1">
      <hardwareInterface>hardware_interface/EffortJointInterface</hardwareInterface>
    </joint>
    <actuator name="motor4">
      <hardwareInterface>hardware_interface/EffortJointInterface</hardwareInterface>
      <mechanicalReduction>1</mechanicalReduction>
    </actuator>
  </transmission>
  <transmission name="tran5">
    <type>transmission_interface/SimpleTransmission</type>
    <joint name="LFB1__LFP1_1">
      <hardwareInterface>hardware_interface/EffortJointInterface</hardwareInterface>
    </joint>
    <actuator name="motor5">
      <hardwareInterface>hardware_interface/EffortJointInterface</hardwareInterface>
      <mechanicalReduction>1</mechanicalReduction>
    </actuator>
  </transmission>
  <transmission name="tran6">
    <type>transmission_interface/SimpleTransmission</type>
    <joint name="LFP1_1__LFP1_2">
      <hardwareInterface>hardware_interface/EffortJointInterface</hardwareInterface>
    </joint>
    <actuator name="motor6">
      <hardwareInterface>hardware_interface/EffortJointInterface</hardwareInterface>
      <mechanicalReduction>1</mechanicalReduction>
    </actuator>
  </transmission>
  <transmission name="tran7">
    <type>transmission_interface/SimpleTransmission</type>
    <joint name="LFP1_2__LFP1_3">
      <hardwareInterface>hardware_interface/EffortJointInterface</hardwareInterface>
    </joint>
    <actuator name="motor7">
      <hardwareInterface>hardware_interface/EffortJointInterface</hardwareInterface>
      <mechanicalReduction>1</mechanicalReduction>
    </actuator>
  </transmission>
  <transmission name="tran8">
    <type>transmission_interface/SimpleTransmission</type>
    <joint name="BASE__LFB2">
      <hardwareInterface>hardware_interface/EffortJointInterface</hardwareInterface>
    </joint>
    <actuator name="motor8">
      <hardwareInterface>hardware_interface/EffortJointInterface</hardwareInterface>
      <mechanicalReduction>1</mechanicalReduction>
    </actuator>
  </transmission>
  <transmission name="tran9">
    <type>transmission_interface/SimpleTransmission</type>
    <joint name="LFB2__LFP2_1">
      <hardwareInterface>hardware_interface/EffortJointInterface</hardwareInterface>
    </joint>
    <actuator name="motor9">
      <hardwareInterface>hardware_interface/EffortJointInterface</hardwareInterface>
      <mechanicalReduction>1</mechanicalReduction>
    </actuator>
  </transmission>
  <transmission name="tran10">
    <type>transmission_interface/SimpleTransmission</type>
    <joint name="LFP2_1__LFP2_2">
      <hardwareInterface>hardware_interface/EffortJointInterface</hardwareInterface>
    </joint>
    <actuator name="motor10">
      <hardwareInterface>hardware_interface/EffortJointInterface</hardwareInterface>
      <mechanicalReduction>1</mechanicalReduction>
    </actuator>
  </transmission>
  <transmission name="tran11">
    <type>transmission_interface/SimpleTransmission</type>
    <joint name="LFP2_2__LFP2_3">
      <hardwareInterface>hardware_interface/EffortJointInterface</hardwareInterface>
    </joint>
    <actuator name="motor11">
      <hardwareInterface>hardware_interface/EffortJointInterface</hardwareInterface>
      <mechanicalReduction>1</mechanicalReduction>
    </actuator>
  </transmission>
</robot>
