<?xml version="1.0" encoding="utf-8"?>
<robot name="heri_II" xmlns:xacro="http://ros.org/wiki/xacro">

  <!-- Import all Gazebo-customization elements, including Gazebo colors -->
  <xacro:include filename="$(find ros_end_effector)/configs/urdf/iit_heri_ros.gazebo" />

  <!-- Import Rviz colors -->
  <xacro:include filename="$(find ros_end_effector)/configs/urdf/materials.xacro" />

  <!-- ///////////////////////////////////////   Short Finger   ////////////////////////////////////////// -->
  <!-- ///////////////////////////////////////   base_link   ////////////////////////////////////////// -->
  <link name="world"/>

  <joint name="world_base" type="fixed">
    <!-- z!= from 1 is necessary because otherwise the hand has tremors. I think this is because it compentetrate
     with the terrain ? -->
    <origin xyz="0 0 0.015" rpy="0 0 0" />
    <parent link="world" />
    <child link="base_link"/>
  </joint>
  
  <link name="base_link">
    <inertial>
      <origin xyz="0.00030739 0.003138 -0.0012876" rpy="0 0 0" />
      <mass value="0.73864" />
      <inertia ixx="0.0010292" ixy="-6.0935E-06" ixz="1.0739E-05" iyy="0.0011781" iyz="1.3882E-05" izz="0.00089393" />
    </inertial>
    <visual>
      <origin xyz="0 0 0" rpy="0 0 0" />
      <geometry>
        <mesh filename="package://ros_end_effector/configs/meshes/heri_II/base_heri_ii.STL" />
      </geometry>
      <material name="">
        <color rgba="0.75294 0.75294 0.75294 1" />
      </material>
    </visual>
    <collision>
      <origin xyz="0 0 0" rpy="0 0 0" />
      <geometry>
        <mesh filename="package://ros_end_effector/configs/meshes/heri_II/base_heri_ii.STL" />
      </geometry>
    </collision>
  </link>

  <!-- ///////////////////////////////////////   Base_Link of the short_finger   ////////////////////////////////////////// -->
  <link name="SFB1">
    <inertial>
      <origin xyz="3.9400487E-03 0 6.4488006E-03" rpy="0 0 0" />
      <mass value="4.1065000E-03" />
      <inertia ixx="4.3061452E-07" ixy="0" ixz="-1.2027573E-07" iyy="3.9605806E-07" iyz="0" izz="3.9738552E-07" />
    </inertial>
    <visual>
      <origin xyz="0 0 0" rpy="0 0 0" />
      <geometry>
        <mesh filename="package://ros_end_effector/configs/meshes/heri_II/SFB1.STL" />
      </geometry>
      <material name="">
        <color rgba="0.75294 0.75294 0.75294 1" />
      </material>
    </visual>
    <collision>
      <origin xyz="0 0 0" rpy="0 0 0" />
      <geometry>
        <mesh filename="package://ros_end_effector/configs/meshes/heri_II/SFB1.STL" />
      </geometry>
    </collision>
  </link>

  <!-- ///////////////////////////////////////   Joint of BASE and the base_link of the short finger   ////////////////////////////////////////// -->
  <joint name="BASE__SFB1" type="revolute">
    <origin xyz="7.6421E-05 -0.031634 0.1213" rpy="1.5708 -1.5708 0" />
    <parent link="base_link" />
    <child link="SFB1" />
    <axis xyz="0 0 1" />
    <limit lower="-0.1" upper="0.1" effort="10" velocity="1" />
    <dynamics damping="0.003" friction="0.003"/>
  </joint>

  <!-- ///////////////////////////////////////   First phalanx of the Short_Finger   ////////////////////////////////////////// -->
  <link name="SFB1_1">
    <inertial>
      <origin xyz="0.013537693 -0.00011389541 0.00014514898" rpy="0 0 0" />
      <mass value="0.021630428" />
      <inertia ixx="1.7547572E-06" ixy="1.2425281E-07" ixz="-5.2776703E-08" iyy="7.3422819E-06" iyz="-1.1395559E-09" izz="7.1587820E-06" />
    </inertial>
    <visual>
      <origin xyz="0 0 0" rpy="0 0 0" />
      <geometry>
        <mesh filename="package://ros_end_effector/configs/meshes/heri_II/SFB1_1.STL" />
      </geometry>
      <material name="">
        <color rgba="0.75294 0.75294 0.75294 1" />
      </material>
    </visual>
    <collision>
      <origin xyz="0 0 0" rpy="0 0 0" />
      <geometry>
        <mesh filename="package://ros_end_effector/configs/meshes/heri_II/SFB1_1.STL" />
      </geometry>
    </collision>
  </link>

  <!-- ///////////////////////////////////////   Joint of base_link and the first phalanx of the short finger   ////////////////////////////////////////// -->
  <joint name="SFB1__SFP1_1" type="revolute">
    <origin xyz="0.0256 0 0.007" rpy="1.5708 -0.29671 0" />
    <parent link="SFB1" />
    <child link="SFB1_1" />
    <axis xyz="0 0 -1" />
    <limit lower="-0.1" upper="0.9" effort="10" velocity="1" />
    <dynamics damping="0.003" friction="0.003"/>
  </joint>

  <!-- ///////////////////////////////////////   Tip phalanx of the short finger   ////////////////////////////////////////// -->
  <link name="SFP1_2">
    <inertial>
      <origin xyz="0.012398348 -0.00034958691 0.000050212619" rpy="0 0 0" />
      <mass value="0.02226615" />
      <inertia ixx="1.7400409E-06" ixy="4.4309075E-07" ixz="-1.3771833E-08" iyy="6.8917616E-06" iyz="6.4562527E-09" izz="6.4653229E-06" />
    </inertial>
    <visual>
      <origin xyz="0 0 0" rpy="0 0 0" />
      <geometry>
        <mesh filename="package://ros_end_effector/configs/meshes/heri_II/SFP1_2.STL" />
      </geometry>
      <material name="">
        <color rgba="0.75294 0.75294 0.75294 1" />
      </material>
    </visual>
    <collision>
      <origin xyz="0 0 0" rpy="0 0 0" />
      <geometry>
        <mesh filename="package://ros_end_effector/configs/meshes/heri_II/SFP1_2.STL" />
      </geometry>
    </collision>
  </link>

  <!-- ///////////////////////////////////////   Joint of first and tip phalanxs of the short finger   ////////////////////////////////////////// -->
  <joint name="SFP1_1__SFP1_2" type="revolute">
    <origin xyz="0.035 0 0" rpy="0 0 0" />
    <parent link="SFB1_1" />
    <child link="SFP1_2" />
    <axis xyz="0 0 -1" />
    <limit lower="-0.1" upper="1.2" effort="10" velocity="1" />
    <dynamics damping="0.003" friction="0.003"/>
    <mimic joint="SFB1__SFP1_1" multiplier="1.2" offset="0.2"/>
  </joint>
  
      <xacro:mimic_joint_plugin_gazebo name_prefix="SFP1_1__SFP1_2_joint"
    parent_joint="SFB1__SFP1_1" mimic_joint="SFP1_1__SFP1_2"
    has_pid="false" multiplier="1.2" max_effort="10.0" offset="0.2"/>

<!-- ///////////////////////////////////////   Long finger 1   ////////////////////////////////////////// -->

  <!-- ///////////////////////////////////////   Base_Link of the long_finger   ////////////////////////////////////////// -->
  <link name="LFB1">
    <inertial>
      <origin xyz="0.000045491656 -0.0037522651 0.0064111226" rpy="0 0 0" />
      <mass value="0.0039598861" />
      <inertia ixx="4.3061452E-07" ixy="0" ixz="-1.2027573E-07" iyy="3.9605806E-07" iyz="0" izz="3.9738552E-07" />
    </inertial>
    <visual>
      <origin xyz="0 0 0" rpy="0 0 0" />
      <geometry>
        <mesh filename="package://ros_end_effector/configs/meshes/heri_II/LFB1.STL" />
      </geometry>
      <material name="">
        <color rgba="0.75294 0.75294 0.75294 1" />
      </material>
    </visual>
    <collision>
      <origin xyz="0 0 0" rpy="0 0 0" />
      <geometry>
        <mesh filename="package://ros_end_effector/configs/meshes/heri_II/LFB1.STL" />
      </geometry>
    </collision>
  </link>

  <!-- ///////////////////////////////////////   Joint of BASE and the base_link of the short finger   ////////////////////////////////////////// -->
  <joint name="BASE__LFB1" type="revolute">
    <origin xyz="-0.031002 0.025903 0.1213" rpy="1.5708 -1.5708 3.1415927" />
    <parent link="base_link" />
    <child link="LFB1" />
    <axis xyz="0 0 1" />
    <limit lower="-0.1" upper="0.1" effort="10" velocity="1" />
    <dynamics damping="0.003" friction="0.003"/>
  </joint>

  <!-- ///////////////////////////////////////   First phalanx of the Long_Finger   ////////////////////////////////////////// -->
  <link name="LFP1_1">
    <inertial>
      <origin xyz="0.013537693 -0.00011389541 0.00014514898" rpy="0 0 0" />
      <mass value="0.021630428" />
      <inertia ixx="1.7547572E-06" ixy="1.2425281E-07" ixz="-5.2776703E-08" iyy="7.3422819E-06" iyz="-1.1395559E-09" izz="7.1587820E-06" />
    </inertial>
    <visual>
      <origin xyz="0 0 0" rpy="0 0 0" />
      <geometry>
        <mesh filename="package://ros_end_effector/configs/meshes/heri_II/LFP1_1.STL" />
      </geometry>
      <material name="">
        <color rgba="0.75294 0.75294 0.75294 1" />
      </material>
    </visual>
    <collision>
      <origin xyz="0 0 0" rpy="0 0 0" />
      <geometry>
        <mesh filename="package://ros_end_effector/configs/meshes/heri_II/LFP1_1.STL" />
      </geometry>
    </collision>
  </link>

  <!-- ///////////////////////////////////////   Joint of base_link and the first phalanx of the short finger   ////////////////////////////////////////// -->
  <joint name="LFB1__LFP1_1" type="revolute">
    <origin xyz="0.011 0 0.007" rpy="1.5708 -0.29671 0" />
    <parent link="LFB1" />
    <child link="LFP1_1" />
    <axis xyz="0 0 -1" />
    <limit lower="-0.1" upper="0.9" effort="10" velocity="1" />
    <dynamics damping="0.003" friction="0.003"/>
  </joint>

  <!-- ///////////////////////////////////////   Second phalanx of the Long_Finger   ////////////////////////////////////////// -->
  <link name="LFP1_2">
    <inertial>
      <origin xyz="0.012816858 0.00029615072 0.00012767631" rpy="0 0 0" />
      <mass value="0.022869549" />
      <inertia ixx="1.9943688E-06" ixy="1.3380251E-07" ixz="-5.3468405E-08" iyy="7.4922799E-06" iyz="-9.2812315E-10" izz="7.3102836E-06" />
    </inertial>
    <visual>
      <origin xyz="0 0 0" rpy="0 0 0" />
      <geometry>
        <mesh filename="package://ros_end_effector/configs/meshes/heri_II/LFP1_2.STL" />
      </geometry>
      <material name="">
        <color rgba="0.75294 0.75294 0.75294 1" />
      </material>
    </visual>
    <collision>
      <origin xyz="0 0 0" rpy="0 0 0" />
      <geometry>
        <mesh filename="package://ros_end_effector/configs/meshes/heri_II/LFP1_2.STL" />
      </geometry>
    </collision>
  </link>

  <!-- ///////////////////////////////////////   Joint of base_link and the first phalanx of the long finger   ////////////////////////////////////////// -->
  <joint name="LFP1_1__LFP1_2" type="revolute">
    <origin xyz="0.035 0 0" rpy="0 0 0" />
    <parent link="LFP1_1" />
    <child link="LFP1_2" />
    <axis xyz="0 0 -1" />
    <limit lower="-0.1" upper="0.5" effort="10" velocity="1" />
    <dynamics damping="0.06" friction="0.05"/>
    <mimic joint="LFB1__LFP1_1" multiplier="1" offset="0.1"/>
  </joint>
  
        <xacro:mimic_joint_plugin_gazebo name_prefix="LFP1_1__LFP1_2_joint"
    parent_joint="LFB1__LFP1_1" mimic_joint="LFP1_1__LFP1_2"
    has_pid="false" multiplier="1.0" max_effort="10.0" offset="0.1" />

  <!-- ///////////////////////////////////////   Tip phalanx of the long finger   ////////////////////////////////////////// -->
  <link name="LFP1_3">
    <inertial>
      <origin xyz="0.012398348 -0.00034958691 0.000050212619" rpy="0 0 0" />
      <mass value="0.02226615" />
      <inertia ixx="1.7400409E-06" ixy="4.4309075E-07" ixz="-1.3771833E-08" iyy="6.8917616E-06" iyz="6.4562527E-09" izz="6.4653229E-06" />
    </inertial>
    <visual>
      <origin xyz="0 0 0" rpy="0 0 0" />
      <geometry>
        <mesh filename="package://ros_end_effector/configs/meshes/heri_II/LFP1_3.STL" />
      </geometry>
      <material name="">
        <color rgba="0.75294 0.75294 0.75294 1" />
      </material>
    </visual>
    <collision>
      <origin xyz="0 0 0" rpy="0 0 0" />
      <geometry>
        <mesh filename="package://ros_end_effector/configs/meshes/heri_II/LFP1_3.STL" />
      </geometry>
    </collision>
  </link>

  <!-- ///////////////////////////////////////   Joint of second and tip phalanxs of the long finger   ////////////////////////////////////////// -->
  <joint name="LFP1_2__LFP1_3" type="revolute">
    <origin xyz="0.035 0 0" rpy="0 0 0" />
    <parent link="LFP1_2" />
    <child link="LFP1_3" />
    <axis xyz="0 0 -1" />
    <limit lower="-0.1" upper="0.5" effort="10" velocity="1" />
    <dynamics damping="0.003" friction="0.003"/>
    <mimic joint="LFB1__LFP1_1" multiplier="0.5" offset="0.2"/>
  </joint>

        <xacro:mimic_joint_plugin_gazebo name_prefix="LFP1_1__LFP1_3_joint"
    parent_joint="LFB1__LFP1_1" mimic_joint="LFP1_2__LFP1_3"
    has_pid="false" multiplier="0.5" max_effort="10.0" offset="0.2" />


  <!-- ///////////////////////////////////////   Long finger 2   ////////////////////////////////////////// -->

  <!-- ///////////////////////////////////////   Base_Link of the long_finger   ////////////////////////////////////////// -->
  <link name="LFB2">
    <inertial>
      <origin xyz="0.000045491656 -0.0037522651 0.0064111226" rpy="0 0 0" />
      <mass value="0.0039598861" />
      <inertia ixx="4.3061452E-07" ixy="0" ixz="-1.2027573E-07" iyy="3.9605806E-07" iyz="0" izz="3.9738552E-07" />
    </inertial>
    <visual>
      <origin xyz="0 0 0" rpy="0 0 0" />
      <geometry>
        <mesh filename="package://ros_end_effector/configs/meshes/heri_II/LFB2.STL" />
      </geometry>
      <material name="">
        <color rgba="0.75294 0.75294 0.75294 1" />
      </material>
    </visual>
    <collision>
      <origin xyz="0 0 0" rpy="0 0 0" />
      <geometry>
        <mesh filename="package://ros_end_effector/configs/meshes/heri_II/LFB2.STL" />
      </geometry>
    </collision>
  </link>

  <!-- ///////////////////////////////////////   Joint of BASE and the base_link of the short finger   ////////////////////////////////////////// -->
  <joint name="BASE__LFB2" type="revolute">
    <origin xyz="0 0.031903 0.1213" rpy="1.5708 -1.5708 3.1415927" />
    <parent link="base_link" />
    <child link="LFB2" />
    <axis xyz="0 0 1" />
    <limit lower="-0.1" upper="0.1" effort="10" velocity="1" />
    <dynamics damping="0.003" friction="0.003"/>
  </joint>

  <!-- ///////////////////////////////////////   First phalanx of the Long_Finger   ////////////////////////////////////////// -->
  <link name="LFP2_1">
    <inertial>
      <origin xyz="0.013537693 -0.00011389541 0.00014514898" rpy="0 0 0" />
      <mass value="0.021630428" />
      <inertia ixx="1.7547572E-06" ixy="1.2425281E-07" ixz="-5.2776703E-08" iyy="7.3422819E-06" iyz="-1.1395559E-09" izz="7.1587820E-06" />
    </inertial>
    <visual>
      <origin xyz="0 0 0" rpy="0 0 0" />
      <geometry>
        <mesh filename="package://ros_end_effector/configs/meshes/heri_II/LFP2_1.STL" />
      </geometry>
      <material name="">
        <color rgba="0.75294 0.75294 0.75294 1" />
      </material>
    </visual>
    <collision>
      <origin xyz="0 0 0" rpy="0 0 0" />
      <geometry>
        <mesh filename="package://ros_end_effector/configs/meshes/heri_II/LFP2_1.STL" />
      </geometry>
    </collision>
  </link>

  <!-- ///////////////////////////////////////   Joint of base_link and the first phalanx of the short finger   ////////////////////////////////////////// -->
  <joint name="LFB2__LFP2_1" type="revolute">
    <origin xyz="0.011 0 0.007" rpy="1.5708 -0.29671 0" />
    <parent link="LFB2" />
    <child link="LFP2_1" />
    <axis xyz="0 0 -1" />
    <limit lower="-0.1" upper="0.73" effort="10" velocity="1" />
    <dynamics damping="0.003" friction="0.003"/>
  </joint>

  <!-- ///////////////////////////////////////   Second phalanx of the Long_Finger   ////////////////////////////////////////// -->
  <link name="LFP2_2">
    <inertial>
      <origin xyz="0.012816858 0.00029615072 0.00012767631" rpy="0 0 0" />
      <mass value="0.022869549" />
      <inertia ixx="1.9943688E-06" ixy="1.3380251E-07" ixz="-5.3468405E-08" iyy="7.4922799E-06" iyz="-9.2812315E-10" izz="7.3102836E-06" />
    </inertial>
    <visual>
      <origin xyz="0 0 0" rpy="0 0 0" />
      <geometry>
        <mesh filename="package://ros_end_effector/configs/meshes/heri_II/LFP2_2.STL" />
      </geometry>
      <material name="">
        <color rgba="0.75294 0.75294 0.75294 1" />
      </material>
    </visual>
    <collision>
      <origin xyz="0 0 0" rpy="0 0 0" />
      <geometry>
        <mesh filename="package://ros_end_effector/configs/meshes/heri_II/LFP2_2.STL" />
      </geometry>
    </collision>
  </link>

  <!-- ///////////////////////////////////////   Joint of base_link and the first phalanx of the short finger   ////////////////////////////////////////// -->
  <joint name="LFP2_1__LFP2_2" type="revolute">
    <origin xyz="0.035 0 0" rpy="0 0 0" />
    <parent link="LFP2_1" />
    <child link="LFP2_2" />
    <axis xyz="0 0 -1" />
    <limit lower="-0.1" upper="0.5" effort="10" velocity="1"/>
    <dynamics damping="0.003" friction="0.003"/>
    <mimic joint="LFB2__LFP2_1" multiplier="1" offset="0.1"/>
  </joint>
  
          <xacro:mimic_joint_plugin_gazebo name_prefix="LFP2_1__LFP2_2_joint"
    parent_joint="LFB2__LFP2_1" mimic_joint="LFP2_1__LFP2_2"
    has_pid="false" multiplier="1.0" max_effort="10.0" offset="0.1" />
  
  

  <!-- ///////////////////////////////////////   Tip phalanx of the long finger   ////////////////////////////////////////// -->
  <link name="LFP2_3">
    <inertial>
      <origin xyz="0.012398348 -0.00034958691 0.000050212619" rpy="0 0 0" />
      <mass value="0.02226615" />
      <inertia ixx="1.7400409E-06" ixy="4.4309075E-07" ixz="-1.3771833E-08" iyy="6.8917616E-06" iyz="6.4562527E-09" izz="6.4653229E-06" />
    </inertial>
    <visual>
      <origin xyz="0 0 0" rpy="0 0 0" />
      <geometry>
        <mesh filename="package://ros_end_effector/configs/meshes/heri_II/LFP2_3.STL" />
      </geometry>
      <material name="">
        <color rgba="0.75294 0.75294 0.75294 1" />
      </material>
    </visual>
    <collision>
      <origin xyz="0 0 0" rpy="0 0 0" />
      <geometry>
        <mesh filename="package://ros_end_effector/configs/meshes/heri_II/LFP2_3.STL" />
      </geometry>
    </collision>
  </link>

  <!-- ///////////////////////////////////////   Joint of second and tip phalanxs of the long finger   ////////////////////////////////////////// -->
  <joint name="LFP2_2__LFP2_3" type="revolute">
    <origin xyz="0.035 0 0" rpy="0 0 0" />
    <parent link="LFP2_2" />
    <child link="LFP2_3" />
    <axis xyz="0 0 -1" />
    <limit lower="-0.1" upper="0.5" effort="10" velocity="1"/>
    <dynamics damping="0.06" friction="0.05"/>
    <mimic joint="LFB2__LFP2_1" multiplier="0.5" offset="0.2"/>
  </joint>

  <xacro:mimic_joint_plugin_gazebo name_prefix="LFP2_2__LFP2_3_joint"
    parent_joint="LFB2__LFP2_1" mimic_joint="LFP2_2__LFP2_3"
    has_pid="false" multiplier="0.5" max_effort="10.0" offset="0.2" />


  <!-- ///////////////////////////////////////   Long finger 3   ////////////////////////////////////////// -->

  <!-- ///////////////////////////////////////   Base_Link of the long_finger   ////////////////////////////////////////// -->
  <link name="LFB3">
    <inertial>
      <origin xyz="0.000045491656 -0.0037522651 0.0064111226" rpy="0 0 0" />
      <mass value="0.0039598861" />
      <inertia ixx="4.3061452E-07" ixy="0" ixz="-1.2027573E-07" iyy="3.9605806E-07" iyz="0" izz="3.9738552E-07" />
    </inertial>
    <visual>
      <origin xyz="0 0 0" rpy="0 0 0" />
      <geometry>
        <mesh filename="package://ros_end_effector/configs/meshes/heri_II/LFB3.STL" />
      </geometry>
      <material name="">
        <color rgba="0.75294 0.75294 0.75294 1" />
      </material>
    </visual>
    <collision>
      <origin xyz="0 0 0" rpy="0 0 0" />
      <geometry>
        <mesh filename="package://ros_end_effector/configs/meshes/heri_II/LFB3.STL" />
      </geometry>
    </collision>
  </link>

  <!-- ///////////////////////////////////////   Joint of BASE and the base_link of the short finger   ////////////////////////////////////////// -->
  <joint name="BASE__LFB3" type="revolute">
    <origin xyz="0.030998 0.025903 0.1213" rpy="1.5708 -1.5708 3.1415927" />
    <parent link="base_link" />
    <child link="LFB3" />
    <axis xyz="0 0 1" />
    <limit lower="-0.1" upper="0.1" effort="10" velocity="1" />
    <dynamics damping="0.003" friction="0.003"/>
  </joint>

  <!-- ///////////////////////////////////////   First phalanx of the Long_Finger   ////////////////////////////////////////// -->
  <link name="LFP3_1">
    <inertial>
      <origin xyz="0.013537693 -0.00011389541 0.00014514898" rpy="0 0 0" />
      <mass value="0.021630428" />
      <inertia ixx="1.7547572E-06" ixy="1.2425281E-07" ixz="-5.2776703E-08" iyy="7.3422819E-06" iyz="-1.1395559E-09" izz="7.1587820E-06" />
    </inertial>
    <visual>
      <origin xyz="0 0 0" rpy="0 0 0" />
      <geometry>
        <mesh filename="package://ros_end_effector/configs/meshes/heri_II/LFP3_1.STL" />
      </geometry>
      <material name="">
        <color rgba="0.75294 0.75294 0.75294 1" />
      </material>
    </visual>
    <collision>
      <origin xyz="0 0 0" rpy="0 0 0" />
      <geometry>
        <mesh filename="package://ros_end_effector/configs/meshes/heri_II/LFP3_1.STL" />
      </geometry>
    </collision>
  </link>

  <!-- ///////////////////////////////////////   Joint of base_link and the first phalanx of the short finger   ////////////////////////////////////////// -->
  <joint name="LFB3__LFP3_1" type="revolute">
    <origin xyz="0.011 0 0.007" rpy="1.5708 -0.29671 0" />
    <parent link="LFB3" />
    <child link="LFP3_1" />
    <axis xyz="0 0 -1" />
    <limit lower="-0.1" upper="0.9" effort="10" velocity="1" />
    <dynamics damping="0.003" friction="0.003"/>
  </joint>

  <!-- ///////////////////////////////////////   Second phalanx of the Long_Finger   ////////////////////////////////////////// -->
  <link name="LFP3_2">
    <inertial>
      <origin xyz="0.012816858 0.00029615072 0.00012767631" rpy="0 0 0" />
      <mass value="0.022869549" />
      <inertia ixx="1.9943688E-06" ixy="1.3380251E-07" ixz="-5.3468405E-08" iyy="7.4922799E-06" iyz="-9.2812315E-10" izz="7.3102836E-06" />
    </inertial>
    <visual>
      <origin xyz="0 0 0" rpy="0 0 0" />
      <geometry>
        <mesh filename="package://ros_end_effector/configs/meshes/heri_II/LFP3_2.STL" />
      </geometry>
      <material name="">
        <color rgba="0.75294 0.75294 0.75294 1" />
      </material>
    </visual>
    <collision>
      <origin xyz="0 0 0" rpy="0 0 0" />
      <geometry>
        <mesh filename="package://ros_end_effector/configs/meshes/heri_II/LFP3_2.STL" />
      </geometry>
    </collision>
  </link>

  <!-- ///////////////////////////////////////   Joint of base_link and the first phalanx of the short finger   ////////////////////////////////////////// -->
  <joint name="LFP3_1__LFP3_2" type="revolute">
    <origin xyz="0.035 0 0" rpy="0 0 0" />
    <parent link="LFP3_1" />
    <child link="LFP3_2" />
    <axis xyz="0 0 -1" />
    <limit lower="-0.1" upper="0.5" effort="10" velocity="1"/>
    <dynamics damping="0.003" friction="0.003"/>
    <mimic joint="LFB3__LFP3_1" multiplier="1" offset="0.1"/>
  </joint>
  <xacro:mimic_joint_plugin_gazebo name_prefix="LFP3_1__LFP3_2_joint"
    parent_joint="LFB3__LFP3_1" mimic_joint="LFP3_1__LFP3_2"
    has_pid="false" multiplier="1.0" max_effort="10.0" offset="0.1" />

  <!-- ///////////////////////////////////////   Tip phalanx of the long finger   ////////////////////////////////////////// -->
  <link name="LFP3_3">
    <inertial>
      <origin xyz="0.012398348 -0.00034958691 0.000050212619" rpy="0 0 0" />
      <mass value="0.02226615" />
      <inertia ixx="1.7400409E-06" ixy="4.4309075E-07" ixz="-1.3771833E-08" iyy="6.8917616E-06" iyz="6.4562527E-09" izz="6.4653229E-06" />
    </inertial>
    <visual>
      <origin xyz="0 0 0" rpy="0 0 0" />
      <geometry>
        <mesh filename="package://ros_end_effector/configs/meshes/heri_II/LFP3_3.STL" />
      </geometry>
      <material name="">
        <color rgba="0.75294 0.75294 0.75294 1" />
      </material>
    </visual>
    <collision>
      <origin xyz="0 0 0" rpy="0 0 0" />
      <geometry>
        <mesh filename="package://ros_end_effector/configs/meshes/heri_II/LFP3_3.STL" />
      </geometry>
    </collision>
  </link>

  <!-- ///////////////////////////////////////   Joint of second and tip phalanxs of the long finger   ////////////////////////////////////////// -->
  <joint name="LFP3_2__LFP3_3" type="revolute">
    <origin xyz="0.035 0 0" rpy="0 0 0" />
    <parent link="LFP3_2" />
    <child link="LFP3_3" />
    <axis xyz="0 0 -1" />
    <limit lower="-0.1" upper="0.5" effort="10" velocity="1"/>
    <dynamics damping="0.003" friction="0.003"/>
    <mimic joint="LFB3__LFP3_1" multiplier="0.5" offset="0.2"/>
  </joint>

  <xacro:mimic_joint_plugin_gazebo name_prefix="LFP3_2__LFP3_3_joint"
    parent_joint="LFB3__LFP3_1" mimic_joint="LFP3_2__LFP3_3"
    has_pid="false" multiplier="0.5" max_effort="10.0" offset="0.2"/>

</robot>
