<?xml version="1.0" ?>
<!-- =================================================================================== -->
<!-- |    This document was autogenerated by xacro from onrobot_3fg15_model.xacro      | -->
<!-- |    EDITING THIS FILE BY HAND IS NOT RECOMMENDED                                 | -->
<!-- =================================================================================== -->
<robot name="onrobot_3fg15">
  <!-- ********* -->
  <!-- Arguments -->
  <!-- ********* -->
  <link name="robot_onrobot_3fg15_base_link">
    <inertial>
      <mass value="0.54"/>
      <origin rpy="0 0 0" xyz="0.0 0.0 0.0"/>
      <!-- <inertia ixx="0.000888868887021" ixy="-0.00012239074652" ixz="3.98699829666e-05" iyy="0.000888001373233" iyz="-9.33825115206e-05" izz="0.0007176834609"/> -->
      <inertia ixx="0.0010845" ixy="0.0" ixz="0.0" iyy="0.00009" iyz="0.0" izz="0.0010305"/>
    </inertial>
    <visual>
      <origin rpy="-1.5707963267948966 0 0" xyz="0 0 0.058"/>
      <geometry>
        <mesh filename="package://hrii_onrobot_3fg15_description/meshes/visual/onrobot_3fg15_base_link.dae"/>
      </geometry>
    </visual>
    <collision>
      <origin rpy="-1.5707963267948966 0 0" xyz="0 0 0.058"/>
      <geometry>
        <mesh filename="package://hrii_onrobot_3fg15_description/meshes/collision/onrobot_3fg15_base_link.stl"/>
      </geometry>
    </collision>
  </link>
  <link name="robot_onrobot_3fg15_finger1">
    <inertial>
      <mass value="0.01"/>
      <origin rpy="0 0 0" xyz="0.0 0.0 0.0"/>
      <inertia ixx="0.0000015" ixy="0" ixz="0" iyy="0.0000015" iyz="0" izz="0.0000015"/>
    </inertial>
    <visual>
      <origin rpy="-1.5707963267948966 0 0" xyz="0 0 0"/>
      <geometry>
        <mesh filename="package://hrii_onrobot_3fg15_description/meshes/visual/onrobot_3fg15_finger2.dae"/>
      </geometry>
    </visual>
    <collision>
      <origin rpy="-1.5707963267948966 0 0" xyz="0 0 0"/>
      <geometry>
        <mesh filename="package://hrii_onrobot_3fg15_description/meshes/collision/onrobot_3fg15_finger.stl"/>
      </geometry>
    </collision>
  </link>
  <link name="robot_onrobot_3fg15_finger2">
    <inertial>
      <mass value="0.01"/>
      <origin rpy="0 0 0" xyz="0.0 0.0 0.0"/>
      <inertia ixx="0.0000015" ixy="0" ixz="0" iyy="0.0000015" iyz="0" izz="0.0000015"/>
    </inertial>
    <visual>
      <origin rpy="-1.5707963267948966 0 0" xyz="0 0 0"/>
      <geometry>
        <mesh filename="package://hrii_onrobot_3fg15_description/meshes/visual/onrobot_3fg15_finger2.dae"/>
      </geometry>
    </visual>
    <collision>
      <origin rpy="-1.5707963267948966 0 0" xyz="0 0 0"/>
      <geometry>
        <mesh filename="package://hrii_onrobot_3fg15_description/meshes/collision/onrobot_3fg15_finger.stl"/>
      </geometry>
    </collision>
  </link>
  <link name="robot_onrobot_3fg15_finger3">
    <inertial>
      <mass value="0.01"/>
      <origin rpy="0 0 0" xyz="0.0 0.0 0.0"/>
      <inertia ixx="0.0000015" ixy="0" ixz="0" iyy="0.0000015" iyz="0" izz="0.0000015"/>
    </inertial>
    <visual>
      <origin rpy="-1.5707963267948966 0 0" xyz="0 0 0"/>
      <geometry>
        <mesh filename="package://hrii_onrobot_3fg15_description/meshes/visual/onrobot_3fg15_finger2.dae"/>
      </geometry>
    </visual>
    <collision>
      <origin rpy="-1.5707963267948966 0 0" xyz="0 0 0"/>
      <geometry>
        <mesh filename="package://hrii_onrobot_3fg15_description/meshes/collision/onrobot_3fg15_finger.stl"/>
      </geometry>
    </collision>
  </link>
  <joint name="robot_onrobot_3fg15_finger_joint1" type="revolute">
    <parent link="robot_onrobot_3fg15_base_link"/>
    <child link="robot_onrobot_3fg15_finger1"/>
    <origin rpy="0 0 -0.5236" xyz="-0.026 0.016 0.11"/>
    <axis xyz="0 0 1"/>
    <limit effort="20" lower="0.0" upper="2.8" velocity="3.0"/>
  </joint>
  <joint name="robot_onrobot_3fg15_finger_joint2" type="revolute">
    <parent link="robot_onrobot_3fg15_base_link"/>
    <child link="robot_onrobot_3fg15_finger2"/>
    <origin rpy="0 0 -2.61799" xyz="0.026 0.016 0.11"/>
    <axis xyz="0 0 1"/>
    <limit effort="20" lower="0.0" upper="2.8" velocity="3.0"/>
    <mimic joint="robot_onrobot_3fg15_finger_joint1"/>
  </joint>
  <joint name="robot_onrobot_3fg15_finger_joint3" type="revolute">
    <parent link="robot_onrobot_3fg15_base_link"/>
    <child link="robot_onrobot_3fg15_finger3"/>
    <origin rpy="0 0 1.5707963267948966" xyz="0.0 -0.0305 0.11"/>
    <axis xyz="0 0 1"/>
    <limit effort="20" lower="0.0" upper="2.8" velocity="3.0"/>
    <mimic joint="robot_onrobot_3fg15_finger_joint1"/>
  </joint>
  <transmission name="robot_onrobot_3fg15_finger_joint1_trans">
    <type>transmission_interface/SimpleTransmission</type>
    <joint name="robot_onrobot_3fg15_finger_joint1">
      <hardwareInterface>hardware_interface/EffortJointInterface</hardwareInterface>
    </joint>
    <actuator name="robot_onrobot_3fg15_finger_joint1_motor">
      <mechanicalReduction>1</mechanicalReduction>
    </actuator>
  </transmission>
  <link name="world"/>
  <joint name="onrobot_3fg15_joint_base_world" type="fixed">
    <parent link="world"/>
    <child link="robot_onrobot_3fg15_base_link"/>
    <origin rpy="0 0 0" xyz="0 0 0"/>
  </joint>
  <gazebo>
    <plugin filename="libroboticsgroup_upatras_gazebo_mimic_joint_plugin.so" name="robot_onrobot_3fg15_mimic_joint2">
      <joint>robot_onrobot_3fg15_finger_joint1</joint>
      <mimicJoint>robot_onrobot_3fg15_finger_joint2</mimicJoint>
    </plugin>
    <plugin filename="libroboticsgroup_upatras_gazebo_mimic_joint_plugin.so" name="robot_onrobot_3fg15_mimic_joint3">
      <joint>robot_onrobot_3fg15_finger_joint1</joint>
      <mimicJoint>robot_onrobot_3fg15_finger_joint3</mimicJoint>
    </plugin>
  </gazebo>
  <gazebo reference="robot_onrobot_3fg15_finger1">
    <material>Gazebo/Black</material>
    <selfCollide>True</selfCollide>
    <mu1>0.2</mu1>
    <mu2>0.2</mu2>
    <!-- <minDepth>0.001</minDepth>
            <maxVel>0.0</maxVel> -->
  </gazebo>
  <gazebo reference="robot_onrobot_3fg15_finger2">
    <material>Gazebo/Black</material>
    <selfCollide>True</selfCollide>
    <mu1>0.2</mu1>
    <mu2>0.2</mu2>
    <!-- <minDepth>0.001</minDepth>
            <maxVel>0.0</maxVel> -->
  </gazebo>
  <gazebo reference="robot_onrobot_3fg15_finger3">
    <material>Gazebo/Black</material>
    <selfCollide>True</selfCollide>
    <mu1>0.2</mu1>
    <mu2>0.2</mu2>
    <!-- <minDepth>0.001</minDepth>
            <maxVel>0.0</maxVel> -->
  </gazebo>
  <gazebo>
    <plugin filename="libgazebo_ros_control.so" name="gazebo_ros_control">
      <legacyModeNS>true</legacyModeNS>
      <robotNamespace>/robot</robotNamespace>
    </plugin>
  </gazebo>
</robot>
