<?xml version="1.0" ?>
<!-- =================================================================================== -->
<!-- |    This document was autogenerated by xacro from qbhand.urdf.xacro              | -->
<!-- |    EDITING THIS FILE BY HAND IS NOT RECOMMENDED                                 | -->
<!-- =================================================================================== -->
<robot name="qbhand" xmlns:xacro="http://www.ros.org/wiki/xacro">
  <material name="qbhand/optional">
    <color rgba="0.0 0.5 0.8 1.0"/>
  </material>
  <material name="qbhand/base">
    <color rgba="0.35 0.35 0.35 1.0"/>
  </material>
  <material name="qbhand/palm">
    <color rgba="0.35 0.35 0.35 1.0"/>
  </material>
  <material name="qbhand/knuckle">
    <color rgba="0.35 0.35 0.35 1.0"/>
  </material>
  <material name="qbhand/proximal">
    <color rgba="0.35 0.35 0.35 1.0"/>
  </material>
  <material name="qbhand/middle">
    <color rgba="0.35 0.35 0.35 1.0"/>
  </material>
  <material name="qbhand/distal">
    <color rgba="0.35 0.35 0.35 1.0"/>
  </material>
  <material name="qbhand/default">
    <color rgba="0.35 0.35 0.35 1.0"/>
  </material>
  
  <link name="world"/>
  <joint name="virtualFixed" type="fixed">
    <parent link="world"/>
    <child link="root_link"/>
  </joint>
  
  <link name="root_link"/>
  <joint name="qbhand_base_fixed_joint" type="fixed">
    <origin rpy="0 0 0" xyz="0 0 0"/>
    <parent link="root_link"/>
    <child link="qbhand_base_link"/>
  </joint>
  <link name="qbhand_base_link">
    <inertial>
      <mass value="0.15"/>
      <origin xyz="0 0 0.0015"/>
      <inertia ixx="6e-01" ixy="0" ixz="0" iyy="6e-01" iyz="0" izz="9e-01"/>
    </inertial>
    <visual>
      <origin rpy="0 0 0" xyz="0 0 0"/>
      <geometry>
        <mesh filename="package://qb_hand_description/meshes/flange_iso_04.stl" scale="0.001 0.001 0.001"/>
      </geometry>
      <material name="qbhand/base"/>
    </visual>
    <collision>
      <origin rpy="0 0 0" xyz="0 0 0"/>
      <geometry>
        <mesh filename="package://qb_hand_description/meshes/flange_iso_04.stl" scale="0.001 0.001 0.001"/>
      </geometry>
    </collision>
  </link>
  <joint name="qbhand_palm_fixed_joint" type="fixed">
    <origin rpy="1.57 0 0" xyz="-0.0045 0.0145 0.144"/>
    <parent link="qbhand_base_link"/>
    <child link="qbhand_palm_link"/>
  </joint>
  <link name="qbhand_palm_link">
    <inertial>
      <mass value="0.36"/>
      <origin xyz="0.0 0.02 0.05"/>
      <inertia ixx="0.00045" ixy="0.0" ixz="0.0" iyy="0.0006" iyz="0.0" izz="0.00025"/>
    </inertial>
    <visual>
      <origin rpy="0 0 0" xyz="0 0 0"/>
      <geometry>
        <mesh filename="package://qb_hand_description/meshes/palm_pinch_r.stl" scale="0.001 0.001 0.001"/>
      </geometry>
      <material name="qbhand/palm"/>
    </visual>
    <collision>
      <origin rpy="0 0 0" xyz="0 0 0"/>
      <geometry>
        <mesh filename="package://qb_hand_description/meshes/palm_pinch_r.stl" scale="0.001 0.001 0.001"/>
      </geometry>
    </collision>
  </link>
  <joint name="qbhand_synergy_joint" type="revolute">
    <origin rpy="0 0 0" xyz="0 0 0"/>
    <parent link="qbhand_palm_link"/>
    <child link="qbhand_tendon_virtual_link"/>
    <axis xyz="0 0 1"/>
    <dynamics damping="0.0" friction="0.0"/>
    <limit effort="100" lower="0.0" upper="1.0" velocity="100"/>
  </joint>
  <link name="qbhand_tendon_virtual_link">
    <inertial>
      <origin rpy="0 0 0" xyz="0 0 0"/>
      <mass value="0.01"/>
      <inertia ixx="1e-03" ixy="0.0" ixz="0.0" iyy="1e-03" iyz="0.0" izz="1e-03"/>
    </inertial>
  </link>
  <joint name="qbhand_thumb_knuckle_joint" type="revolute">
    <origin rpy="-1.57 3.14 0" xyz="-0.0435 -0.0435 -0.002"/>
    <parent link="qbhand_palm_link"/>
    <child link="qbhand_thumb_knuckle_link"/>
    <axis xyz="0 0 -1"/>
    <dynamics damping="0.0" friction="0.0"/>
    <limit effort="100" lower="0.0" upper="1.571" velocity="100"/>
    <mimic joint="qbhand_synergy_joint" multiplier="2.542"/>
  </joint>
  <gazebo>
    <plugin filename="libroboticsgroup_gazebo_mimic_joint_plugin.so" name="qbhand_thumb_knuckle_joint_jointmimic_joint_plugin">
      <joint>qbhand_synergy_joint</joint>
      <mimicJoint>qbhand_thumb_knuckle_joint</mimicJoint>
      <multiplier>2.542</multiplier>
      <offset>0</offset>
      <sensitiveness>0.0</sensitiveness>
      <!-- if absolute difference between setpoint and process value is below this threshold, do nothing; 0.0 = disable [rad] -->
      <maxEffort>100</maxEffort>
    </plugin>
  </gazebo>
  <link name="qbhand_thumb_knuckle_link">
    <inertial>
      <mass value="0.01"/>
      <origin xyz="0 0 0"/>
      <inertia ixx="1e-02" ixy="0.0" ixz="0.0" iyy="1e-02" iyz="0.0" izz="1e-02"/>
    </inertial>
    <visual>
      <origin rpy="0 0 0" xyz="0 0 0"/>
      <geometry>
        <mesh filename="package://qb_hand_description/meshes/ph_thumb_r.stl" scale="0.001 0.001 0.001"/>
      </geometry>
      <material name="qbhand/knuckle"/>
    </visual>
    <collision>
      <origin rpy="0 0 0" xyz="0 0 0"/>
      <geometry>
        <mesh filename="package://qb_hand_description/meshes/ph_thumb_r.stl" scale="0.001 0.001 0.001"/>
      </geometry>
    </collision>
  </link>
  <joint name="qbhand_thumb_proximal_joint" type="revolute">
    <origin rpy="-1.15 0.0 0.0" xyz="0.0255 -0.004 -0.0025"/>
    <parent link="qbhand_thumb_knuckle_link"/>
    <child link="qbhand_thumb_proximal_virtual_link"/>
    <axis xyz="0 0 -1"/>
    <dynamics damping="0.0" friction="0.0"/>
    <limit effort="100" lower="0.0" upper="0.785" velocity="100"/>
    <mimic joint="qbhand_synergy_joint" multiplier="0.785"/>
  </joint>
  <gazebo>
    <plugin filename="libroboticsgroup_gazebo_mimic_joint_plugin.so" name="qbhand_thumb_proximal_joint_jointmimic_joint_plugin">
      <joint>qbhand_synergy_joint</joint>
      <mimicJoint>qbhand_thumb_proximal_joint</mimicJoint>
      <multiplier>0.785</multiplier>
      <offset>0</offset>
      <sensitiveness>0.0</sensitiveness>
      <!-- if absolute difference between setpoint and process value is below this threshold, do nothing; 0.0 = disable [rad] -->
      <maxEffort>100</maxEffort>
    </plugin>
  </gazebo>
  <link name="qbhand_thumb_proximal_virtual_link">
    <inertial>
      <origin rpy="0 0 0" xyz="0 0 0"/>
      <mass value="0.01"/>
      <inertia ixx="1e-03" ixy="0.0" ixz="0.0" iyy="1e-03" iyz="0.0" izz="1e-03"/>
    </inertial>
  </link>
  <joint name="qbhand_thumb_proximal_virtual_joint" type="revolute">
    <origin rpy="0 0 0" xyz="0.013 0 0"/>
    <parent link="qbhand_thumb_proximal_virtual_link"/>
    <child link="qbhand_thumb_proximal_link"/>
    <axis xyz="0 0 -1"/>
    <dynamics damping="0.0" friction="0.0"/>
    <limit effort="100" lower="0.0" upper="0.785" velocity="100"/>
    <mimic joint="qbhand_thumb_proximal_joint" multiplier="1.0"/>
  </joint>
  <gazebo>
    <plugin filename="libroboticsgroup_gazebo_mimic_joint_plugin.so" name="qbhand_thumb_proximal_virtual_joint_jointmimic_joint_plugin">
      <joint>qbhand_synergy_joint</joint>
      <mimicJoint>qbhand_thumb_proximal_virtual_joint</mimicJoint>
      <multiplier>1.0</multiplier>
      <offset>0</offset>
      <sensitiveness>0.0</sensitiveness>
      <!-- if absolute difference between setpoint and process value is below this threshold, do nothing; 0.0 = disable [rad] -->
      <maxEffort>100</maxEffort>
    </plugin>
  </gazebo>
  <link name="qbhand_thumb_proximal_link">
    <inertial>
      <mass value="0.01"/>
      <origin xyz="0 0 0"/>
      <inertia ixx="1e-02" ixy="0.0" ixz="0.0" iyy="1e-02" iyz="0.0" izz="1e-02"/>
    </inertial>
    <visual>
      <origin rpy="0 0 0" xyz="0 0 0"/>
      <geometry>
        <mesh filename="package://qb_hand_description/meshes/ph_small.stl" scale="0.001 0.001 0.001"/>
      </geometry>
      <material name="qbhand/proximal"/>
    </visual>
    <collision>
      <origin rpy="0 0 0" xyz="0 0 0"/>
      <geometry>
        <mesh filename="package://qb_hand_description/meshes/ph_small.stl" scale="0.001 0.001 0.001"/>
      </geometry>
    </collision>
  </link>
  <joint name="qbhand_thumb_distal_joint" type="revolute">
    <origin rpy="0 0 0" xyz="0.009 0 0"/>
    <parent link="qbhand_thumb_proximal_link"/>
    <child link="qbhand_thumb_distal_virtual_link"/>
    <axis xyz="0 0 -1"/>
    <dynamics damping="0.0" friction="0.0"/>
    <limit effort="100" lower="0.0" upper="0.785" velocity="100"/>
    <mimic joint="qbhand_synergy_joint" multiplier="0.785"/>
  </joint>
  <gazebo>
    <plugin filename="libroboticsgroup_gazebo_mimic_joint_plugin.so" name="qbhand_thumb_distal_joint_jointmimic_joint_plugin">
      <joint>qbhand_synergy_joint</joint>
      <mimicJoint>qbhand_thumb_distal_joint</mimicJoint>
      <multiplier>0.785</multiplier>
      <offset>0</offset>
      <sensitiveness>0.0</sensitiveness>
      <!-- if absolute difference between setpoint and process value is below this threshold, do nothing; 0.0 = disable [rad] -->
      <maxEffort>100</maxEffort>
    </plugin>
  </gazebo>
  <link name="qbhand_thumb_distal_virtual_link">
    <inertial>
      <origin rpy="0 0 0" xyz="0 0 0"/>
      <mass value="0.01"/>
      <inertia ixx="1e-03" ixy="0.0" ixz="0.0" iyy="1e-03" iyz="0.0" izz="1e-03"/>
    </inertial>
  </link>
  <joint name="qbhand_thumb_distal_virtual_joint" type="revolute">
    <origin rpy="0 0 0" xyz="0.013 0 0"/>
    <parent link="qbhand_thumb_distal_virtual_link"/>
    <child link="qbhand_thumb_distal_link"/>
    <axis xyz="0 0 -1"/>
    <dynamics damping="0.0" friction="0.0"/>
    <limit effort="100" lower="0.0" upper="0.785" velocity="100"/>
    <mimic joint="qbhand_thumb_distal_joint" multiplier="1.0"/>
  </joint>
  <gazebo>
    <plugin filename="libroboticsgroup_gazebo_mimic_joint_plugin.so" name="qbhand_thumb_distal_virtual_joint_jointmimic_joint_plugin">
      <joint>qbhand_synergy_joint</joint>
      <mimicJoint>qbhand_thumb_distal_virtual_joint</mimicJoint>
      <multiplier>1.0</multiplier>
      <offset>0</offset>
      <sensitiveness>0.0</sensitiveness>
      <!-- if absolute difference between setpoint and process value is below this threshold, do nothing; 0.0 = disable [rad] -->
      <maxEffort>100</maxEffort>
    </plugin>
  </gazebo>
  <link name="qbhand_thumb_distal_link">
    <inertial>
      <mass value="0.01"/>
      <origin xyz="0 0 0"/>
      <inertia ixx="1e-02" ixy="0.0" ixz="0.0" iyy="1e-02" iyz="0.0" izz="1e-02"/>
    </inertial>
    <visual>
      <origin rpy="0 0 0" xyz="0 0 0"/>
      <geometry>
        <mesh filename="package://qb_hand_description/meshes/ph_distal.stl" scale="0.001 0.001 0.001"/>
      </geometry>
      <material name="qbhand/distal"/>
    </visual>
    <collision>
      <origin rpy="0 0 0" xyz="0 0 0"/>
      <geometry>
        <mesh filename="package://qb_hand_description/meshes/ph_distal.stl" scale="0.001 0.001 0.001"/>
      </geometry>
    </collision>
  </link>
  <joint name="qbhand_index_knuckle_joint" type="revolute">
    <origin rpy="0 0 0" xyz="-0.02 -0.007 0.014"/>
    <parent link="qbhand_palm_link"/>
    <child link="qbhand_index_knuckle_link"/>
    <axis xyz="0 0 -1"/>
    <dynamics damping="0.0" friction="0.0"/>
    <limit effort="100" lower="-0.524" upper="0.524" velocity="100"/>
    <mimic joint="qbhand_synergy_joint" multiplier="-0.2"/>
  </joint>
  <gazebo>
    <plugin filename="libroboticsgroup_gazebo_mimic_joint_plugin.so" name="qbhand_index_knuckle_joint_jointmimic_joint_plugin">
      <joint>qbhand_synergy_joint</joint>
      <mimicJoint>qbhand_index_knuckle_joint</mimicJoint>
      <multiplier>-0.2</multiplier>
      <offset>0</offset>
      <sensitiveness>0.0</sensitiveness>
      <!-- if absolute difference between setpoint and process value is below this threshold, do nothing; 0.0 = disable [rad] -->
      <maxEffort>100</maxEffort>
    </plugin>
  </gazebo>
  <link name="qbhand_index_knuckle_link">
    <inertial>
      <mass value="0.01"/>
      <origin xyz="0 0 0"/>
      <inertia ixx="1e-02" ixy="0.0" ixz="0.0" iyy="1e-02" iyz="0.0" izz="1e-02"/>
    </inertial>
    <visual>
      <origin rpy="0 0 0" xyz="0 0 0"/>
      <geometry>
        <mesh filename="package://qb_hand_description/meshes/ph_knuckle.stl" scale="0.001 0.001 0.001"/>
      </geometry>
      <material name="qbhand/knuckle"/>
    </visual>
    <collision>
      <origin rpy="0 0 0" xyz="0 0 0"/>
      <geometry>
        <mesh filename="package://qb_hand_description/meshes/ph_knuckle.stl" scale="0.001 0.001 0.001"/>
      </geometry>
    </collision>
  </link>
  <joint name="qbhand_index_proximal_joint" type="revolute">
    <origin rpy="1.57 0 1.57" xyz="0 0.009 0"/>
    <parent link="qbhand_index_knuckle_link"/>
    <child link="qbhand_index_proximal_virtual_link"/>
    <axis xyz="0 0 -1"/>
    <dynamics damping="0.0" friction="0.0"/>
    <limit effort="100" lower="0.0" upper="0.785" velocity="100"/>
    <mimic joint="qbhand_synergy_joint" multiplier="0.785"/>
  </joint>
  <gazebo>
    <plugin filename="libroboticsgroup_gazebo_mimic_joint_plugin.so" name="qbhand_index_proximal_joint_jointmimic_joint_plugin">
      <joint>qbhand_synergy_joint</joint>
      <mimicJoint>qbhand_index_proximal_joint</mimicJoint>
      <multiplier>0.785</multiplier>
      <offset>0</offset>
      <sensitiveness>0.0</sensitiveness>
      <!-- if absolute difference between setpoint and process value is below this threshold, do nothing; 0.0 = disable [rad] -->
      <maxEffort>100</maxEffort>
    </plugin>
  </gazebo>
  <link name="qbhand_index_proximal_virtual_link">
    <inertial>
      <origin rpy="0 0 0" xyz="0 0 0"/>
      <mass value="0.01"/>
      <inertia ixx="1e-03" ixy="0.0" ixz="0.0" iyy="1e-03" iyz="0.0" izz="1e-03"/>
    </inertial>
  </link>
  <joint name="qbhand_index_proximal_virtual_joint" type="revolute">
    <origin rpy="0 0 0" xyz="0.013 0 0"/>
    <parent link="qbhand_index_proximal_virtual_link"/>
    <child link="qbhand_index_proximal_link"/>
    <axis xyz="0 0 -1"/>
    <dynamics damping="0.0" friction="0.0"/>
    <limit effort="100" lower="0.0" upper="0.785" velocity="100"/>
    <mimic joint="qbhand_index_proximal_joint" multiplier="1.0"/>
  </joint>
  <gazebo>
    <plugin filename="libroboticsgroup_gazebo_mimic_joint_plugin.so" name="qbhand_index_proximal_virtual_joint_jointmimic_joint_plugin">
      <joint>qbhand_synergy_joint</joint>
      <mimicJoint>qbhand_index_proximal_virtual_joint</mimicJoint>
      <multiplier>1.0</multiplier>
      <offset>0</offset>
      <sensitiveness>0.0</sensitiveness>
      <!-- if absolute difference between setpoint and process value is below this threshold, do nothing; 0.0 = disable [rad] -->
      <maxEffort>100</maxEffort>
    </plugin>
  </gazebo>
  <link name="qbhand_index_proximal_link">
    <inertial>
      <mass value="0.01"/>
      <origin xyz="0 0 0"/>
      <inertia ixx="1e-02" ixy="0.0" ixz="0.0" iyy="1e-02" iyz="0.0" izz="1e-02"/>
    </inertial>
    <visual>
      <origin rpy="0 0 0" xyz="0 0 0"/>
      <geometry>
        <mesh filename="package://qb_hand_description/meshes/ph_medium.stl" scale="0.001 0.001 0.001"/>
      </geometry>
      <material name="qbhand/proximal"/>
    </visual>
    <collision>
      <origin rpy="0 0 0" xyz="0 0 0"/>
      <geometry>
        <mesh filename="package://qb_hand_description/meshes/ph_medium.stl" scale="0.001 0.001 0.001"/>
      </geometry>
    </collision>
  </link>
  <joint name="qbhand_index_middle_joint" type="revolute">
    <origin rpy="0 0 0" xyz="0.017 0 0"/>
    <parent link="qbhand_index_proximal_link"/>
    <child link="qbhand_index_middle_virtual_link"/>
    <axis xyz="0 0 -1"/>
    <dynamics damping="0.0" friction="0.0"/>
    <limit effort="100" lower="0.0" upper="0.785" velocity="100"/>
    <mimic joint="qbhand_synergy_joint" multiplier="0.785"/>
  </joint>
  <gazebo>
    <plugin filename="libroboticsgroup_gazebo_mimic_joint_plugin.so" name="qbhand_index_middle_joint_jointmimic_joint_plugin">
      <joint>qbhand_synergy_joint</joint>
      <mimicJoint>qbhand_index_middle_joint</mimicJoint>
      <multiplier>0.785</multiplier>
      <offset>0</offset>
      <sensitiveness>0.0</sensitiveness>
      <!-- if absolute difference between setpoint and process value is below this threshold, do nothing; 0.0 = disable [rad] -->
      <maxEffort>100</maxEffort>
    </plugin>
  </gazebo>
  <link name="qbhand_index_middle_virtual_link">
    <inertial>
      <origin rpy="0 0 0" xyz="0 0 0"/>
      <mass value="0.01"/>
      <inertia ixx="1e-03" ixy="0.0" ixz="0.0" iyy="1e-03" iyz="0.0" izz="1e-03"/>
    </inertial>
  </link>
  <joint name="qbhand_index_middle_virtual_joint" type="revolute">
    <origin rpy="0 0 0" xyz="0.013 0 0"/>
    <parent link="qbhand_index_middle_virtual_link"/>
    <child link="qbhand_index_middle_link"/>
    <axis xyz="0 0 -1"/>
    <dynamics damping="0.0" friction="0.0"/>
    <limit effort="100" lower="0.0" upper="0.785" velocity="100"/>
    <mimic joint="qbhand_index_middle_joint" multiplier="1.0"/>
  </joint>
  <gazebo>
    <plugin filename="libroboticsgroup_gazebo_mimic_joint_plugin.so" name="qbhand_index_middle_virtual_joint_jointmimic_joint_plugin">
      <joint>qbhand_synergy_joint</joint>
      <mimicJoint>qbhand_index_middle_virtual_joint</mimicJoint>
      <multiplier>1.0</multiplier>
      <offset>0</offset>
      <sensitiveness>0.0</sensitiveness>
      <!-- if absolute difference between setpoint and process value is below this threshold, do nothing; 0.0 = disable [rad] -->
      <maxEffort>100</maxEffort>
    </plugin>
  </gazebo>
  <link name="qbhand_index_middle_link">
    <inertial>
      <mass value="0.01"/>
      <origin xyz="0 0 0"/>
      <inertia ixx="1e-02" ixy="0.0" ixz="0.0" iyy="1e-02" iyz="0.0" izz="1e-02"/>
    </inertial>
    <visual>
      <origin rpy="0 0 0" xyz="0 0 0"/>
      <geometry>
        <mesh filename="package://qb_hand_description/meshes/ph_small.stl" scale="0.001 0.001 0.001"/>
      </geometry>
      <material name="qbhand/middle"/>
    </visual>
    <collision>
      <origin rpy="0 0 0" xyz="0 0 0"/>
      <geometry>
        <mesh filename="package://qb_hand_description/meshes/ph_small.stl" scale="0.001 0.001 0.001"/>
      </geometry>
    </collision>
  </link>
  <joint name="qbhand_index_distal_joint" type="revolute">
    <origin rpy="0 0 0" xyz="0.009 0 0"/>
    <parent link="qbhand_index_middle_link"/>
    <child link="qbhand_index_distal_virtual_link"/>
    <axis xyz="0 0 -1"/>
    <dynamics damping="0.0" friction="0.0"/>
    <limit effort="100" lower="0.0" upper="0.785" velocity="100"/>
    <mimic joint="qbhand_synergy_joint" multiplier="0.785"/>
  </joint>
  <gazebo>
    <plugin filename="libroboticsgroup_gazebo_mimic_joint_plugin.so" name="qbhand_index_distal_joint_jointmimic_joint_plugin">
      <joint>qbhand_synergy_joint</joint>
      <mimicJoint>qbhand_index_distal_joint</mimicJoint>
      <multiplier>0.785</multiplier>
      <offset>0</offset>
      <sensitiveness>0.0</sensitiveness>
      <!-- if absolute difference between setpoint and process value is below this threshold, do nothing; 0.0 = disable [rad] -->
      <maxEffort>100</maxEffort>
    </plugin>
  </gazebo>
  <link name="qbhand_index_distal_virtual_link">
    <inertial>
      <origin rpy="0 0 0" xyz="0 0 0"/>
      <mass value="0.01"/>
      <inertia ixx="1e-03" ixy="0.0" ixz="0.0" iyy="1e-03" iyz="0.0" izz="1e-03"/>
    </inertial>
  </link>
  <joint name="qbhand_index_distal_virtual_joint" type="revolute">
    <origin rpy="0 0 0" xyz="0.013 0 0"/>
    <parent link="qbhand_index_distal_virtual_link"/>
    <child link="qbhand_index_distal_link"/>
    <axis xyz="0 0 -1"/>
    <dynamics damping="0.0" friction="0.0"/>
    <limit effort="100" lower="0.0" upper="0.785" velocity="100"/>
    <mimic joint="qbhand_index_distal_joint" multiplier="1.0"/>
  </joint>
  <gazebo>
    <plugin filename="libroboticsgroup_gazebo_mimic_joint_plugin.so" name="qbhand_index_distal_virtual_joint_jointmimic_joint_plugin">
      <joint>qbhand_synergy_joint</joint>
      <mimicJoint>qbhand_index_distal_virtual_joint</mimicJoint>
      <multiplier>1.0</multiplier>
      <offset>0</offset>
      <sensitiveness>0.0</sensitiveness>
      <!-- if absolute difference between setpoint and process value is below this threshold, do nothing; 0.0 = disable [rad] -->
      <maxEffort>100</maxEffort>
    </plugin>
  </gazebo>
  <link name="qbhand_index_distal_link">
    <inertial>
      <mass value="0.01"/>
      <origin xyz="0 0 0"/>
      <inertia ixx="1e-02" ixy="0.0" ixz="0.0" iyy="1e-02" iyz="0.0" izz="1e-02"/>
    </inertial>
    <visual>
      <origin rpy="0 0 0" xyz="0 0 0"/>
      <geometry>
        <mesh filename="package://qb_hand_description/meshes/ph_distal.stl" scale="0.001 0.001 0.001"/>
      </geometry>
      <material name="qbhand/distal"/>
    </visual>
    <collision>
      <origin rpy="0 0 0" xyz="0 0 0"/>
      <geometry>
        <mesh filename="package://qb_hand_description/meshes/ph_distal.stl" scale="0.001 0.001 0.001"/>
      </geometry>
    </collision>
  </link>
  <joint name="qbhand_middle_knuckle_joint" type="revolute">
    <origin rpy="0 0 0" xyz="0 0 0.014"/>
    <parent link="qbhand_palm_link"/>
    <child link="qbhand_middle_knuckle_link"/>
    <axis xyz="0 0 -1"/>
    <dynamics damping="0.0" friction="0.0"/>
    <limit effort="100" lower="-0.524" upper="0.524" velocity="100"/>
    <mimic joint="qbhand_synergy_joint" multiplier="0.0"/>
  </joint>
  <gazebo>
    <plugin filename="libroboticsgroup_gazebo_mimic_joint_plugin.so" name="qbhand_middle_knuckle_joint_jointmimic_joint_plugin">
      <joint>qbhand_synergy_joint</joint>
      <mimicJoint>qbhand_middle_knuckle_joint</mimicJoint>
      <multiplier>0.0</multiplier>
      <offset>0</offset>
      <sensitiveness>0.0</sensitiveness>
      <!-- if absolute difference between setpoint and process value is below this threshold, do nothing; 0.0 = disable [rad] -->
      <maxEffort>100</maxEffort>
    </plugin>
  </gazebo>
  <link name="qbhand_middle_knuckle_link">
    <inertial>
      <mass value="0.01"/>
      <origin xyz="0 0 0"/>
      <inertia ixx="1e-02" ixy="0.0" ixz="0.0" iyy="1e-02" iyz="0.0" izz="1e-02"/>
    </inertial>
    <visual>
      <origin rpy="0 0 0" xyz="0 0 0"/>
      <geometry>
        <mesh filename="package://qb_hand_description/meshes/ph_knuckle.stl" scale="0.001 0.001 0.001"/>
      </geometry>
      <material name="qbhand/knuckle"/>
    </visual>
    <collision>
      <origin rpy="0 0 0" xyz="0 0 0"/>
      <geometry>
        <mesh filename="package://qb_hand_description/meshes/ph_knuckle.stl" scale="0.001 0.001 0.001"/>
      </geometry>
    </collision>
  </link>
  <joint name="qbhand_middle_proximal_joint" type="revolute">
    <origin rpy="1.57 0 1.57" xyz="0 0.009 0"/>
    <parent link="qbhand_middle_knuckle_link"/>
    <child link="qbhand_middle_proximal_virtual_link"/>
    <axis xyz="0 0 -1"/>
    <dynamics damping="0.0" friction="0.0"/>
    <limit effort="100" lower="0.0" upper="0.785" velocity="100"/>
    <mimic joint="qbhand_synergy_joint" multiplier="0.785"/>
  </joint>
  <gazebo>
    <plugin filename="libroboticsgroup_gazebo_mimic_joint_plugin.so" name="qbhand_middle_proximal_joint_jointmimic_joint_plugin">
      <joint>qbhand_synergy_joint</joint>
      <mimicJoint>qbhand_middle_proximal_joint</mimicJoint>
      <multiplier>0.785</multiplier>
      <offset>0</offset>
      <sensitiveness>0.0</sensitiveness>
      <!-- if absolute difference between setpoint and process value is below this threshold, do nothing; 0.0 = disable [rad] -->
      <maxEffort>100</maxEffort>
    </plugin>
  </gazebo>
  <link name="qbhand_middle_proximal_virtual_link">
    <inertial>
      <origin rpy="0 0 0" xyz="0 0 0"/>
      <mass value="0.01"/>
      <inertia ixx="1e-03" ixy="0.0" ixz="0.0" iyy="1e-03" iyz="0.0" izz="1e-03"/>
    </inertial>
  </link>
  <joint name="qbhand_middle_proximal_virtual_joint" type="revolute">
    <origin rpy="0 0 0" xyz="0.013 0 0"/>
    <parent link="qbhand_middle_proximal_virtual_link"/>
    <child link="qbhand_middle_proximal_link"/>
    <axis xyz="0 0 -1"/>
    <dynamics damping="0.0" friction="0.0"/>
    <limit effort="100" lower="0.0" upper="0.785" velocity="100"/>
    <mimic joint="qbhand_middle_proximal_joint" multiplier="1.0"/>
  </joint>
  <gazebo>
    <plugin filename="libroboticsgroup_gazebo_mimic_joint_plugin.so" name="qbhand_middle_proximal_virtual_joint_jointmimic_joint_plugin">
      <joint>qbhand_synergy_joint</joint>
      <mimicJoint>qbhand_middle_proximal_virtual_joint</mimicJoint>
      <multiplier>1.0</multiplier>
      <offset>0</offset>
      <sensitiveness>0.0</sensitiveness>
      <!-- if absolute difference between setpoint and process value is below this threshold, do nothing; 0.0 = disable [rad] -->
      <maxEffort>100</maxEffort>
    </plugin>
  </gazebo>
  <link name="qbhand_middle_proximal_link">
    <inertial>
      <mass value="0.01"/>
      <origin xyz="0 0 0"/>
      <inertia ixx="1e-02" ixy="0.0" ixz="0.0" iyy="1e-02" iyz="0.0" izz="1e-02"/>
    </inertial>
    <visual>
      <origin rpy="0 0 0" xyz="0 0 0"/>
      <geometry>
        <mesh filename="package://qb_hand_description/meshes/ph_medium.stl" scale="0.001 0.001 0.001"/>
      </geometry>
      <material name="qbhand/proximal"/>
    </visual>
    <collision>
      <origin rpy="0 0 0" xyz="0 0 0"/>
      <geometry>
        <mesh filename="package://qb_hand_description/meshes/ph_medium.stl" scale="0.001 0.001 0.001"/>
      </geometry>
    </collision>
  </link>
  <joint name="qbhand_middle_middle_joint" type="revolute">
    <origin rpy="0 0 0" xyz="0.017 0 0"/>
    <parent link="qbhand_middle_proximal_link"/>
    <child link="qbhand_middle_middle_virtual_link"/>
    <axis xyz="0 0 -1"/>
    <dynamics damping="0.0" friction="0.0"/>
    <limit effort="100" lower="0.0" upper="0.785" velocity="100"/>
    <mimic joint="qbhand_synergy_joint" multiplier="0.785"/>
  </joint>
  <gazebo>
    <plugin filename="libroboticsgroup_gazebo_mimic_joint_plugin.so" name="qbhand_middle_middle_joint_jointmimic_joint_plugin">
      <joint>qbhand_synergy_joint</joint>
      <mimicJoint>qbhand_middle_middle_joint</mimicJoint>
      <multiplier>0.785</multiplier>
      <offset>0</offset>
      <sensitiveness>0.0</sensitiveness>
      <!-- if absolute difference between setpoint and process value is below this threshold, do nothing; 0.0 = disable [rad] -->
      <maxEffort>100</maxEffort>
    </plugin>
  </gazebo>
  <link name="qbhand_middle_middle_virtual_link">
    <inertial>
      <origin rpy="0 0 0" xyz="0 0 0"/>
      <mass value="0.01"/>
      <inertia ixx="1e-03" ixy="0.0" ixz="0.0" iyy="1e-03" iyz="0.0" izz="1e-03"/>
    </inertial>
  </link>
  <joint name="qbhand_middle_middle_virtual_joint" type="revolute">
    <origin rpy="0 0 0" xyz="0.013 0 0"/>
    <parent link="qbhand_middle_middle_virtual_link"/>
    <child link="qbhand_middle_middle_link"/>
    <axis xyz="0 0 -1"/>
    <dynamics damping="0.0" friction="0.0"/>
    <limit effort="100" lower="0.0" upper="0.785" velocity="100"/>
    <mimic joint="qbhand_middle_middle_joint" multiplier="1.0"/>
  </joint>
  <gazebo>
    <plugin filename="libroboticsgroup_gazebo_mimic_joint_plugin.so" name="qbhand_middle_middle_virtual_joint_jointmimic_joint_plugin">
      <joint>qbhand_synergy_joint</joint>
      <mimicJoint>qbhand_middle_middle_virtual_joint</mimicJoint>
      <multiplier>1.0</multiplier>
      <offset>0</offset>
      <sensitiveness>0.0</sensitiveness>
      <!-- if absolute difference between setpoint and process value is below this threshold, do nothing; 0.0 = disable [rad] -->
      <maxEffort>100</maxEffort>
    </plugin>
  </gazebo>
  <link name="qbhand_middle_middle_link">
    <inertial>
      <mass value="0.01"/>
      <origin xyz="0 0 0"/>
      <inertia ixx="1e-02" ixy="0.0" ixz="0.0" iyy="1e-02" iyz="0.0" izz="1e-02"/>
    </inertial>
    <visual>
      <origin rpy="0 0 0" xyz="0 0 0"/>
      <geometry>
        <mesh filename="package://qb_hand_description/meshes/ph_small.stl" scale="0.001 0.001 0.001"/>
      </geometry>
      <material name="qbhand/middle"/>
    </visual>
    <collision>
      <origin rpy="0 0 0" xyz="0 0 0"/>
      <geometry>
        <mesh filename="package://qb_hand_description/meshes/ph_small.stl" scale="0.001 0.001 0.001"/>
      </geometry>
    </collision>
  </link>
  <joint name="qbhand_middle_distal_joint" type="revolute">
    <origin rpy="0 0 0" xyz="0.009 0 0"/>
    <parent link="qbhand_middle_middle_link"/>
    <child link="qbhand_middle_distal_virtual_link"/>
    <axis xyz="0 0 -1"/>
    <dynamics damping="0.0" friction="0.0"/>
    <limit effort="100" lower="0.0" upper="0.785" velocity="100"/>
    <mimic joint="qbhand_synergy_joint" multiplier="0.785"/>
  </joint>
  <gazebo>
    <plugin filename="libroboticsgroup_gazebo_mimic_joint_plugin.so" name="qbhand_middle_distal_joint_jointmimic_joint_plugin">
      <joint>qbhand_synergy_joint</joint>
      <mimicJoint>qbhand_middle_distal_joint</mimicJoint>
      <multiplier>0.785</multiplier>
      <offset>0</offset>
      <sensitiveness>0.0</sensitiveness>
      <!-- if absolute difference between setpoint and process value is below this threshold, do nothing; 0.0 = disable [rad] -->
      <maxEffort>100</maxEffort>
    </plugin>
  </gazebo>
  <link name="qbhand_middle_distal_virtual_link">
    <inertial>
      <origin rpy="0 0 0" xyz="0 0 0"/>
      <mass value="0.01"/>
      <inertia ixx="1e-03" ixy="0.0" ixz="0.0" iyy="1e-03" iyz="0.0" izz="1e-03"/>
    </inertial>
  </link>
  <joint name="qbhand_middle_distal_virtual_joint" type="revolute">
    <origin rpy="0 0 0" xyz="0.013 0 0"/>
    <parent link="qbhand_middle_distal_virtual_link"/>
    <child link="qbhand_middle_distal_link"/>
    <axis xyz="0 0 -1"/>
    <dynamics damping="0.0" friction="0.0"/>
    <limit effort="100" lower="0.0" upper="0.785" velocity="100"/>
    <mimic joint="qbhand_middle_distal_joint" multiplier="1.0"/>
  </joint>
  <gazebo>
    <plugin filename="libroboticsgroup_gazebo_mimic_joint_plugin.so" name="qbhand_middle_distal_virtual_joint_jointmimic_joint_plugin">
      <joint>qbhand_synergy_joint</joint>
      <mimicJoint>qbhand_middle_distal_virtual_joint</mimicJoint>
      <multiplier>1.0</multiplier>
      <offset>0</offset>
      <sensitiveness>0.0</sensitiveness>
      <!-- if absolute difference between setpoint and process value is below this threshold, do nothing; 0.0 = disable [rad] -->
      <maxEffort>100</maxEffort>
    </plugin>
  </gazebo>
  <link name="qbhand_middle_distal_link">
    <inertial>
      <mass value="0.01"/>
      <origin xyz="0 0 0"/>
      <inertia ixx="1e-02" ixy="0.0" ixz="0.0" iyy="1e-02" iyz="0.0" izz="1e-02"/>
    </inertial>
    <visual>
      <origin rpy="0 0 0" xyz="0 0 0"/>
      <geometry>
        <mesh filename="package://qb_hand_description/meshes/ph_distal.stl" scale="0.001 0.001 0.001"/>
      </geometry>
      <material name="qbhand/distal"/>
    </visual>
    <collision>
      <origin rpy="0 0 0" xyz="0 0 0"/>
      <geometry>
        <mesh filename="package://qb_hand_description/meshes/ph_distal.stl" scale="0.001 0.001 0.001"/>
      </geometry>
    </collision>
  </link>
  <joint name="qbhand_ring_knuckle_joint" type="revolute">
    <origin rpy="0 0 0" xyz="0.02 -0.007 0.014"/>
    <parent link="qbhand_palm_link"/>
    <child link="qbhand_ring_knuckle_link"/>
    <axis xyz="0 0 -1"/>
    <dynamics damping="0.0" friction="0.0"/>
    <limit effort="100" lower="-0.524" upper="0.524" velocity="100"/>
    <mimic joint="qbhand_synergy_joint" multiplier="0.2"/>
  </joint>
  <gazebo>
    <plugin filename="libroboticsgroup_gazebo_mimic_joint_plugin.so" name="qbhand_ring_knuckle_joint_jointmimic_joint_plugin">
      <joint>qbhand_synergy_joint</joint>
      <mimicJoint>qbhand_ring_knuckle_joint</mimicJoint>
      <multiplier>0.2</multiplier>
      <offset>0</offset>
      <sensitiveness>0.0</sensitiveness>
      <!-- if absolute difference between setpoint and process value is below this threshold, do nothing; 0.0 = disable [rad] -->
      <maxEffort>100</maxEffort>
    </plugin>
  </gazebo>
  <link name="qbhand_ring_knuckle_link">
    <inertial>
      <mass value="0.01"/>
      <origin xyz="0 0 0"/>
      <inertia ixx="1e-02" ixy="0.0" ixz="0.0" iyy="1e-02" iyz="0.0" izz="1e-02"/>
    </inertial>
    <visual>
      <origin rpy="0 0 0" xyz="0 0 0"/>
      <geometry>
        <mesh filename="package://qb_hand_description/meshes/ph_knuckle.stl" scale="0.001 0.001 0.001"/>
      </geometry>
      <material name="qbhand/knuckle"/>
    </visual>
    <collision>
      <origin rpy="0 0 0" xyz="0 0 0"/>
      <geometry>
        <mesh filename="package://qb_hand_description/meshes/ph_knuckle.stl" scale="0.001 0.001 0.001"/>
      </geometry>
    </collision>
  </link>
  <joint name="qbhand_ring_proximal_joint" type="revolute">
    <origin rpy="1.57 0 1.57" xyz="0 0.009 0"/>
    <parent link="qbhand_ring_knuckle_link"/>
    <child link="qbhand_ring_proximal_virtual_link"/>
    <axis xyz="0 0 -1"/>
    <dynamics damping="0.0" friction="0.0"/>
    <limit effort="100" lower="0.0" upper="0.785" velocity="100"/>
    <mimic joint="qbhand_synergy_joint" multiplier="0.785"/>
  </joint>
  <gazebo>
    <plugin filename="libroboticsgroup_gazebo_mimic_joint_plugin.so" name="qbhand_ring_proximal_joint_jointmimic_joint_plugin">
      <joint>qbhand_synergy_joint</joint>
      <mimicJoint>qbhand_ring_proximal_joint</mimicJoint>
      <multiplier>0.785</multiplier>
      <offset>0</offset>
      <sensitiveness>0.0</sensitiveness>
      <!-- if absolute difference between setpoint and process value is below this threshold, do nothing; 0.0 = disable [rad] -->
      <maxEffort>100</maxEffort>
    </plugin>
  </gazebo>
  <link name="qbhand_ring_proximal_virtual_link">
    <inertial>
      <origin rpy="0 0 0" xyz="0 0 0"/>
      <mass value="0.01"/>
      <inertia ixx="1e-03" ixy="0.0" ixz="0.0" iyy="1e-03" iyz="0.0" izz="1e-03"/>
    </inertial>
  </link>
  <joint name="qbhand_ring_proximal_virtual_joint" type="revolute">
    <origin rpy="0 0 0" xyz="0.013 0 0"/>
    <parent link="qbhand_ring_proximal_virtual_link"/>
    <child link="qbhand_ring_proximal_link"/>
    <axis xyz="0 0 -1"/>
    <dynamics damping="0.0" friction="0.0"/>
    <limit effort="100" lower="0.0" upper="0.785" velocity="100"/>
    <mimic joint="qbhand_ring_proximal_joint" multiplier="1.0"/>
  </joint>
  <gazebo>
    <plugin filename="libroboticsgroup_gazebo_mimic_joint_plugin.so" name="qbhand_ring_proximal_virtual_joint_jointmimic_joint_plugin">
      <joint>qbhand_synergy_joint</joint>
      <mimicJoint>qbhand_ring_proximal_virtual_joint</mimicJoint>
      <multiplier>1.0</multiplier>
      <offset>0</offset>
      <sensitiveness>0.0</sensitiveness>
      <!-- if absolute difference between setpoint and process value is below this threshold, do nothing; 0.0 = disable [rad] -->
      <maxEffort>100</maxEffort>
    </plugin>
  </gazebo>
  <link name="qbhand_ring_proximal_link">
    <inertial>
      <mass value="0.01"/>
      <origin xyz="0 0 0"/>
      <inertia ixx="1e-02" ixy="0.0" ixz="0.0" iyy="1e-02" iyz="0.0" izz="1e-02"/>
    </inertial>
    <visual>
      <origin rpy="0 0 0" xyz="0 0 0"/>
      <geometry>
        <mesh filename="package://qb_hand_description/meshes/ph_medium.stl" scale="0.001 0.001 0.001"/>
      </geometry>
      <material name="qbhand/proximal"/>
    </visual>
    <collision>
      <origin rpy="0 0 0" xyz="0 0 0"/>
      <geometry>
        <mesh filename="package://qb_hand_description/meshes/ph_medium.stl" scale="0.001 0.001 0.001"/>
      </geometry>
    </collision>
  </link>
  <joint name="qbhand_ring_middle_joint" type="revolute">
    <origin rpy="0 0 0" xyz="0.017 0 0"/>
    <parent link="qbhand_ring_proximal_link"/>
    <child link="qbhand_ring_middle_virtual_link"/>
    <axis xyz="0 0 -1"/>
    <dynamics damping="0.0" friction="0.0"/>
    <limit effort="100" lower="0.0" upper="0.785" velocity="100"/>
    <mimic joint="qbhand_synergy_joint" multiplier="0.785"/>
  </joint>
  <gazebo>
    <plugin filename="libroboticsgroup_gazebo_mimic_joint_plugin.so" name="qbhand_ring_middle_joint_jointmimic_joint_plugin">
      <joint>qbhand_synergy_joint</joint>
      <mimicJoint>qbhand_ring_middle_joint</mimicJoint>
      <multiplier>0.785</multiplier>
      <offset>0</offset>
      <sensitiveness>0.0</sensitiveness>
      <!-- if absolute difference between setpoint and process value is below this threshold, do nothing; 0.0 = disable [rad] -->
      <maxEffort>100</maxEffort>
    </plugin>
  </gazebo>
  <link name="qbhand_ring_middle_virtual_link">
    <inertial>
      <origin rpy="0 0 0" xyz="0 0 0"/>
      <mass value="0.01"/>
      <inertia ixx="1e-03" ixy="0.0" ixz="0.0" iyy="1e-03" iyz="0.0" izz="1e-03"/>
    </inertial>
  </link>
  <joint name="qbhand_ring_middle_virtual_joint" type="revolute">
    <origin rpy="0 0 0" xyz="0.013 0 0"/>
    <parent link="qbhand_ring_middle_virtual_link"/>
    <child link="qbhand_ring_middle_link"/>
    <axis xyz="0 0 -1"/>
    <dynamics damping="0.0" friction="0.0"/>
    <limit effort="100" lower="0.0" upper="0.785" velocity="100"/>
    <mimic joint="qbhand_ring_middle_joint" multiplier="1.0"/>
  </joint>
  <gazebo>
    <plugin filename="libroboticsgroup_gazebo_mimic_joint_plugin.so" name="qbhand_ring_middle_virtual_joint_jointmimic_joint_plugin">
      <joint>qbhand_synergy_joint</joint>
      <mimicJoint>qbhand_ring_middle_virtual_joint</mimicJoint>
      <multiplier>1.0</multiplier>
      <offset>0</offset>
      <sensitiveness>0.0</sensitiveness>
      <!-- if absolute difference between setpoint and process value is below this threshold, do nothing; 0.0 = disable [rad] -->
      <maxEffort>100</maxEffort>
    </plugin>
  </gazebo>
  <link name="qbhand_ring_middle_link">
    <inertial>
      <mass value="0.01"/>
      <origin xyz="0 0 0"/>
      <inertia ixx="1e-02" ixy="0.0" ixz="0.0" iyy="1e-02" iyz="0.0" izz="1e-02"/>
    </inertial>
    <visual>
      <origin rpy="0 0 0" xyz="0 0 0"/>
      <geometry>
        <mesh filename="package://qb_hand_description/meshes/ph_small.stl" scale="0.001 0.001 0.001"/>
      </geometry>
      <material name="qbhand/middle"/>
    </visual>
    <collision>
      <origin rpy="0 0 0" xyz="0 0 0"/>
      <geometry>
        <mesh filename="package://qb_hand_description/meshes/ph_small.stl" scale="0.001 0.001 0.001"/>
      </geometry>
    </collision>
  </link>
  <joint name="qbhand_ring_distal_joint" type="revolute">
    <origin rpy="0 0 0" xyz="0.009 0 0"/>
    <parent link="qbhand_ring_middle_link"/>
    <child link="qbhand_ring_distal_virtual_link"/>
    <axis xyz="0 0 -1"/>
    <dynamics damping="0.0" friction="0.0"/>
    <limit effort="100" lower="0.0" upper="0.785" velocity="100"/>
    <mimic joint="qbhand_synergy_joint" multiplier="0.785"/>
  </joint>
  <gazebo>
    <plugin filename="libroboticsgroup_gazebo_mimic_joint_plugin.so" name="qbhand_ring_distal_joint_jointmimic_joint_plugin">
      <joint>qbhand_synergy_joint</joint>
      <mimicJoint>qbhand_ring_distal_joint</mimicJoint>
      <multiplier>0.785</multiplier>
      <offset>0</offset>
      <sensitiveness>0.0</sensitiveness>
      <!-- if absolute difference between setpoint and process value is below this threshold, do nothing; 0.0 = disable [rad] -->
      <maxEffort>100</maxEffort>
    </plugin>
  </gazebo>
  <link name="qbhand_ring_distal_virtual_link">
    <inertial>
      <origin rpy="0 0 0" xyz="0 0 0"/>
      <mass value="0.01"/>
      <inertia ixx="1e-03" ixy="0.0" ixz="0.0" iyy="1e-03" iyz="0.0" izz="1e-03"/>
    </inertial>
  </link>
  <joint name="qbhand_ring_distal_virtual_joint" type="revolute">
    <origin rpy="0 0 0" xyz="0.013 0 0"/>
    <parent link="qbhand_ring_distal_virtual_link"/>
    <child link="qbhand_ring_distal_link"/>
    <axis xyz="0 0 -1"/>
    <dynamics damping="0.0" friction="0.0"/>
    <limit effort="100" lower="0.0" upper="0.785" velocity="100"/>
    <mimic joint="qbhand_ring_distal_joint" multiplier="1.0"/>
  </joint>
  <gazebo>
    <plugin filename="libroboticsgroup_gazebo_mimic_joint_plugin.so" name="qbhand_ring_distal_virtual_joint_jointmimic_joint_plugin">
      <joint>qbhand_synergy_joint</joint>
      <mimicJoint>qbhand_ring_distal_virtual_joint</mimicJoint>
      <multiplier>1.0</multiplier>
      <offset>0</offset>
      <sensitiveness>0.0</sensitiveness>
      <!-- if absolute difference between setpoint and process value is below this threshold, do nothing; 0.0 = disable [rad] -->
      <maxEffort>100</maxEffort>
    </plugin>
  </gazebo>
  <link name="qbhand_ring_distal_link">
    <inertial>
      <mass value="0.01"/>
      <origin xyz="0 0 0"/>
      <inertia ixx="1e-02" ixy="0.0" ixz="0.0" iyy="1e-02" iyz="0.0" izz="1e-02"/>
    </inertial>
    <visual>
      <origin rpy="0 0 0" xyz="0 0 0"/>
      <geometry>
        <mesh filename="package://qb_hand_description/meshes/ph_distal.stl" scale="0.001 0.001 0.001"/>
      </geometry>
      <material name="qbhand/distal"/>
    </visual>
    <collision>
      <origin rpy="0 0 0" xyz="0 0 0"/>
      <geometry>
        <mesh filename="package://qb_hand_description/meshes/ph_distal.stl" scale="0.001 0.001 0.001"/>
      </geometry>
    </collision>
  </link>
  <joint name="qbhand_little_knuckle_joint" type="revolute">
    <origin rpy="0 0 0" xyz="0.04 -0.012 0.014"/>
    <parent link="qbhand_palm_link"/>
    <child link="qbhand_little_knuckle_link"/>
    <axis xyz="0 0 -1"/>
    <dynamics damping="0.0" friction="0.0"/>
    <limit effort="100" lower="-0.524" upper="0.524" velocity="100"/>
    <mimic joint="qbhand_synergy_joint" multiplier="0.4"/>
  </joint>
  <gazebo>
    <plugin filename="libroboticsgroup_gazebo_mimic_joint_plugin.so" name="qbhand_little_knuckle_joint_jointmimic_joint_plugin">
      <joint>qbhand_synergy_joint</joint>
      <mimicJoint>qbhand_little_knuckle_joint</mimicJoint>
      <multiplier>0.4</multiplier>
      <offset>0</offset>
      <sensitiveness>0.0</sensitiveness>
      <!-- if absolute difference between setpoint and process value is below this threshold, do nothing; 0.0 = disable [rad] -->
      <maxEffort>100</maxEffort>
    </plugin>
  </gazebo>
  <link name="qbhand_little_knuckle_link">
    <inertial>
      <mass value="0.01"/>
      <origin xyz="0 0 0"/>
      <inertia ixx="1e-02" ixy="0.0" ixz="0.0" iyy="1e-02" iyz="0.0" izz="1e-02"/>
    </inertial>
    <visual>
      <origin rpy="0 0 0" xyz="0 0 0"/>
      <geometry>
        <mesh filename="package://qb_hand_description/meshes/ph_knuckle.stl" scale="0.001 0.001 0.001"/>
      </geometry>
      <material name="qbhand/knuckle"/>
    </visual>
    <collision>
      <origin rpy="0 0 0" xyz="0 0 0"/>
      <geometry>
        <mesh filename="package://qb_hand_description/meshes/ph_knuckle.stl" scale="0.001 0.001 0.001"/>
      </geometry>
    </collision>
  </link>
  <joint name="qbhand_little_proximal_joint" type="revolute">
    <origin rpy="1.57 0 1.57" xyz="0 0.009 0"/>
    <parent link="qbhand_little_knuckle_link"/>
    <child link="qbhand_little_proximal_virtual_link"/>
    <axis xyz="0 0 -1"/>
    <dynamics damping="0.0" friction="0.0"/>
    <limit effort="100" lower="0.0" upper="0.785" velocity="100"/>
    <mimic joint="qbhand_synergy_joint" multiplier="0.785"/>
  </joint>
  <gazebo>
    <plugin filename="libroboticsgroup_gazebo_mimic_joint_plugin.so" name="qbhand_little_proximal_joint_jointmimic_joint_plugin">
      <joint>qbhand_synergy_joint</joint>
      <mimicJoint>qbhand_little_proximal_joint</mimicJoint>
      <multiplier>0.785</multiplier>
      <offset>0</offset>
      <sensitiveness>0.0</sensitiveness>
      <!-- if absolute difference between setpoint and process value is below this threshold, do nothing; 0.0 = disable [rad] -->
      <maxEffort>100</maxEffort>
    </plugin>
  </gazebo>
  <link name="qbhand_little_proximal_virtual_link">
    <inertial>
      <origin rpy="0 0 0" xyz="0 0 0"/>
      <mass value="0.01"/>
      <inertia ixx="1e-03" ixy="0.0" ixz="0.0" iyy="1e-03" iyz="0.0" izz="1e-03"/>
    </inertial>
  </link>
  <joint name="qbhand_little_proximal_virtual_joint" type="revolute">
    <origin rpy="0 0 0" xyz="0.013 0 0"/>
    <parent link="qbhand_little_proximal_virtual_link"/>
    <child link="qbhand_little_proximal_link"/>
    <axis xyz="0 0 -1"/>
    <dynamics damping="0.0" friction="0.0"/>
    <limit effort="100" lower="0.0" upper="0.785" velocity="100"/>
    <mimic joint="qbhand_little_proximal_joint" multiplier="1.0"/>
  </joint>
  <gazebo>
    <plugin filename="libroboticsgroup_gazebo_mimic_joint_plugin.so" name="qbhand_little_proximal_virtual_joint_jointmimic_joint_plugin">
      <joint>qbhand_synergy_joint</joint>
      <mimicJoint>qbhand_little_proximal_virtual_joint</mimicJoint>
      <multiplier>1.0</multiplier>
      <offset>0</offset>
      <sensitiveness>0.0</sensitiveness>
      <!-- if absolute difference between setpoint and process value is below this threshold, do nothing; 0.0 = disable [rad] -->
      <maxEffort>100</maxEffort>
    </plugin>
  </gazebo>
  <link name="qbhand_little_proximal_link">
    <inertial>
      <mass value="0.01"/>
      <origin xyz="0 0 0"/>
      <inertia ixx="1e-02" ixy="0.0" ixz="0.0" iyy="1e-02" iyz="0.0" izz="1e-02"/>
    </inertial>
    <visual>
      <origin rpy="0 0 0" xyz="0 0 0"/>
      <geometry>
        <mesh filename="package://qb_hand_description/meshes/ph_small.stl" scale="0.001 0.001 0.001"/>
      </geometry>
      <material name="qbhand/proximal"/>
    </visual>
    <collision>
      <origin rpy="0 0 0" xyz="0 0 0"/>
      <geometry>
        <mesh filename="package://qb_hand_description/meshes/ph_small.stl" scale="0.001 0.001 0.001"/>
      </geometry>
    </collision>
  </link>
  <joint name="qbhand_little_middle_joint" type="revolute">
    <origin rpy="0 0 0" xyz="0.009 0 0"/>
    <parent link="qbhand_little_proximal_link"/>
    <child link="qbhand_little_middle_virtual_link"/>
    <axis xyz="0 0 -1"/>
    <dynamics damping="0.0" friction="0.0"/>
    <limit effort="100" lower="0.0" upper="0.785" velocity="100"/>
    <mimic joint="qbhand_synergy_joint" multiplier="0.785"/>
  </joint>
  <gazebo>
    <plugin filename="libroboticsgroup_gazebo_mimic_joint_plugin.so" name="qbhand_little_middle_joint_jointmimic_joint_plugin">
      <joint>qbhand_synergy_joint</joint>
      <mimicJoint>qbhand_little_middle_joint</mimicJoint>
      <multiplier>0.785</multiplier>
      <offset>0</offset>
      <sensitiveness>0.0</sensitiveness>
      <!-- if absolute difference between setpoint and process value is below this threshold, do nothing; 0.0 = disable [rad] -->
      <maxEffort>100</maxEffort>
    </plugin>
  </gazebo>
  <link name="qbhand_little_middle_virtual_link">
    <inertial>
      <origin rpy="0 0 0" xyz="0 0 0"/>
      <mass value="0.01"/>
      <inertia ixx="1e-03" ixy="0.0" ixz="0.0" iyy="1e-03" iyz="0.0" izz="1e-03"/>
    </inertial>
  </link>
  <joint name="qbhand_little_middle_virtual_joint" type="revolute">
    <origin rpy="0 0 0" xyz="0.013 0 0"/>
    <parent link="qbhand_little_middle_virtual_link"/>
    <child link="qbhand_little_middle_link"/>
    <axis xyz="0 0 -1"/>
    <dynamics damping="0.0" friction="0.0"/>
    <limit effort="100" lower="0.0" upper="0.785" velocity="100"/>
    <mimic joint="qbhand_little_middle_joint" multiplier="1.0"/>
  </joint>
  <gazebo>
    <plugin filename="libroboticsgroup_gazebo_mimic_joint_plugin.so" name="qbhand_little_middle_virtual_joint_jointmimic_joint_plugin">
      <joint>qbhand_synergy_joint</joint>
      <mimicJoint>qbhand_little_middle_virtual_joint</mimicJoint>
      <multiplier>1.0</multiplier>
      <offset>0</offset>
      <sensitiveness>0.0</sensitiveness>
      <!-- if absolute difference between setpoint and process value is below this threshold, do nothing; 0.0 = disable [rad] -->
      <maxEffort>100</maxEffort>
    </plugin>
  </gazebo>
  <link name="qbhand_little_middle_link">
    <inertial>
      <mass value="0.01"/>
      <origin xyz="0 0 0"/>
      <inertia ixx="1e-02" ixy="0.0" ixz="0.0" iyy="1e-02" iyz="0.0" izz="1e-02"/>
    </inertial>
    <visual>
      <origin rpy="0 0 0" xyz="0 0 0"/>
      <geometry>
        <mesh filename="package://qb_hand_description/meshes/ph_small.stl" scale="0.001 0.001 0.001"/>
      </geometry>
      <material name="qbhand/middle"/>
    </visual>
    <collision>
      <origin rpy="0 0 0" xyz="0 0 0"/>
      <geometry>
        <mesh filename="package://qb_hand_description/meshes/ph_small.stl" scale="0.001 0.001 0.001"/>
      </geometry>
    </collision>
  </link>
  <joint name="qbhand_little_distal_joint" type="revolute">
    <origin rpy="0 0 0" xyz="0.009 0 0"/>
    <parent link="qbhand_little_middle_link"/>
    <child link="qbhand_little_distal_virtual_link"/>
    <axis xyz="0 0 -1"/>
    <dynamics damping="0.0" friction="0.0"/>
    <limit effort="100" lower="0.0" upper="0.785" velocity="100"/>
    <mimic joint="qbhand_synergy_joint" multiplier="0.785"/>
  </joint>
  <gazebo>
    <plugin filename="libroboticsgroup_gazebo_mimic_joint_plugin.so" name="qbhand_little_distal_joint_jointmimic_joint_plugin">
      <joint>qbhand_synergy_joint</joint>
      <mimicJoint>qbhand_little_distal_joint</mimicJoint>
      <multiplier>0.785</multiplier>
      <offset>0</offset>
      <sensitiveness>0.0</sensitiveness>
      <!-- if absolute difference between setpoint and process value is below this threshold, do nothing; 0.0 = disable [rad] -->
      <maxEffort>100</maxEffort>
    </plugin>
  </gazebo>
  <link name="qbhand_little_distal_virtual_link">
    <inertial>
      <origin rpy="0 0 0" xyz="0 0 0"/>
      <mass value="0.01"/>
      <inertia ixx="1e-03" ixy="0.0" ixz="0.0" iyy="1e-03" iyz="0.0" izz="1e-03"/>
    </inertial>
  </link>
  <joint name="qbhand_little_distal_virtual_joint" type="revolute">
    <origin rpy="0 0 0" xyz="0.013 0 0"/>
    <parent link="qbhand_little_distal_virtual_link"/>
    <child link="qbhand_little_distal_link"/>
    <axis xyz="0 0 -1"/>
    <dynamics damping="0.0" friction="0.0"/>
    <limit effort="100" lower="0.0" upper="0.785" velocity="100"/>
    <mimic joint="qbhand_little_distal_joint" multiplier="1.0"/>
  </joint>
  <gazebo>
    <plugin filename="libroboticsgroup_gazebo_mimic_joint_plugin.so" name="qbhand_little_distal_virtual_joint_jointmimic_joint_plugin">
      <joint>qbhand_synergy_joint</joint>
      <mimicJoint>qbhand_little_distal_virtual_joint</mimicJoint>
      <multiplier>1.0</multiplier>
      <offset>0</offset>
      <sensitiveness>0.0</sensitiveness>
      <!-- if absolute difference between setpoint and process value is below this threshold, do nothing; 0.0 = disable [rad] -->
      <maxEffort>100</maxEffort>
    </plugin>
  </gazebo>
  <link name="qbhand_little_distal_link">
    <inertial>
      <mass value="0.01"/>
      <origin xyz="0 0 0"/>
      <inertia ixx="1e-02" ixy="0.0" ixz="0.0" iyy="1e-02" iyz="0.0" izz="1e-02"/>
    </inertial>
    <visual>
      <origin rpy="0 0 0" xyz="0 0 0"/>
      <geometry>
        <mesh filename="package://qb_hand_description/meshes/ph_distal.stl" scale="0.001 0.001 0.001"/>
      </geometry>
      <material name="qbhand/distal"/>
    </visual>
    <collision>
      <origin rpy="0 0 0" xyz="0 0 0"/>
      <geometry>
        <mesh filename="package://qb_hand_description/meshes/ph_distal.stl" scale="0.001 0.001 0.001"/>
      </geometry>
    </collision>
  </link>
  
  <gazebo>
      <plugin name="qbhand_controller" filename="libRoseePlugin.so">
      </plugin>
    </gazebo>
</robot>
