<?xml version="1.0" ?>
<!-- =================================================================================== -->
<!-- |    This document was autogenerated by xacro from robotiq-3f-gripper_articulated.xacro | -->
<!-- |    EDITING THIS FILE BY HAND IS NOT RECOMMENDED  
						BUT I EDIT IT ANYWAY                                | -->
<!-- =================================================================================== -->
<!-- 
robotiq-3f-gripper_articulated - articulated version of the robotiq robotiq-3f-gripper,
3 fingered gripper.                                                
-->
<robot name="robotiq_3f" xmlns:xacro="http://ros.org/wiki/xacro">

  <gazebo>
      <plugin name='xbot2_gz_joint_server' filename='libxbot2_gz_joint_server.so'>
        <pid>
            <gain name="small_mot"  p="1"  d="0.05"/>
            <gain name="medium_mot" p="1000" d="10"/>
            <gain name="big_mot"    p="3000" d="10"/>
            <gain name="wheel_mot"  p="0" d="30"/>
            <gain name="null"  p="0" d="0" i="0"/>

            <gain name="palm_finger_1_joint" profile="small_mot"/>
            <gain name="finger_1_joint_1" profile="small_mot"/>

            <gain name="finger_1_joint_2" profile="null"/>
            <gain name="finger_1_joint_3" profile="null"/>

            <gain name="palm_finger_2_joint" profile="null"/>
            <gain name="finger_2_joint_1" profile="null"/>
            <gain name="finger_2_joint_2" profile="null"/>
            <gain name="finger_2_joint_3" profile="null"/>

            <gain name="palm_finger_middle_joint" profile="null"/>
            <gain name="finger_middle_joint_1" profile="null"/>
            <gain name="finger_middle_joint_2" profile="null"/>
            <gain name="finger_middle_joint_3" profile="null"/>

        </pid>
    </plugin>
  </gazebo>

  <link name="world"/>
  <joint name="world_base" type="fixed">
    <parent link="world"/>
    <child link="palm"/>
    <origin rpy="1.57079632679 0 0" xyz="0 0 0"/>  <!-- to rotate the hand that is originally spawned horizonzal -->
  </joint>
  <!-- rosee plugin -->
  <gazebo>
    <plugin filename="libRoseePlugin.so" name="robotiq3f_controller">
      </plugin>
  </gazebo>
  
  <gazebo reference="finger_1_link_3">
    <self_collide>1</self_collide>
  </gazebo>
  <gazebo reference="finger_2_link_3">
    <self_collide>1</self_collide>
  </gazebo> 
  <gazebo reference="finger_middle_link_3">
    <self_collide>1</self_collide>
  </gazebo>
  
  <material name="White">
    <color rgba="1 1 1 1"/>
  </material>
  <material name="Blue">
    <color rgba="0 0 1 1"/>
  </material>
  <material name="Red">
    <color rgba="1 0 0 1"/>
  </material>
  
  <gazebo reference="palm">
    <fudgeFactor value="0.1"/>
    <material>Gazebo/DarkGrey</material>
  </gazebo>

  <gazebo reference="finger_1_link_0">
    <fudgeFactor value="0.5"/>
    <material>Gazebo/DarkGrey</material>
  </gazebo>
  <gazebo reference="finger_1_link_1">
    <fudgeFactor value="0.5"/>
    <material>Gazebo/DarkGrey</material>
  </gazebo>
  <gazebo reference="finger_1_link_2">
    <fudgeFactor value="0.5"/>
    <material>Gazebo/DarkGrey</material>
  </gazebo>
  <gazebo reference="finger_1_link_3">
    <fudgeFactor value="0.5"/>
    <material>Gazebo/White</material>
  </gazebo>
  
  <gazebo reference="finger_2_link_0">
    <fudgeFactor value="0.5"/>
    <material>Gazebo/DarkGrey</material>
  </gazebo>
  <gazebo reference="finger_2_link_1">
    <fudgeFactor value="0.5"/>
    <material>Gazebo/DarkGrey</material>
  </gazebo>
  <gazebo reference="finger_2_link_2">
    <fudgeFactor value="0.5"/>
    <material>Gazebo/DarkGrey</material>
  </gazebo>
  <gazebo reference="finger_2_link_3">
    <fudgeFactor value="0.5"/>
    <material>Gazebo/White</material>
  </gazebo>
  
  <gazebo reference="finger_middle_link_0">
    <fudgeFactor value="0.5"/>
    <material>Gazebo/DarkGrey</material>
  </gazebo>
  <gazebo reference="finger_middle_link_1">
    <fudgeFactor value="0.5"/>
    <material>Gazebo/DarkGrey</material>
  </gazebo>
  <gazebo reference="finger_middle_link_2">
    <fudgeFactor value="0.5"/>
    <material>Gazebo/DarkGrey</material>
  </gazebo>
  <gazebo reference="finger_middle_link_3">
    <fudgeFactor value="0.5"/>
    <material>Gazebo/White</material>
  </gazebo>

  <!-- link list -->
  <link name="finger_1_link_0">
    <visual>
      <origin rpy="0 0 0" xyz="0.020 0 0"/>
      <geometry>
        <mesh filename="package://robotiq_3f_gripper_visualization/meshes/robotiq-3f-gripper_articulated/visual/link_0.dae"/>
      </geometry>
      <material name="blue"/>
    </visual>
    <collision>
      <origin rpy="0 0 0" xyz="0.020 0 0"/>
      <geometry>
        <mesh filename="package://robotiq_3f_gripper_visualization/meshes/robotiq-3f-gripper_articulated/collision/link_0.STL"/>
      </geometry>
      <material name="blue" />
    </collision>
    <inertial>
      <origin rpy="0 0 0" xyz="0 0 0"/>
      <mass value="0.05"/>
      <inertia ixx="0.01" ixy="-0.00002" ixz="0.00001" iyy="0.0008" iyz="0" izz="0.001"/>
    </inertial>
  </link>
  <link name="finger_1_link_1">
    <visual>
      <origin rpy="0 0 -0.52" xyz="0.050 -.028 0"/>
      <geometry>
        <mesh filename="package://robotiq_3f_gripper_visualization/meshes/robotiq-3f-gripper_articulated/visual/link_1.dae"/>
      </geometry>
      <material name="gray"/>
    </visual>
    <collision>
      <origin rpy="0 0 -0.52" xyz="0.050 -.028 0"/>
      <geometry>
        <mesh filename="package://robotiq_3f_gripper_visualization/meshes/robotiq-3f-gripper_articulated/collision/link_1.STL"/>
      </geometry>
      <material name="yellow"/>
    </collision>
    <inertial>
      <origin rpy="0 0 0" xyz="0 0 0"/>
      <mass value="0.15"/>
      <inertia ixx="0.001859" ixy="-0.000376" ixz="0.000028" iyy="0.012756" iyz="0" izz="0.0024"/>
    </inertial>
  </link>
  <link name="finger_1_link_2">
    <!--
			NOTE: This link has an offset in the z-direction based on the models that were
			used to generate grap-it poses.  With the offset below the model appears visually
			correct, but it is suspect.
			-->
    <visual>
      <origin rpy="0 0 0" xyz="0.039 0 0.0075"/>
      <geometry>
        <mesh filename="package://robotiq_3f_gripper_visualization/meshes/robotiq-3f-gripper_articulated/visual/link_2.dae"/>
      </geometry>
      <material name="gray"/>
    </visual>
    <collision>
      <origin rpy="0 0 0" xyz="0.039 0 0.0075"/>
      <geometry>
        <mesh filename="package://robotiq_3f_gripper_visualization/meshes/robotiq-3f-gripper_articulated/collision/link_2.STL"/>
      </geometry>
      <material name="yellow"/>
    </collision>
    <inertial>
      <origin rpy="0 0 0" xyz="0 0 0"/>
      <mass value="0.15"/>
      <inertia ixx="0.001859" ixy="-0.000376" ixz="0.000028" iyy="0.012756" iyz="0" izz="0.0024"/>
    </inertial>
  </link>
  <link name="finger_1_link_3">
    <visual>
      <origin rpy="0 0 0.52" xyz="0 0 0"/>
      <geometry>
        <mesh filename="package://robotiq_3f_gripper_visualization/meshes/robotiq-3f-gripper_articulated/visual/link_3.dae"/>
      </geometry>
      <material name="gray"/>
    </visual>
    <collision>
      <origin rpy="0 0 0.52" xyz="0 0 0"/>
      <geometry>
        <mesh filename="package://robotiq_3f_gripper_visualization/meshes/robotiq-3f-gripper_articulated/collision/link_3.STL"/>
      </geometry>
      <material name="yellow"/>
      <contact_coefficients mu="1" kp="10.0" kd="1.0"/>
    </collision>
    <inertial>
      <origin rpy="0 0 0" xyz="0 0 0"/>
      <mass value="0.05"/>
      <inertia ixx="0.001239" ixy="-0.000251" ixz="0.000019" iyy="0.00085" iyz="0" izz="0.001632"/>
    </inertial>
  </link>
  <!-- end of link list -->
  <!-- joint list -->
  <joint name="finger_1_joint_1" type="revolute">
    <parent link="finger_1_link_0"/>
    <child link="finger_1_link_1"/>
    <axis xyz="0 0 1"/>
    <origin rpy="0 0 0" xyz="0.020 0 0"/>
    <dynamics damping="0.1" friction="0.03"/>
    <limit effort="100" lower="0.0495" upper="1.2218" velocity="100"/>
  </joint>
  <joint name="finger_1_joint_2" type="revolute">
    <parent link="finger_1_link_1"/>
    <child link="finger_1_link_2"/>
    <axis xyz="0 0 1"/>
    <origin rpy="0 0 -0.52" xyz="0.050 -.028 0"/>
    <dynamics damping="0.1" friction="0.03"/>
    <limit effort="100" lower="0.0" upper="1.5708" velocity="100"/>
		<mimic joint="finger_1_joint_1" multiplier ="0.85" offset="0" />
  </joint>
  <!--<gazebo>
    <plugin filename="libroboticsgroup_gazebo_mimic_joint_plugin.so" name="finger_1_joint_2_jointmimic_joint_plugin">
      <joint>finger_1_joint_1</joint>
      <mimicJoint>finger_1_joint_2</mimicJoint>
      <multiplier>0.85</multiplier>
      <offset>0</offset>
      <sensitiveness>0.0</sensitiveness>
      if absolute difference between setpoint and process value is below this threshold, do nothing; 0.0 = disable [rad]
      <maxEffort>100.0</maxEffort>
    </plugin>
  </gazebo>  	-->
  <joint name="finger_1_joint_3" type="revolute">
    <parent link="finger_1_link_2"/>
    <child link="finger_1_link_3"/>
    <axis xyz="0 0 1"/>
    <origin rpy="0 0 0" xyz="0.039 0 0"/>
    <dynamics damping="0.1" friction="0.03"/>
    <limit effort="100" lower="-1.2217" upper="-0.0523" velocity="100"/>
    <mimic joint="finger_1_joint_1" multiplier ="0.8" offset="0" />
  </joint>
  <!--<gazebo>
    <plugin filename="libroboticsgroup_gazebo_mimic_joint_plugin.so" name="finger_1_joint_3_jointmimic_joint_plugin">
      <joint>finger_1_joint_1</joint>
      <mimicJoint>finger_1_joint_3</mimicJoint>
      <multiplier>0.8</multiplier>
      <offset>0</offset>
      <sensitiveness>0.0</sensitiveness>
      if absolute difference between setpoint and process value is below this threshold, do nothing; 0.0 = disable [rad]
      <maxEffort>100.0</maxEffort>
    </plugin>
  </gazebo> 	-->
  <!-- end of joint list -->
  <!-- link list -->
  <link name="finger_2_link_0">
    <visual>
      <origin rpy="0 0 0" xyz="0.020 0 0"/>
      <geometry>
        <mesh filename="package://robotiq_3f_gripper_visualization/meshes/robotiq-3f-gripper_articulated/visual/link_0.dae"/>
      </geometry>
      <material name="">
        <color rgba="0.75294 0.75294 0.75294 1"/>
      </material>
    </visual>
    <collision>
      <origin rpy="0 0 0" xyz="0.020 0 0"/>
      <geometry>
        <mesh filename="package://robotiq_3f_gripper_visualization/meshes/robotiq-3f-gripper_articulated/collision/link_0.STL"/>
      </geometry>
      <material name="yellow">
        <color rgba="0 1 1 1"/>
      </material>
    </collision>
    <inertial>
      <origin rpy="0 0 0" xyz="0 0 0"/>
      <mass value="0.05"/>
      <inertia ixx="0.01" ixy="-0.00002" ixz="0.00001" iyy="0.0008" iyz="0" izz="0.001"/>
    </inertial>
  </link>
  <link name="finger_2_link_1">
    <visual>
      <origin rpy="0 0 -0.52" xyz="0.050 -.028 0"/>
      <geometry>
        <mesh filename="package://robotiq_3f_gripper_visualization/meshes/robotiq-3f-gripper_articulated/visual/link_1.dae"/>
      </geometry>
      <material name="gray"/>
    </visual>
    <collision>
      <origin rpy="0 0 -0.52" xyz="0.050 -.028 0"/>
      <geometry>
        <mesh filename="package://robotiq_3f_gripper_visualization/meshes/robotiq-3f-gripper_articulated/collision/link_1.STL"/>
      </geometry>
      <material name="yellow"/>
    </collision>
    <inertial>
      <origin rpy="0 0 0" xyz="0 0 0"/>
      <mass value="0.15"/>
      <inertia ixx="0.001859" ixy="-0.000376" ixz="0.000028" iyy="0.012756" iyz="0" izz="0.0024"/>
    </inertial>
  </link>
  <link name="finger_2_link_2">
    <!--
			NOTE: This link has an offset in the z-direction based on the models that were
			used to generate grap-it poses.  With the offset below the model appears visually
			correct, but it is suspect.
			-->
    <visual>
      <origin rpy="0 0 0" xyz="0.039 0 0.0075"/>
      <geometry>
        <mesh filename="package://robotiq_3f_gripper_visualization/meshes/robotiq-3f-gripper_articulated/visual/link_2.dae"/>
      </geometry>
      <material name="gray"/>
    </visual>
    <collision>
      <origin rpy="0 0 0" xyz="0.039 0 0.0075"/>
      <geometry>
        <mesh filename="package://robotiq_3f_gripper_visualization/meshes/robotiq-3f-gripper_articulated/collision/link_2.STL"/>
      </geometry>
      <material name="yellow"/>
    </collision>
    <inertial>
      <origin rpy="0 0 0" xyz="0 0 0"/>
      <mass value="0.15"/>
      <inertia ixx="0.001859" ixy="-0.000376" ixz="0.000028" iyy="0.012756" iyz="0" izz="0.0024"/>
    </inertial>
  </link>
  <link name="finger_2_link_3">
    <visual>
      <origin rpy="0 0 0.52" xyz="0 0 0"/>
      <geometry>
        <mesh filename="package://robotiq_3f_gripper_visualization/meshes/robotiq-3f-gripper_articulated/visual/link_3.dae"/>
      </geometry>
      <material name="gray"/>
    </visual>
    <collision>
      <origin rpy="0 0 0.52" xyz="0 0 0"/>
      <geometry>
        <mesh filename="package://robotiq_3f_gripper_visualization/meshes/robotiq-3f-gripper_articulated/collision/link_3.STL"/>
      </geometry>
      <material name="yellow"/>
      <contact_coefficients mu="1" kp="10.0" kd="1.0"/>
    </collision>
    <inertial>
      <origin rpy="0 0 0" xyz="0 0 0"/>
      <mass value="0.05"/>
      <inertia ixx="0.001239" ixy="-0.000251" ixz="0.000019" iyy="0.00085" iyz="0" izz="0.001632"/>
    </inertial>
  </link>
  <!-- end of link list -->
  <!-- joint list -->
  <joint name="finger_2_joint_1" type="revolute">
    <parent link="finger_2_link_0"/>
    <child link="finger_2_link_1"/>
    <axis xyz="0 0 1"/>
    <origin rpy="0 0 0" xyz="0.020 0 0"/>
    <limit effort="100" lower="0.0495" upper="1.2218" velocity="100"/>
    <dynamics damping="0.1" friction="0.03"/>
		<mimic joint="finger_1_joint_1" multiplier ="1" offset="0" />
  </joint>
  <gazebo>
    <plugin filename="libroboticsgroup_gazebo_mimic_joint_plugin.so" name="finger_2_joint_1_jointmimic_joint_plugin">
      <joint>finger_1_joint_1</joint>
      <mimicJoint>finger_2_joint_1</mimicJoint>
      <multiplier>1.0</multiplier>
      <offset>0</offset>
      <sensitiveness>0.0</sensitiveness>
      <!-- if absolute difference between setpoint and process value is below this threshold, do nothing; 0.0 = disable [rad] -->
      <maxEffort>100.0</maxEffort>
    </plugin>
  </gazebo>
  
  <joint name="finger_2_joint_2" type="revolute">
    <parent link="finger_2_link_1"/>
    <child link="finger_2_link_2"/>
    <axis xyz="0 0 1"/>
    <origin rpy="0 0 -0.52" xyz="0.050 -.028 0"/>
    <limit effort="100" lower="0.0" upper="1.5708" velocity="100"/>
    <dynamics damping="0.1" friction="0.03"/>
    <mimic joint="finger_2_joint_1" multiplier ="0.85" offset="0" />
  </joint>
  <!--<gazebo>
    <plugin filename="libroboticsgroup_gazebo_mimic_joint_plugin.so" name="finger_2_joint_2_jointmimic_joint_plugin">
      <joint>finger_2_joint_1</joint>
      <mimicJoint>finger_2_joint_2</mimicJoint>
      <multiplier>0.85</multiplier>
      <offset>0</offset>
      <sensitiveness>0.0</sensitiveness>
       if absolute difference between setpoint and process value is below this threshold, do nothing; 0.0 = disable [rad]
      <maxEffort>100.0</maxEffort>
    </plugin>
  </gazebo>   --> 
  
  <joint name="finger_2_joint_3" type="revolute">
    <parent link="finger_2_link_2"/>
    <child link="finger_2_link_3"/>
    <axis xyz="0 0 1"/>
    <origin rpy="0 0 0" xyz="0.039 0 0"/>
    <dynamics damping="0.1" friction="0.03"/>
    <limit effort="100" lower="-1.2217" upper="-0.0523" velocity="100"/>
    <mimic joint="finger_2_joint_1" multiplier ="0.8" offset="0" />
  </joint>
  <!--<gazebo>
    <plugin filename="libroboticsgroup_gazebo_mimic_joint_plugin.so" name="finger_2_joint_3_jointmimic_joint_plugin">
      <joint>finger_2_joint_1</joint>
      <mimicJoint>finger_2_joint_3</mimicJoint>
      <multiplier>0.8</multiplier>
      <offset>0</offset>
      <sensitiveness>0.0</sensitiveness>
       if absolute difference between setpoint and process value is below this threshold, do nothing; 0.0 = disable [rad]
      <maxEffort>100.0</maxEffort>
    </plugin>
  </gazebo>  -->
  
  <!-- end of joint list -->
  <!-- link list -->
  <link name="finger_middle_link_0">
    <visual>
      <origin rpy="0 0 0" xyz="0.020 0 0"/>
      <geometry>
        <mesh filename="package://robotiq_3f_gripper_visualization/meshes/robotiq-3f-gripper_articulated/visual/link_0.dae"/>
      </geometry>
      <material name="">
        <color rgba="0.75294 0.75294 0.75294 1"/>
      </material>
    </visual>
    <collision>
      <origin rpy="0 0 0" xyz="0.020 0 0"/>
      <geometry>
        <mesh filename="package://robotiq_3f_gripper_visualization/meshes/robotiq-3f-gripper_articulated/collision/link_0.STL"/>
      </geometry>
      <material name="yellow">
        <color rgba="0 1 1 1"/>
      </material>
    </collision>
    <inertial>
      <origin rpy="0 0 0" xyz="0 0 0"/>
      <mass value="0.05"/>
      <inertia ixx="0.01" ixy="-0.00002" ixz="0.00001" iyy="0.0008" iyz="0" izz="0.001"/>
    </inertial>
  </link>
  <link name="finger_middle_link_1">
    <visual>
      <origin rpy="0 0 -0.52" xyz="0.050 -.028 0"/>
      <geometry>
        <mesh filename="package://robotiq_3f_gripper_visualization/meshes/robotiq-3f-gripper_articulated/visual/link_1.dae"/>
      </geometry>
      <material name="gray"/>
    </visual>
    <collision>
      <origin rpy="0 0 -0.52" xyz="0.050 -.028 0"/>
      <geometry>
        <mesh filename="package://robotiq_3f_gripper_visualization/meshes/robotiq-3f-gripper_articulated/collision/link_1.STL"/>
      </geometry>
      <material name="yellow"/>
    </collision>
    <inertial>
      <origin rpy="0 0 0" xyz="0 0 0"/>
      <mass value="0.15"/>
      <inertia ixx="0.001859" ixy="-0.000376" ixz="0.000028" iyy="0.012756" iyz="0" izz="0.0024"/>
    </inertial>
  </link>
  <link name="finger_middle_link_2">
    <!--
			NOTE: This link has an offset in the z-direction based on the models that were
			used to generate grap-it poses.  With the offset below the model appears visually
			correct, but it is suspect.
			-->
    <visual>
      <origin rpy="0 0 0" xyz="0.039 0 0.0075"/>
      <geometry>
        <mesh filename="package://robotiq_3f_gripper_visualization/meshes/robotiq-3f-gripper_articulated/visual/link_2.dae"/>
      </geometry>
      <material name="gray"/>
    </visual>
    <collision>
      <origin rpy="0 0 0" xyz="0.039 0 0.0075"/>
      <geometry>
        <mesh filename="package://robotiq_3f_gripper_visualization/meshes/robotiq-3f-gripper_articulated/collision/link_2.STL"/>
      </geometry>
      <material name="yellow"/>
    </collision>
    <inertial>
      <origin rpy="0 0 0" xyz="0 0 0"/>
      <mass value="0.15"/>
      <inertia ixx="0.001859" ixy="-0.000376" ixz="0.000028" iyy="0.012756" iyz="0" izz="0.0024"/>
    </inertial>
  </link>
  <link name="finger_middle_link_3">
    <visual>
      <origin rpy="0 0 0.52" xyz="0 0 0"/>
      <geometry>
        <mesh filename="package://robotiq_3f_gripper_visualization/meshes/robotiq-3f-gripper_articulated/visual/link_3.dae"/>
      </geometry>
      <material name="gray"/>
    </visual>
    <collision>
      <origin rpy="0 0 0.52" xyz="0 0 0"/>
      <geometry>
        <mesh filename="package://robotiq_3f_gripper_visualization/meshes/robotiq-3f-gripper_articulated/collision/link_3.STL"/>
      </geometry>
      <material name="yellow"/>
      <contact_coefficients mu="1" kp="10.0" kd="1.0"/>
    </collision>
    <inertial>
      <origin rpy="0 0 0" xyz="0 0 0"/>
      <mass value="0.05"/>
      <inertia ixx="0.001239" ixy="-0.000251" ixz="0.000019" iyy="0.00085" iyz="0" izz="0.001632"/>
    </inertial>
  </link>
  <!-- end of link list -->
  <!-- joint list -->
  <joint name="finger_middle_joint_1" type="revolute">
    <parent link="finger_middle_link_0"/>
    <child link="finger_middle_link_1"/>
    <axis xyz="0 0 1"/>
    <origin rpy="0 0 0" xyz="0.020 0 0"/>
    <limit effort="100" lower="0.0495" upper="1.2218" velocity="100"/>
    <dynamics damping="0.1" friction="0.03"/>
		<mimic joint="finger_1_joint_1" multiplier ="1" offset="0" />
  </joint>
  <gazebo>
    <plugin filename="libroboticsgroup_gazebo_mimic_joint_plugin.so" name="finger_middle_joint_1_jointmimic_joint_plugin">
      <joint>finger_1_joint_1</joint>
      <mimicJoint>finger_middle_joint_1</mimicJoint>
      <multiplier>1.0</multiplier>
      <offset>0</offset>
      <sensitiveness>0.0</sensitiveness>
      <!-- if absolute difference between setpoint and process value is below this threshold, do nothing; 0.0 = disable [rad] -->
      <maxEffort>100.0</maxEffort>
    </plugin>
  </gazebo>
  
  <joint name="finger_middle_joint_2" type="revolute">
    <parent link="finger_middle_link_1"/>
    <child link="finger_middle_link_2"/>
    <axis xyz="0 0 1"/>
    <origin rpy="0 0 -0.52" xyz="0.050 -.028 0"/>
    <dynamics damping="0.1" friction="0.03"/>
    <limit effort="100" lower="0.0" upper="1.5708" velocity="100"/>
    <mimic joint="finger_middle_joint_1" multiplier ="0.85" offset="0" />
  </joint>
  <gazebo>
    <plugin filename="libroboticsgroup_gazebo_mimic_joint_plugin.so" name="finger_middle_joint_2_jointmimic_joint_plugin">
      <joint>finger_middle_joint_1</joint>
      <mimicJoint>finger_middle_joint_2</mimicJoint>
      <multiplier>0.85</multiplier>
      <offset>0</offset>
      <sensitiveness>0.0</sensitiveness>
      <!-- if absolute difference between setpoint and process value is below this threshold, do nothing; 0.0 = disable [rad] -->
      <maxEffort>100.0</maxEffort>
    </plugin>
  </gazebo>  
  
  
  <joint name="finger_middle_joint_3" type="revolute">
    <parent link="finger_middle_link_2"/>
    <child link="finger_middle_link_3"/>
    <axis xyz="0 0 1"/>
    <origin rpy="0 0 0" xyz="0.039 0 0"/>
    <dynamics damping="0.1" friction="0.03"/>
    <limit effort="100" lower="-1.2217" upper="-0.0523" velocity="100"/>
    <mimic joint="finger_middle_joint_1" multiplier ="0.8" offset="0" />
  </joint>
  <gazebo>
    <plugin filename="libroboticsgroup_gazebo_mimic_joint_plugin.so" name="finger_middle_joint_3_jointmimic_joint_plugin">
      <joint>finger_middle_joint_1</joint>
      <mimicJoint>finger_middle_joint_3</mimicJoint>
      <multiplier>0.8</multiplier>
      <offset>0</offset>
      <sensitiveness>0.0</sensitiveness>
      <!-- if absolute difference between setpoint and process value is below this threshold, do nothing; 0.0 = disable [rad] -->
      <maxEffort>100.0</maxEffort>
    </plugin>
  </gazebo>  
  <!-- end of joint list -->
 <!-- link list -->
  <link name="palm">
    <visual>
      <geometry>
        <mesh filename="package://robotiq_3f_gripper_visualization/meshes/robotiq-3f-gripper_articulated/visual/palm.dae"/>
      </geometry>
      <material name="red">
        <color rgba="0 204 0 1"/>
      </material>
    </visual>
    <collision>
      <geometry>
        <mesh filename="package://robotiq_3f_gripper_visualization/meshes/robotiq-3f-gripper_articulated/collision/palm.STL"/>
      </geometry>
      <material name="">
        <color rgba="0 204 0 1"/>
      </material>
    </collision>
    <inertial>
      <origin rpy="0 0 0" xyz="0 0 0"/>
      <mass value="1.3"/>
      <inertia ixx="0.006012" ixy="0.000079" ixz="-0.00024" iyy="0.012892" iyz="0" izz="0.002435"/>
    </inertial>
  </link>
  <link name="tool0"/>
  <!-- end of link list -->
  <!-- joint list -->
  <joint name="palm_finger_1_joint" type="revolute">
    <parent link="palm"/>
    <child link="finger_1_link_0"/>
    <axis xyz="0 1 0"/>
    <origin rpy="0 3.1416 -1.57" xyz="-0.0455 0.0214 0.036"/>
    <dynamics damping="0.1" friction="0.03"/>
    <limit effort="100" lower="-0.1784" upper="0.192" velocity="100"/>
  </joint>
  <joint name="palm_finger_2_joint" type="revolute">
    <parent link="palm"/>
    <child link="finger_2_link_0"/>
    <axis xyz="0 1 0"/>
    <origin rpy="0 3.1416 -1.57" xyz="-0.0455 0.0214 -0.036"/>
    <limit effort="100" lower="-0.192" upper="0.1784" velocity="100"/>
    <dynamics damping="0.1" friction="0.03"/>
		<mimic joint="palm_finger_1_joint" multiplier ="-1" offset="0" />
  </joint>
  <gazebo>
    <plugin filename="libroboticsgroup_gazebo_mimic_joint_plugin.so" name="palm_finger_2_joint_jointmimic_joint_plugin">
      <joint>palm_finger_1_joint</joint>
      <mimicJoint>palm_finger_2_joint</mimicJoint>
      <multiplier>-1.0</multiplier>
      <offset>0</offset>
      <sensitiveness>0.0</sensitiveness>
      <!-- if absolute difference between setpoint and process value is below this threshold, do nothing; 0.0 = disable [rad] -->
      <maxEffort>100.0</maxEffort>
    </plugin>
  </gazebo>  
  
  <joint name="palm_finger_middle_joint" type="fixed">
    <parent link="palm"/>
    <child link="finger_middle_link_0"/>
    <axis xyz="0 0 1"/>
    <origin rpy="0 0 1.57" xyz="0.0455 0.0214 0"/>
  </joint>
  <joint name="palm_tool0" type="fixed">
    <parent link="palm"/>
    <child link="tool0"/>
    <origin rpy="0 0 1.5707" xyz="0.0 0.0875 0.0"/>
  </joint>
  <!-- end of joint list -->
  <!--
        <xacro:include filename="$(find robotiq_3f_gripper_visualization)/cfg/robotiq-3f-gripper_finger_articulated_macro.xacro" />
        <xacro:robotiq-3f-gripper_finger_articulated prefix=""/>
-->
</robot>
