<?xml version="1.0"?>
<robot xmlns:xacro="http://www.ros.org/wiki/xacro">

  <xacro:property name="cyl_radius" value="0.001" />
  <xacro:macro name="svh" params="parent name side *origin">
    <!-- RIGHT HAND = 1, LEFT HAND = -1 -->
    <!-- BASE_LINE LINKS -->
    
    <joint name="${name}_base_joint" type="fixed" >
      <xacro:insert_block name="origin" />
      <parent link="${parent}" />
      <child link="${name}_base_link" />
    </joint>
    
    <link name="${name}_base_link">
      <xacro:insert_block name="origin" />
      <visual>
	<origin xyz="0 0 -0.032" rpy="0 0 0" />
	<geometry>
          <mesh filename="package://ros_end_effector/configs/meshes/base10.dae" />
	</geometry>
      </visual>
      <collision>
	<origin xyz="0 0 -0.032" rpy="0 0 0" />
	<geometry>
          <mesh filename="package://ros_end_effector/configs/meshes/base10.dae" />
	</geometry>
      </collision>
    </link>

    <link name="${name}_d">
      <!-- <visual> -->
      <!-- 	<geometry> -->
      <!-- 	  <cylinder length="0.110" radius="${cyl_radius}" /> -->
      <!-- 	</geometry> -->
      <!-- 	<material name="${name}_green" /> -->
      <!-- </visual> -->
    </link>

    <link name="${name}_h">
      <!-- <visual> -->
      <!-- 	<origin rpy="0 1.571 0" xyz="${side*(-0.0125)} 0 0.0825" /> -->
      <!-- 	<geometry> -->
      <!-- 	  <cylinder length="0.025" radius="${cyl_radius}" /> -->
      <!-- 	</geometry> -->
      <!-- 	<material name="${name}_green" /> -->
      <!-- </visual> -->
    </link>

    <link name="${name}_d2">
      <!-- <visual> -->
      <!-- 	<origin rpy="0 0 0" xyz="${side*(-0.025)} 0 0.09625" /> -->
      <!-- 	<geometry> -->
      <!-- 	  <cylinder length="0.0275" radius="${cyl_radius}" /> -->
      <!-- 	</geometry> -->
      <!-- 	<material name="${name}_green" /> -->
      <!-- </visual> -->
    </link>

    <!-- LENGTH NOT FOUND IN DATASHEET! GUESSED!!! -->
    <link name="${name}_e1">
      <visual>
	<origin rpy="0 0 0" xyz="0 0.01313 0" />
	<geometry>
          <mesh scale="${side*(1)} 1 1" filename="package://ros_end_effector/configs/meshes/h10.dae" />
	</geometry>
      </visual>
      <collision>
	<origin rpy="0 0 0" xyz="0 0.01313 0" />
	<geometry>
          <mesh scale="${side*(1)} 1 1" filename="package://ros_end_effector/configs/meshes/h10.dae" />
	</geometry>
      </collision>
    </link>

    <!-- LENGTH NOT FOUND IN DATASHEET! GUESSED!!! -->
    <link name="${name}_e2">
      <visual>
	<origin xyz="${side*(-0.0007)} 0 -0.01002" />
	<geometry>
          <mesh scale="${side*(1)} 1 1" filename="package://ros_end_effector/configs/meshes/h11.dae" />
	</geometry>
      </visual>
      <collision>
	<origin xyz="${side*(-0.0007)} 0 -0.01002" />
	<geometry>
          <mesh scale="${side*(1)} 1 1" filename="package://ros_end_effector/configs/meshes/h11.dae" />
	</geometry>
      </collision>
    </link>

    <!-- LENGTH NOT FOUND IN DATASHEET! GUESSED!!! -->
    <link name="${name}_e3">
      <!-- <visual> -->
      <!-- 	<origin rpy="0 0 0" xyz="${side*(0.0175)} 0 0.015" /> -->
      <!-- 	<geometry> -->
      <!-- 	  <cylinder length="0.03" radius="${cyl_radius}" /> -->
      <!-- 	</geometry> -->
      <!-- 	<material name="green" /> -->
      <!-- </visual> -->
    </link>

    <link name="${name}_e">
    </link>

    <!-- LENGTH NOT FOUND IN DATASHEET! GUESSED, BUT POSITION CALCULATED: E4 = D-G-F!!! -->
    <link name="${name}_e4">
      <!-- <visual> -->
      <!-- 	<origin rpy="0 0 0" xyz="${side*(0.02825)} 0 0.043" /> -->
      <!-- 	<geometry> -->
      <!-- 	  <cylinder length="0.026" radius="${cyl_radius}" /> -->
      <!-- 	</geometry> -->
      <!-- 	<material name="green" /> -->
      <!-- </visual> -->
    </link>

    <!-- LENGTH NOT FOUND IN DATASHEET! GUESSED, BUT POSITION CALCULATED: E5 = D-G!!! -->
    <link name="${name}_e5">
      <!-- <visual> -->
      <!-- 	<origin rpy="0 0 0" xyz="${side*(0.00675)} 0 0.04775" /> -->
      <!-- 	<geometry> -->
      <!-- 	  <cylinder length="0.0355" radius="${cyl_radius}" /> -->
      <!-- 	</geometry> -->
      <!-- 	<material name="green" /> -->
      <!-- </visual> -->
    </link>


    <!-- THUMB LINKS -->
    <link name="${name}_z">
      <visual>
	<origin xyz="0 0 0.02442" />
	<geometry>
          <mesh scale="1 ${side*(1)} 1" filename="package://ros_end_effector/configs/meshes/d10.dae" />
	</geometry>
      </visual>
      <collision>
	<origin xyz="0 0 0.02442" />
	<geometry>
          <mesh scale="1 ${side*(1)} 1" filename="package://ros_end_effector/configs/meshes/d10.dae" />
	</geometry>
      </collision>
    </link>

    <link name="${name}_virtual_a" />
    <link name="${name}_a">
      <visual>
	<geometry>
          <mesh scale="1 ${side*(1)} ${side*(1)}" filename="package://ros_end_effector/configs/meshes/d11.dae" />
	</geometry>
      </visual>
      <collision>
	<geometry>
          <mesh scale="1 ${side*(1)} ${side*(1)}" filename="package://ros_end_effector/configs/meshes/d11.dae" />
	</geometry>
      </collision>
    </link>

    <link name="${name}_b">
      <visual>
	<geometry>
          <mesh scale="1 ${side*(1)} ${side*(1)}" filename="package://ros_end_effector/configs/meshes/d12.dae" />
	</geometry>
      </visual>
      <collision>
	<geometry>
          <mesh scale="1 ${side*(1)} ${side*(1)}" filename="package://ros_end_effector/configs/meshes/d12.dae" />
	</geometry>
      </collision>
    </link>

    <link name="${name}_c">
      <visual>
	<geometry>
          <mesh scale="1 ${side*(1)} ${side*(1)}" filename="package://ros_end_effector/configs/meshes/d13.dae" />
	</geometry>
      </visual>
      <collision>
	<geometry>
          <mesh scale="1 ${side*(1)} ${side*(1)}" filename="package://ros_end_effector/configs/meshes/d13.dae" />
	</geometry>
      </collision>
    </link>


    <!-- INDEX FINGER LINKS -->
    <link name="${name}_virtual_l">
      <visual>
	<origin xyz="0 0 0.01321" />
	<geometry>
          <mesh filename="package://ros_end_effector/configs/meshes/f10.dae" />
	</geometry>
      </visual>
      <collision>
	<origin xyz="0 0 0.01321" />
	<geometry>
          <mesh filename="package://ros_end_effector/configs/meshes/f10.dae" />
	</geometry>
      </collision>
    </link>

    <link name="${name}_l">
      <visual>
	<geometry>
          <mesh filename="package://ros_end_effector/configs/meshes/f11.dae" />
	</geometry>
      </visual>
      <collision>
	<geometry>
          <mesh filename="package://ros_end_effector/configs/meshes/f11.dae" />
	</geometry>
      </collision>
    </link>

    <link name="${name}_p">
      <visual>
	<geometry>
          <mesh filename="package://ros_end_effector/configs/meshes/f12.dae" />
	</geometry>
      </visual>
      <collision>
	<geometry>
          <mesh filename="package://ros_end_effector/configs/meshes/f12.dae" />
	</geometry>
      </collision>
    </link>

    <link name="${name}_t">
      <visual>
	<geometry>
          <mesh filename="package://ros_end_effector/configs/meshes/f13.dae" />
	</geometry>
      </visual>
      <collision>
	<geometry>
          <mesh filename="package://ros_end_effector/configs/meshes/f13.dae" />
	</geometry>
      </collision>
    </link>


    <!-- MIDDLE FINGER LINKS -->
    <link name="${name}_virtual_k">
      <visual>
	<origin xyz="0 0 0.01321" />
	<geometry>
          <mesh filename="package://ros_end_effector/configs/meshes/f20.dae" />
	</geometry>
      </visual>
      <collision>
	<origin xyz="0 0 0.01321" />
	<geometry>
          <mesh filename="package://ros_end_effector/configs/meshes/f20.dae" />
	</geometry>
      </collision>
    </link>

    <link name="${name}_k">
      <visual>
	<geometry>
          <mesh filename="package://ros_end_effector/configs/meshes/f21.dae" />
	</geometry>
      </visual>
      <collision>
	<geometry>
          <mesh filename="package://ros_end_effector/configs/meshes/f21.dae" />
	</geometry>
      </collision>
    </link>

    <link name="${name}_o">
      <visual>
	<geometry>
          <mesh filename="package://ros_end_effector/configs/meshes/f22.dae" />
	</geometry>
      </visual>
      <collision>
	<geometry>
          <mesh filename="package://ros_end_effector/configs/meshes/f22.dae" />
	</geometry>
      </collision>
    </link>

    <link name="${name}_s">
      <visual>
	<geometry>
          <mesh filename="package://ros_end_effector/configs/meshes/f23.dae" />
	</geometry>
      </visual>
      <collision>
	<geometry>
          <mesh filename="package://ros_end_effector/configs/meshes/f23.dae" />
	</geometry>
      </collision>
    </link>


    <!-- RING FINGER LINKS -->
    <link name="${name}_virtual_j">
      <visual>
	<origin xyz="0 0 -0.01321" />
	<geometry>
          <mesh filename="package://ros_end_effector/configs/meshes/f30.dae" />
	</geometry>
      </visual>
      <collision>
	<origin xyz="0 0 -0.01321" />
	<geometry>
          <mesh filename="package://ros_end_effector/configs/meshes/f30.dae" />
	</geometry>
      </collision>
    </link>

    <link name="${name}_j">
      <visual>
	<geometry>
          <mesh filename="package://ros_end_effector/configs/meshes/f31.dae" />
	</geometry>
      </visual>
      <collision>
	<geometry>
          <mesh filename="package://ros_end_effector/configs/meshes/f31.dae" />
	</geometry>
      </collision>
    </link>

    <link name="${name}_n">
      <visual>
	<geometry>
          <mesh filename="package://ros_end_effector/configs/meshes/f32.dae" />
	</geometry>
      </visual>
      <collision>
	<geometry>
          <mesh filename="package://ros_end_effector/configs/meshes/f32.dae" />
	</geometry>
      </collision>
    </link>

    <link name="${name}_r">
      <visual>
	<geometry>
          <mesh filename="package://ros_end_effector/configs/meshes/f33.dae" />
	</geometry>
      </visual>
      <collision>
	<geometry>
          <mesh filename="package://ros_end_effector/configs/meshes/f33.dae" />
	</geometry>
      </collision>
    </link>


    <!-- LITTLE FINGER LINKS -->
    <link name="${name}_virtual_i">
      <visual>
	<origin xyz="0 0 -0.01321" />
	<geometry>
          <mesh filename="package://ros_end_effector/configs/meshes/f40.dae" />
	</geometry>
      </visual>
      <collision>
	<origin xyz="0 0 -0.01321" />
	<geometry>
          <mesh filename="package://ros_end_effector/configs/meshes/f40.dae" />
	</geometry>
      </collision>
    </link>

    <link name="${name}_i">
      <visual>
	<geometry>
          <mesh filename="package://ros_end_effector/configs/meshes/f41.dae" />
	</geometry>
      </visual>
      <collision>
	<geometry>
          <mesh filename="package://ros_end_effector/configs/meshes/f41.dae" />
	</geometry>
      </collision>
    </link>

    <link name="${name}_m">
      <visual>
	<geometry>
          <mesh filename="package://ros_end_effector/configs/meshes/f42.dae" />
	</geometry>
      </visual>
      <collision>
	<geometry>
          <mesh filename="package://ros_end_effector/configs/meshes/f42.dae" />
	</geometry>
      </collision>
    </link>

    <link name="${name}_q">
      <visual>
	<geometry>
          <mesh filename="package://ros_end_effector/configs/meshes/f43.dae" />
	</geometry>
      </visual>
      <collision>
	<geometry>
          <mesh filename="package://ros_end_effector/configs/meshes/f43.dae" />
	</geometry>
      </collision>
    </link>


    <joint name="${name}_Thumb_Flexion" type="revolute">
      <parent link="${name}_virtual_a" />
      <child link="${name}_a" />
      <limit effort="1000.0" lower="0.0" upper="0.9704" velocity="1" />
      <origin xyz="0 0 0" rpy="0 0 ${side*(-0.9704)}" />
      <axis xyz="0 0 ${side*(1)}" />
    </joint>
    
    <joint name="${name}_Thumb_Helper" type="fixed">
      <parent link="${name}_z" />
      <child link="${name}_virtual_a" />
      <origin xyz="0 0 0.04596" rpy="0 -1.5707 3.1416" />
    </joint>


    <!-- BASE_LINE JOINTS -->
    <joint name="${name}_Thumb_Opposition" type="revolute">
      <parent link="${name}_e1" />
      <child link="${name}_z" />
      <limit effort="1000.0" lower="0.0" upper="0.9879" velocity="1" />
      <origin xyz="${side*(-0.01690)} 0.02626 0" rpy="0 0.2618 1.571" />
      <axis xyz="0 0 ${side*(-1)}" />
    </joint>

    <!-- JOINT NOT FOR BASE_LINE. BUT WRITTEN DOWN HERE FOR BETTER UX -->

    <joint name="${name}_f1" type="fixed">
      <parent link="${name}_e1" />
      <child link="${name}_d" />
      <origin xyz="0 0 0" rpy="0 0 0" />
    </joint>

    <joint name="${name}_f2" type="fixed">
      <parent link="${name}_d" />
      <child link="${name}_h" />
      <origin xyz="0 0 0" rpy="0 0 0" />
    </joint>

    <joint name="${name}_f3" type="fixed">
      <parent link="${name}_h" />
      <child link="${name}_d2" />
      <origin xyz="0 0 0" rpy="0 0 0" />
    </joint>

    <joint name="${name}_f4" type="fixed">
      <parent link="${name}_base_link" />
      <child link="${name}_e1" />
      <origin xyz="0 -0.01313 0" rpy="0 0 0" />
    </joint>

    <joint name="${name}_j5" type="revolute">
      <parent link="${name}_e1" />
      <child link="${name}_e2" />
      <limit effort="1000.0" lower="0.0" upper="0.98786" velocity="1" />
      <origin xyz="${side*(0.01840)} 0.006 0.0375" rpy="0 0 0" />
      <axis xyz="0 0 ${side*(1)}" />
      <mimic joint="${name}_Thumb_Opposition" multiplier="1" offset="0" />
    </joint>

    <joint name="${name}_f5" type="fixed">
      <parent link="${name}_e2" />
      <child link="${name}_e3" />
      <origin xyz="0 -0.0060 0" rpy="0 0 0" />
    </joint>

    <joint name="${name}_f6" type="fixed">
      <parent link="${name}_e3" />
      <child link="${name}_e" />
      <origin xyz="0 0 0" rpy="0 0 0" />
    </joint>

    <joint name="${name}_f7" type="fixed">
      <parent link="${name}_e" />
      <child link="${name}_e4" />
      <origin xyz="0 0 0" rpy="0 0 0" />
    </joint>

    <joint name="${name}_f8" type="fixed">
      <parent link="${name}_e" />
      <child link="${name}_e5" />
      <origin xyz="0 0 0" rpy="0 0 0" />
    </joint>

    <!-- THUMB JOINTS -->
    <joint name="${name}_j3" type="revolute">
      <parent link="${name}_a" />
      <child link="${name}_b" />
      <limit effort="1000.0" lower="0.0" upper="0.98506" velocity="1" />
      <origin xyz="0.0485 0 0" rpy="0 0 0" />
      <axis xyz="0 0 ${side*(1)}" />
      <mimic joint="${name}_Thumb_Flexion" multiplier="1.01511" offset="0" />
    </joint>

    <joint name="${name}_j4" type="revolute">
      <parent link="${name}_b" />
      <child link="${name}_c" />
      <limit effort="1000.0" lower="0.0" upper="1.406" velocity="1" />
      <origin xyz="0.030 0 0" rpy="0 0 0" />
      <axis xyz="0 0 ${side*(1)}" />
      <mimic joint="${name}_Thumb_Flexion" multiplier="1.44889" offset="0" />
    </joint>

    <!-- INDEX FINGER JOINTS -->
    <joint name="${name}_Index_Finger_Distal" type="revolute">
      <parent link="${name}_l" />
      <child link="${name}_p" />
      <limit effort="1000.0" lower="0" upper="1.334" velocity="1" />
      <origin xyz="0.04804 0 0" rpy="0 0 0" />
      <axis xyz="0 0 1" />
    </joint>

    <joint name="${name}_Index_Finger_Proximal" type="revolute">
      <parent link="${name}_virtual_l" />
      <child link="${name}_l" />
      <limit effort="1000.0" lower="0.0" upper="0.79849" velocity="1" />
      <origin xyz="0 0 0" rpy="-1.5707 0 0" />
      <axis xyz="0 0 1" />
    </joint>

    <!-- JOINT Finger_Spread in BASE_LINE section for better UX -->
    <joint name="${name}_j14" type="revolute">
      <parent link="${name}_p" />
      <child link="${name}_t" />
      <limit effort="1000.0" lower="0" upper="1.394" velocity="1" />
      <origin xyz="0.026 0 0" rpy="0 0 0" />
      <axis xyz="0 0 1" />
      <mimic joint="${name}_Index_Finger_Distal" multiplier="1.0450" offset="0" />
    </joint>

    <!-- MIDDLE FINGER JOINTS -->
    <joint name="${name}_Middle_Finger_Proximal" type="revolute">
      <parent link="${name}_virtual_k" />
      <child link="${name}_k" />
      <limit effort="1000.0" lower="0.0" upper="0.79849" velocity="1" />
      <origin xyz="0 0 0" rpy="-1.5707 0 0" />
      <axis xyz="0 0 1" />
    </joint>

    <joint name="${name}_Middle_Finger_Distal" type="revolute">
      <parent link="${name}_k" />
      <child link="${name}_o" />
      <limit effort="1000.0" lower="0" upper="1.334" velocity="1" />
      <origin xyz="0.05004 0 0" rpy="0 0 0" />
      <axis xyz="0 0 1" />
    </joint>

    <joint name="${name}_j15" type="revolute">
      <parent link="${name}_o" />
      <child link="${name}_s" />
      <limit effort="1000.0" lower="0" upper="1.334" velocity="1" />
      <origin xyz="0.032 0 0" rpy="0 0 0" />
      <axis xyz="0 0 1" />
      <mimic joint="${name}_Middle_Finger_Distal" multiplier="1.0454" offset="0" />
    </joint>

    <!-- RING FINGER JOINTS -->
    <joint name="${name}_Ring_Finger" type="revolute">
      <parent link="${name}_virtual_j" />
      <child link="${name}_j" />
      <limit effort="1000.0" lower="0.0" upper="0.98175" velocity="1" />
      <origin xyz="0 0 0" rpy="1.5707 0 0" />
      <axis xyz="0 0 1" />
    </joint>
    
    <joint name="${name}_j12" type="revolute">
      <parent link="${name}_j" />
      <child link="${name}_n" />
      <limit effort="1000.0" lower="0" upper="1.334" velocity="1" />
      <origin xyz="0.05004 0 0" rpy="0 0 0" />
      <axis xyz="0 0 1" />
      <mimic joint="${name}_Ring_Finger" multiplier="1.3588" offset="0" />
    </joint>

    <joint name="${name}_j16" type="revolute">
      <parent link="${name}_n" />
      <child link="${name}_r" />
      <limit effort="1000.0" lower="0" upper="1.395" velocity="1" />
      <origin xyz="0.032 0 0" rpy="0 0 0" />
      <axis xyz="0 0 1" />
      <mimic joint="${name}_Ring_Finger" multiplier="1.42093" offset="0" />
    </joint>

    <!-- PINKY JOINTS -->
    <joint name="${name}_Pinky" type="revolute">
      <parent link="${name}_virtual_i" />
      <child link="${name}_i" />
      <limit effort="1000.0" lower="0.0" upper="0.98175" velocity="1" />
      <origin xyz="0 0 0" rpy="1.5707 0 0" />
      <axis xyz="0 0 1" />
    </joint>

    <joint name="${name}_j13" type="revolute">
      <parent link="${name}_i" />
      <child link="${name}_m" />
      <limit effort="1000.0" lower="0" upper="1.334" velocity="1" />
      <origin xyz="0.04454 0 0" rpy="0 0 0" />
      <axis xyz="0 0 1" />
      <mimic joint="${name}_Pinky" multiplier="1.35880" offset="0" />
    </joint>

    <joint name="${name}_j17" type="revolute">
      <parent link="${name}_m" />
      <child link="${name}_q" />
      <limit effort="1000.0" lower="0" upper="1.3971" velocity="1" />
      <origin xyz="0.022 0 0" rpy="0 0 0" />
      <axis xyz="0 0 1" />
      <mimic joint="${name}_Pinky" multiplier="1.42307" offset="0" />
    </joint>

    <joint name="${name}_index_spread" type="revolute">
      <parent link="${name}_d2" />
      <child link="${name}_virtual_l" />
      <limit effort="1000.0" lower="0.0" upper="0.28833" velocity="1" />
      <origin xyz="${side*(-0.025)} 0 0.110" rpy="0 -1.5707 1.5707" />
      <axis xyz="0 0 ${side*(1)}" />
      <mimic joint="${name}_Finger_Spread" multiplier="0.5" offset="0" />
    </joint>

    <joint name="${name}_middle_spread_dummy" type="fixed">
      <parent link="${name}_d" />
      <child link="${name}_virtual_k" />
      <origin xyz="0 0 0.110" rpy="0 -1.5707 1.5707" />
    </joint>


    <joint name="${name}_ring_spread" type="revolute">
      <parent link="${name}_e5" />
      <child link="${name}_virtual_j" />
      <limit effort="1000.0" lower="0.0" upper="0.28833" velocity="1" />
      <origin xyz="${side*(0.003855)} 0 0.0655" rpy="-1.5707 -1.5707 0" />
      <axis xyz="0 0 ${side*(1)}" />
      <mimic joint="${name}_Finger_Spread" multiplier="0.5" offset="0" />
    </joint>

    <joint name="${name}_Finger_Spread" type="revolute">
      <parent link="${name}_e4" />
      <child link="${name}_virtual_i" />
      <limit effort="1000.0" lower="0.0" upper="0.5829" velocity="1" />
      <origin xyz="${side*(0.025355)} 0 0.056" rpy="-1.5707 -1.5707 0" />
      <axis xyz="0 0 ${side*(1)}" />
    </joint>    
</xacro:macro>
</robot>

